Workbook
Name AfricaCountries: CountryList!$A$1:$A$54
Name DegradationRate: expected_production!$J$1

Sheet site_tech_info
A1: Site Name | B1: PV Capacity (W) | C1: PV Inverter Size (kW) | D1: Battery Size (Wh) | E1: Battery Name | F1: Battery Inverter/Hybrid Size | G1: Generator Size | H1: Genset/Grid set point kit | I1: Country | J1: Province | K1: Location | L1: Meter | M1: Contract Type | N1: Business Type | O1: Operational Satus | P1: Sales Type | Q1: Investment Party | R1: Project Number | S1: Commisioned Date | T1: Installer Name | U1: Platform | V1: Offtake Guarantee | W1: Age | X1: Soiling Intensity | Y1: Shading | Z1: Power Limit
A2: 21 Melrose | B2: 14000 | C2: 36 | D2: 35808 | E2: Sunsynk | F2: 3x12kW | G2: None | H2: None | I2: South Africa | J2: Gauteng | K2: 21 Melrose St Melrose | L2: N/A | M2: RTO | N2: Residential | O2: Reduced Demand | Q2: Anuva | R2: P00062 | S2: 44963 | T2: SA Energy | U2: Sunsynk | V2: NO | W2: =IF(ISNUMBER(S2),(TODAY()-S2)/365.25,"") -> 3.7207392 | X2: Low | Y2: Low | Z2: Zero Export
A3: African Global Plastics | B3: 178000 | C3: =2*80 -> 160 | D3: 0 | E3: N/A | F3: N/A | G3: None | H3: None | I3: South Africa | J3: Gauteng | K3: 1st St & 11th road, Kew, Sandton, 2090 | L3: Alester Meter | M3: PPA | N3: Manufacture | O3: Producing | Q3: SSI | R3: P00008 | S3: 45196 | T3: SA Energy | U3: mypower24 | V3: NO | W3: =IF(ISNUMBER(S3),(TODAY()-S3)/365.25,"") -> 3.08282 | X3: Medium | Y3: Low | Z3: Zero Export
A4: Alpine Heath Residential | B4: 36000 | C4: =1*33 -> 33 | D4: 0 | E4: N/A | F4: N/A | G4: None | H4: None | I4: South Africa | J4: KZN | K4: Busingatha, South Africa | L4: Eastron Meter | M4: PPA | N4: Residential | O4: Reduced Demand | Q4: 12B Fund | R4: null | S4: 45658 | T4: SA Energy | U4: isolarCloud | V4: YES | W4: =IF(ISNUMBER(S4),(TODAY()-S4)/365.25,"") -> 1.8179329 | X4: Low | Y4: Low | Z4: Zero Export
A5: Alpine Heath Resort | B5: 217000 | C5: =2*110 -> 220 | D5: 0 | E5: N/A | F5: N/A | G5: N/A | H5: N/A | I5: South Africa | J5: KZN | K5: Busingatha, South Africa | L5: Eastron Meter | M5: PPA | N5: Residential | O5: Producing | Q5: 12B Fund | R5: null | S5: 46140 | T5: SA Energy | U5: IsolarCloud | V5: YES | W5: =IF(ISNUMBER(S5),(TODAY()-S5)/365.25,"") -> 0.49828884 | X5: Low | Y5: Low | Z5: Zero Export
A6: Bendstore Plaza Shops | B6: 110000 | C6: =1*110 -> 110 | D6: 0 | E6: N/A | F6: N/A | G6: N/A | H6: N/A | I6: South Africa | J6: Limpopo | K6: Stand 87, Bendstore Plaza, Giyani Main Rd, Giyani-BA, Giyani, 0832 | L6: null | M6: PPA | N6: Retail | O6: Reduced Demand | Q6: Anuva | R6: P00072 | S6: 44908 | T6: SA Energy | U6: null | V6: NO | W6: =IF(ISNUMBER(S6),(TODAY()-S6)/365.25,"") -> 3.871321 | X6: Low | Y6: Unknown | Z6: Zero Export
A7: Bendstore Spar | B7: 400000 | C7: null | D7: 0 | E7: N/A | F7: N/A | G7: null | H7: null | I7: South Africa | J7: Limpopo | K7: null | L7: null | M7: PPA | N7: Retail | O7: Producing | Q7: Anuva | R7: null | S7: 45272 | T7: SA Energy | U7: null | V7: NO | W7: =IF(ISNUMBER(S7),(TODAY()-S7)/365.25,"") -> 2.8747433 | X7: Low | Y7: Unknown | Z7: Zero Export
A8: Beyerskloof | B8: 78000 | C8: null | D8: 0 | E8: N/A | F8: N/A | G8: null | H8: null | I8: South Africa | J8: Western Cape | K8: Koelenhof Street, R304, Koelenhof, Stellenbosch, 7600 | L8: null | M8: PPA | N8: Manufacture | O8: Reduced Demand | Q8: SSI | R8: null | S8: 45272 | T8: Solar Synergy | U8: null | V8: NO | W8: =IF(ISNUMBER(S8),(TODAY()-S8)/365.25,"") -> 2.8747433 | X8: Low | Y8: Low | Z8: Zero Export
A9: BP Parys | B9: 544000 | C9: 50 | D9: 0 | E9: N/A | F9: N/A | G9: N/A | H9: N/A | I9: South Africa | J9: Free state | K9: 63 Bree St, Parys, 9585 | L9: Eastron Meter | M9: RTO | N9: Retail | O9: Reduced Demand | Q9: SSI | R9: null | S9: 45610 | T9: SA Energy | U9: null | V9: NO | W9: =IF(ISNUMBER(S9),(TODAY()-S9)/365.25,"") -> 1.9493498 | X9: Low | Y9: Unknown | Z9: Zero Export
A10: Buffalo Rock | B10: 15000 | C10: N/A | D10: 57200 | E10: null | F10: 2x12kW | G10: N/A | H10: N/A | I10: South Africa | J10: Mpumalanga | K10: Hazyview Ehlanzeni District Municipality MP | L10: null | M10: RTO | N10: Residential | O10: Reduced Demand | Q10: SSI | R10: P00054 | S10: 45183 | T10: SA Energy | U10: Sunsynk | V10: NO | W10: =IF(ISNUMBER(S10),(TODAY()-S10)/365.25,"") -> 3.118412 | X10: Low | Y10: Unknown | Z10: Zero Export
A11: Checkers De Aar | B11: 154000 | C11: 125 | D11: 0 | E11: N/A | F11: N/A | G11: N/A | H11: NuVo | I11: South Africa | J11: Northern Cape | K11: 21 Alexander St, De Aar, 7000, South Africa | M11: PPA | N11: Retail | O11: Producing | Q11: 12B Fund | R11: P00038 | S11: 45449 | T11: SA Energy | U11: iSolarCloud & NuVo | V11: NO | W11: =IF(ISNUMBER(S11),(TODAY()-S11)/365.25,"") -> 2.3901437 | X11: Low | Y11: Low | Z11: Zero Export
A12: Checkers Lichtenburg | B12: 161000 | C12: 150 | D12: 0 | E12: N/A | F12: N/A | G12: N/A | H12: N/A | I12: South Africa | J12: North West | K12: 33 Nelson Mandela Dr, Lichtenburg, 2740 | L12: Eastron Meter | M12: PPA | N12: Retail | O12: Producing | Q12: SSI | R12: null | S12: 46129 | T12: SA Energy | U12: IsolarCloud | V12: NO | W12: =IF(ISNUMBER(S12),(TODAY()-S12)/365.25,"") -> 0.5284052 | X12: Unknown | Y12: Low | Z12: Zero Export
A13: Checkers Silverlakes Gen | B13: 152000 | C13: 125 | D13: 0 | E13: N/A | F13: N/A | G13: 500 | H13: Nuvo | I13: South Africa | J13: Gauteng | K13: Chamberlain Shopping Cntr (Six Fountains Cnr Solomon Mahlangu Dr, Bendeman Blvd, &, Pretoria, 0081 | L13: Eastron Meter | M13: PPA | N13: Retail | O13: Producing | Q13: 12B Fund | R13: null | S13: 2025/02/29 | T13: SA Energy | U13: isolarCloud | V13: NO | W13: =IF(ISNUMBER(S13),(TODAY()-S13)/365.25,"") | X13: Low | Y13: Low | Z13: Zero Export
A14: Checkers Silverlakes No Gen | B14: 142000 | C14: 125 | D14: 0 | E14: N/A | F14: N/A | G14: N/A | H14: N/A | I14: South Africa | J14: Gauteng | K14: Chamberlain Shopping Cntr (Six Fountains Cnr Solomon Mahlangu Dr, Bendeman Blvd, &, Pretoria, 0081 | L14: Eastron Meter | M14: PPA | N14: Retail | O14: Producing | Q14: 12B Fund | R14: null | S14: 2025/02/29 | T14: SA Energy | U14: isolarCloud | V14: NO | W14: =IF(ISNUMBER(S14),(TODAY()-S14)/365.25,"") | X14: Low | Y14: Low | Z14: Zero Export
A15: Checkrite Inanda | B15: 70000 | C15: =2*33 -> 66 | D15: 0 | E15: N/A | F15: N/A | G15: N/A | H15: N/A | I15: South Africa | J15: Gauteng | K15: 6th Ave, Springs New, Springs, 1560 | L15: null | M15: PPA | N15: Retail | O15: Producing | Q15: 12B Fund | R15: P00056 | S15: 45471 | T15: SA Energy | U15: iSolarCloud | V15: YES | W15: =IF(ISNUMBER(S15),(TODAY()-S15)/365.25,"") -> 2.329911 | X15: Low | Y15: Low | Z15: Zero Export
A16: Club Houghton | B16: 60000 | C16: N/A | D16: 84000 | E16: N/A | F16: 6x12kW Sunsynk Inverters | G16: N/A | H16: null | I16: South Africa | J16: Gauteng | K16: Osborn Rd, Houghton Estate, Johannesburg, 2198, South Africa | L16: N/A | M16: PPA | N16: Residential | O16: Reduced Demand | Q16: Anuva | R16: P00067 | S16: 44665 | T16: SA Energy | U16: Sunsysnk;SolarMd | V16: NO | W16: =IF(ISNUMBER(S16),(TODAY()-S16)/365.25,"") -> 4.5366188 | X16: Low | Y16: Low | Z16: Zero Export
A17: Coldstar International | B17: 41000 | C17: 36 | D17: 0 | E17: N/A | F17: N/A | G17: N/A | H17: N/A | I17: South Africa | J17: KZN | K17: Coldstar International, 3 Rana Rd, Isipingo Rail, Isipingo, 4110 | client miss use data | L17: N/A | M17: PPA | N17: Commercial | O17: Reduced Demand | Q17: Anuva | R17: P00051 | S17: 44643 | T17: SA Energy | U17: iSolarCloud | V17: NO | W17: =IF(ISNUMBER(S17),(TODAY()-S17)/365.25,"") -> 4.5968515 | X17: Low | Y17: Low | Z17: Exporting
A18: Cultura Fresh | B18: 65000 | C18: 110 | D18: 171600 | E18: Atess | F18: ATESS PCS250 | G18: N/A | H18: null | I18: South Africa | J18: Western Cape | K18: null | L18: null | M18: PPA | N18: Agricultural | O18: Reduced Demand | Q18: 12B Fund | R18: null | S18: 45509 | T18: Solar Synergy | U18: null | V18: NO | W18: =IF(ISNUMBER(S18),(TODAY()-S18)/365.25,"") -> 2.2258727 | X18: Low | Y18: Low | Z18: Zero Export
A19: Demco | B19: 235000 | C19: =2*110 -> 220 | D19: 0 | E19: N/A | F19: N/A | G19: N/A | H19: N/A | I19: South Africa | J19: Gauteng | K19: Industries East, 12 -14 Moller Street, Germiston. 1401 | L19: Alester Meter | M19: PPA | N19: Manufacture | O19: Reduced Demand | Q19: 12B Fund | R19: P00035 | S19: 45460 | T19: SA Energy | U19: iSolarCloud | V19: YES | W19: =IF(ISNUMBER(S19),(TODAY()-S19)/365.25,"") -> 2.3600274 | X19: Low | Y19: Low | Z19: Zero Export
A20: Engen Kaalfontein | B20: 114070 | C20: 125 | D20: 0 | E20: N/A | F20: N/A | G20: N/A | H20: N/A | I20: South Africa | J20: Gauteng | K20: 3117 Angelfish St, Kaalfontein, Midrand, 1632 | L20: Eastron Meter | M20: PPA | N20: Retail | O20: Producing | Q20: SSI | R20: null | S20: 46162 | T20: SA Energy | U20: IsolarCloud | V20: YES | W20: =IF(ISNUMBER(S20),(TODAY()-S20)/365.25,"") -> 0.43805613 | X20: High | Y20: Low | Z20: Zero Export
A21: Engen Lotus Gardens | B21: 23010 | D21: 0 | E21: N/A | F21: N/A | G21: N/A | H21: N/A | I21: South Africa | J21: Gauteng | K21: 63WC+CQ4 Pretoria | L21: Eastron Meter | M21: PPA | N21: Retail | O21: Producing | Q21: SSI | R21: null | S21: 45951 | T21: SA Energy | U21: IsolarCloud | V21: YES | W21: =IF(ISNUMBER(S21),(TODAY()-S21)/365.25,"") -> 1.0157426 | X21: Low | Y21: Low | Z21: Zero Export
A22: Giba Gorge Main | B22: 123360 | C22: 160 | D22: 0 | E22: N/A | F22: N/A | G22: N/A | H22: N/A | I22: South Africa | J22: KZN | K22: 5QCJ+XM2 Clifton Canyon, Pinetown Rural | L22: Alester Meter | M22: PPA | N22: Manufacture | O22: Reduced Demand | Q22: SSI | R22: P00069 | S22: 44479 | T22: SA Energy | U22: soliscloud | V22: NO | W22: =IF(ISNUMBER(S22),(TODAY()-S22)/365.25,"") -> 5.045859 | X22: Low | Y22: Low | Z22: Zero Export
A23: Giba Gorge Storage | B23: 106000 | C23: null | D23: 0 | E23: N/A | F23: N/A | G23: N/A | H23: null | I23: South Africa | J23: KZN | K23: 5QCJ+XM2 Clifton Canyon, Pinetown Rural | L23: Alester Meter | M23: PPA | N23: Commercial | O23: Reduced Demand | Q23: SSI | R23: null | S23: 44479 | T23: SA Energy | U23: SolisCloud | V23: NO | W23: =IF(ISNUMBER(S23),(TODAY()-S23)/365.25,"") -> 5.045859 | X23: Low | Y23: Low | Z23: Zero Export
A24: Golden Spot Resort | B24: 30000 | C24: 33 | D24: 0 | E24: N/A | F24: N/A | G24: N/A | H24: N/A | I24: South Africa | J24: Mpumalanga | K24: HR2M+GQ7 Alkmaar (-25.4487127, 30.8344204) | L24: null | M24: PPA | N24: Residential | O24: Reduced Demand | Q24: SSI | R24: P00071 | S24: 45073 | T24: SA Energy | U24: iSolarCloud | V24: YES | W24: =IF(ISNUMBER(S24),(TODAY()-S24)/365.25,"") -> 3.4195756 | X24: Low | Y24: Low | Z24: Zero Export
A25: Golden Spot Shops | B25: 30000 | C25: 33 | D25: 0 | E25: N/A | F25: N/A | G25: N/A | H25: N/A | I25: South Africa | J25: Mpumalanga | K25: HR2M+GQ7 Alkmaar (-25.4487127, 30.8344204) | L25: null | M25: PPA | N25: Retail | O25: Producing | Q25: SSI | R25: P00060 | S25: 45072 | T25: SA Energy | U25: iSolarCloud | V25: YES | W25: =IF(ISNUMBER(S25),(TODAY()-S25)/365.25,"") -> 3.4223135 | X25: Low | Y25: Low | Z25: Zero Export
A26: Grootpan | B26: 170000 | C26: =4*50 -> 200 | D26: 491520 | E26: Deye | F26: Daye | G26: N/A | H26: N/A | I26: South Africa | J26: North West | K26: 2G4H+RXQ Ga-Motlatla | L26: N/A | M26: RTO | N26: Agricultural | O26: Reduced Demand | Q26: SSI | R26: null | S26: 46086 | T26: OTG 4 U | U26: Deye Cloud | V26: NO | W26: =IF(ISNUMBER(S26),(TODAY()-S26)/365.25,"") -> 0.64613279 | X26: Low | Y26: Low | Z26: Zero Export
A27: HB Dunn | B27: 24000 | C27: N/A | D27: 127400 | E27: N/A | F27: 1x50 kW | G27: N/A | H27: N/A | I27: South Africa | J27: Mpumalanga | K27: Kriel Nkangala District Municipality MP | L27: null | M27: RTO | N27: Residential | O27: Reduced Demand | Q27: SSI | R27: P00045 | S27: 45407 | T27: SA Energy | U27: Sunsynk | V27: NO | W27: =IF(ISNUMBER(S27),(TODAY()-S27)/365.25,"") -> 2.5051335 | X27: Low | Y27: Low | Z27: Zero Export
A28: Helderberg Collage | B28: 223000 | C28: null | D28: 0 | E28: N/A | F28: N/A | G28: N/A | H28: null | I28: South Africa | J28: Western Cape | K28: null | L28: null | M28: PPA | N28: Residential | O28: Producing | Q28: SSI | R28: null | S28: 43700 | T28: SA Energy | U28: null | V28: NO | W28: =IF(ISNUMBER(S28),(TODAY()-S28)/365.25,"") -> 7.1786448 | X28: Low | Y28: Low | Z28: Zero Export
A29: Hilston Rotoflo | B29: 240000 | C29: 240 | D29: 0 | E29: N/A | F29: N/A | G29: N/A | H29: N/A | I29: South Africa | J29: Gauteng | K29: 28 Hilston Rd, Kya Sand, Randburg, 2163 | L29: null | M29: PPA | N29: Residential | O29: Producing | Q29: Anuva | R29: P00055 | S29: 45056 | T29: SA Energy | U29: isolarCloud | V29: YES | W29: =IF(ISNUMBER(S29),(TODAY()-S29)/365.25,"") -> 3.4661191 | X29: Low | Y29: Low | Z29: Zero Export
A30: Huis Herfsblaar | B30: 215000 | C30: =2*110 -> 220 | D30: 0 | E30: N/A | F30: N/A | G30: N/A | H30: N/A | I30: South Africa | J30: Gauteng | K30: Edging Pretoria, 1244 Webb Rd, Queenswood, Pretoria, 0186, South Africa | L30: Eastron Meter | M30: PPA | N30: Commercial | O30: Producing | Q30: 12B Fund | R30: P00034 | S30: 45463 | T30: SA Energy | U30: iSolarCloud | V30: YES | W30: =IF(ISNUMBER(S30),(TODAY()-S30)/365.25,"") -> 2.3518138 | X30: Low | Y30: Low | Z30: Zero Export
A31: IPID - Floor 4 | B31: 54740 | C31: null | D31: 0 | E31: N/A | F31: N/A | G31: N/A | H31: N/A | I31: South Africa | J31: Gauteng | K31: 7633+M46 Pretoria | L31: Eastron Meter | M31: PPA | N31: Commercial | O31: Producing | Q31: SSI | R31: null | S31: 45934 | T31: SA Energy | U31: IsolarCloud | V31: YES | W31: =IF(ISNUMBER(S31),(TODAY()-S31)/365.25,"") -> 1.0622861 | X31: Low | Y31: Low | Z31: Zero Export
A32: IPID - Floor 6 | B32: 47600 | C32: null | D32: 0 | E32: N/A | F32: N/A | G32: N/A | H32: N/A | I32: South Africa | J32: Gauteng | K32: 7633+M46 Pretoria | L32: Eastron Meter | M32: PPA | N32: Commercial | O32: Producing | Q32: SSI | R32: null | S32: 45934 | T32: SA Energy | U32: IsolarCloud | V32: YES | W32: =IF(ISNUMBER(S32),(TODAY()-S32)/365.25,"") -> 1.0622861 | X32: Low | Y32: Low | Z32: Zero Export
A33: Kool Village | B33: 79000 | C33: null | D33: 0 | E33: N/A | F33: N/A | G33: N/A | H33: null | I33: South Africa | J33: Northern Cape | K33: Kool Village, 89 Virginia Way, Virginia, 9430 | L33: null | M33: null | N33: Commercial | O33: Producing | Q33: Anuva | R33: null | S33: 2022/16/12 | T33: SA Energy | U33: null | V33: NO | W33: =IF(ISNUMBER(S33),(TODAY()-S33)/365.25,"") | X33: Low | Y33: Low | Z33: Zero Export
A34: Makalali | B34: 120000 | C34: null | D34: 171600 | E34: N/A | F34: 250 | G34: N/A | H34: N/A | I34: South Africa | J34: Limpopo | K34: Makalali game reserve Road D202 Harmony Block 33, Gravelotte | N34: Agriculural | O34: Reduced Demand | Q34: SSI | R34: null | S34: 45050 | T34: SA Energy | W34: =IF(ISNUMBER(S34),(TODAY()-S34)/365.25,"") -> 3.4825462 | X34: Low | Y34: Low | Z34: Zero Export
A35: Mambha Cash & Carry | B35: 184000 | C35: null | D35: 0 | E35: N/A | F35: N/A | G35: N/A | H35: null | I35: South Africa | J35: KZN | K35: null | L35: null | M35: PPA | N35: Retail | O35: Producing | Q35: Anuva | R35: P00015 | S35: 44879 | T35: SA Energy | U35: mypower24 | V35: NO | W35: =IF(ISNUMBER(S35),(TODAY()-S35)/365.25,"") -> 3.9507187 | X35: High | Y35: Low | Z35: Zero Export
A36: Mathe Group Company | B36: 518000 | C36: =4*110 -> 440 | D36: 0 | E36: N/A | F36: N/A | G36: N/A | H36: N/A | I36: South Africa | J36: KZN | K36: 4/160 Buckman Blvd, Cato Ridge, 3699, South Africa | L36: null | M36: PPA | N36: Manufacture | O36: Producing | Q36: Anuva | R36: P00059 | S36: 44692 | T36: SA Energy | U36: iSolarCloud | W36: =IF(ISNUMBER(S36),(TODAY()-S36)/365.25,"") -> 4.4626968 | X36: Low | Y36: Low | Z36: Zero Export
A37: Mdluli | B37: 114000 | C37: null | D37: =228800*2 -> 457600 | E37: N/A | F37: N/A | G37: N/A | H37: null | I37: South Africa | J37: Mpumalanga | K37: Makoko, South Africa,1251 | L37: null | M37: PPA | N37: Residential | O37: Reduced Demand | Q37: 12B Fund | R37: P00083 | S37: 45399 | T37: SA Energy | U37: mypower24&IsolarCloud | V37: YES | W37: =IF(ISNUMBER(S37),(TODAY()-S37)/365.25,"") -> 2.5270363 | X37: Low | Y37: Low | Z37: Zero Export
A38: Medipost | B38: 330000 | C38: null | D38: 0 | E38: N/A | F38: N/A | G38: N/A | H38: N/A | I38: South Africa | J38: Western Cape | K38: 593 Nico Smith St, Gezina, Pretoria, 0084 | L38: Eastron Meter | M38: PPA | N38: Commercial | O38: Producing | Q38: 12B Fund | R38: null | S38: 45713 | T38: SA Energy | U38: null | W38: =IF(ISNUMBER(S38),(TODAY()-S38)/365.25,"") -> 1.6673511 | X38: Low | Y38: Low | Z38: Zero Export
A39: Meredale Heights | B39: 33000 | C39: =1*33 -> 33 | D39: 0 | E39: N/A | F39: N/A | G39: N/A | H39: N/A | I39: South Africa | J39: Gauteng | K39: 40 thomas street | L39: null | M39: PPA | N39: Residential | O39: Producing | Q39: Anuva | R39: P00052 | S39: 45248 | T39: SA Energy | U39: iSolarCloud | V39: YES | W39: =IF(ISNUMBER(S39),(TODAY()-S39)/365.25,"") -> 2.9404517 | X39: Low | Y39: Low | Z39: Zero Export
A40: Monument Park Checkers | B40: 281000 | C40: =2*125 -> 250 | D40: 0 | E40: N/A | F40: N/A | G40: N/A | H40: NuVo | I40: South Africa | J40: Gauteng | K40: 242 Voortrekker Rd, Monument, Krugersdorp, 1739, South Africa | L40: null | M40: PPA | N40: Retail | O40: Producing | Q40: Anuva | R40: P00037 | S40: 45351 | T40: SA Energy | U40: isloarcloud &Nuvo | V40: NO | W40: =IF(ISNUMBER(S40),(TODAY()-S40)/365.25,"") -> 2.6584531 | X40: Low | Y40: Low | Z40: Zero Export
...

Sheet Simulated Production
A1: Site Name | B1: Jan | C1: Feb | D1: Mar | E1: Apr | F1: May | G1: Jun | H1: Jul | I1: Aug | J1: Sep | K1: Oct | L1: Nov | M1: Dec
A2: 21 Melrose | B2: 2634 | C2: 2978 | D2: 2426 | E2: 2082 | F2: 2025 | G2: 1810 | H2: 2016 | I2: 2352 | J2: 2528 | K2: 2675 | L2: 2618 | M2: 2758
A3: African Global Plastics | B3: 26489.3 | C3: 23277.8 | D3: 23704 | E3: 19723.4 | F3: 18790.7 | G3: 16902.6 | H3: 18714.9 | I3: 21796.9 | J3: 24005.1 | K3: 26259.6 | L3: 26494.9 | M3: 27974.1
A4: Alpine Heath Residential | B4: 5335 | C4: 4782 | D4: 5051 | E4: 5133 | F4: 5545 | G4: 5291 | H4: 5201 | I4: 5833 | J4: 5216 | K4: 5258 | L4: 5358 | M4: 5339
A5: Bendstore Plaza Shops | B5: 19132 | C5: 16455 | D5: 18192 | E5: 17513 | F5: 16955 | G5: 15353 | H5: 16159 | I5: 18059 | J5: 18155 | K5: 17437 | L5: 17289 | M5: 19005
A6: Bendstore Spar | B6: 57016.372 | C6: 49003.656 | D6: 54154.745 | E6: 52055.443 | F6: 50303.593 | G6: 45493.302 | H6: 47903.114 | I6: 53629.448 | J6: 54003.213 | K6: 51943.234 | L6: 51542.757 | M6: 56267.013
A7: Beyerskloof | B7: 15319 | C7: 12622 | D7: 12090 | E7: 8698 | F7: 6615 | G7: 5740 | H7: 6183 | I7: 7734 | J7: 9940 | K7: 12572 | L7: 14126 | M7: 15421
A8: BP Parys | B8: 9057 | C8: 8039 | D8: 7862 | E8: 6394 | F8: 6027 | G8: 5319 | H8: 5956 | I8: 7070 | J8: 8021 | K8: 8710 | L8: =9102 -> 9102 | M8: 9142
A9: Buffalo Rock | B9: 2447 | C9: 2204 | D9: 2364 | E9: 1964 | F9: 1813 | G9: 1645 | H9: 1792 | I9: 1960 | J9: 2076 | K9: 2112 | L9: 2039 | M9: 2207
A10: Checkers De Aar | B10: 29655 | C10: 22972 | D10: 22328 | E10: 18096 | F10: 15021 | G10: 13183 | H10: 15099 | I10: 19010 | J10: 21674 | K10: 26757 | L10: 28766 | M10: 31103
A11: Checkers Silverlakes Gen | B11: 23450 | C11: 20245 | D11: 20409 | E11: 16782 | F11: 15700 | G11: 14022 | H11: 15558 | I11: 18491 | J11: 20696 | K11: 22782 | L11: 22890 | M11: 24472
A12: Checkers Silverlakes No Gen | B12: 23450 | C12: 20245 | D12: 20409 | E12: 16782 | F12: 15700 | G12: 14022 | H12: 15558 | I12: 18491 | J12: 20696 | K12: 22782 | L12: 22890 | M12: 24472
A13: Checkrite Inanda | B13: 9627 | C13: 9000 | D13: 8673 | E13: 7260 | F13: 6214 | G13: 5622 | H13: 5969 | I13: 7206 | J13: 7683 | K13: 8926 | L13: 8903 | M13: 9497
A14: Club Houghton | B14: 6408 | C14: 5365 | D14: 5459 | E14: 4611 | F14: 4375 | G14: 3848 | H14: 4305 | I14: 5067 | J14: 5593 | K14: 6237 | L14: 6347 | M14: 6697
A15: Coldstar International | B15: 5761.2 | C15: 5289.7 | D15: 5351.3 | E15: 4476.7 | F15: 4144.2 | G15: 3750.5 | H15: 4019 | I15: 4537.7 | J15: 4477.3 | K15: 4986.7 | L15: 5100.4 | M15: 5950.6
A16: Cultura Fresh | B16: 13109 | C16: 11411 | D16: 11746 | E16: 9262 | F16: 7471 | G16: 6511 | H16: 7170 | I16: 8324 | J16: 9849 | K16: 11513 | L16: 12192 | M16: 12923
A17: Demco | B17: 41895 | C17: 35971 | D17: 36483 | E17: 30848 | F17: 29226 | G17: 26233 | H17: 29069 | I17: 34133 | J17: 37890 | K17: 41280 | L17: 41518 | M17: 43833
A18: Engen Lotus Gardens | B18: 2735 | C18: 2556 | D18: 2535 | E18: 2442 | F18: 2474 | G18: 2756 | H18: 2611 | I18: 2800 | J18: 2707 | K18: 2695 | L18: 2618 | M18: 2708
A19: Giba Gorge Main | B19: 16980 | C19: 15556.6 | D19: 15927.6 | E19: 13677.3 | F19: 12351.6 | G19: 11543.6 | H19: 12195.1 | I19: 13528 | J19: 13644.6 | K19: 15166.4 | L19: 15407.487 | M19: 16842.372
A20: Giba Gorge Storage | B20: 15179.5 | C20: 13524.8 | D20: 13861.9 | E20: 11789.7 | F20: 10618.3 | G20: 9819.1 | H20: 10486.9 | I20: 11678.3 | J20: 11941.8 | K20: 13277 | L20: 13346.218 | M20: 14828.668
... A59: Shoprite Newlands | B59: 34135 | C59: 26981 | D59: 26829 | E59: 20433 | F59: 21068 | G59: 16978 | H59: 19291 | I59: 21448 | J59: 20157 | K59: 25054 | L59: 25471 | M59: 31547
A60: Shoprite Thokoza | B60: 20649 | C60: 17891 | D60: 17668 | E60: =15178 -> 15178 | F60: 14023 | G60: 12327 | H60: 13742 | I60: 16094 | J60: 17988 | K60: 20737 | L60: 20655 | M60: 21136
A61: Spring Glade | B61: 19574.9 | C61: 16723.6 | D61: 17808.6 | E61: 15502.2 | F61: 15075 | G61: 13622.2 | H61: 15167.7 | I61: 17455.2 | J61: 18819 | K61: 19760.2 | L61: 19368.5 | M61: 20469.3
A62: SR Morula TF 1 | B62: 10342 | C62: 8891 | D62: 8671 | E62: 7539 | F62: 6938 | G62: 6138 | H62: 6763 | I62: =7916 -> 7916 | J62: 8738 | K62: 10008 | L62: 9999 | M62: 10268
A63: SR Morula TF 1 - Shoprite | B63: 31888.4 | C63: 27677 | D63: 27300 | E63: 23765 | F63: 21915 | G63: 19368 | H63: 21313 | I63: =24908 -> 24908 | J63: 27534 | K63: 31253 | L63: 31179 | M63: 31893
A64: SR Morula TF 2 | B64: 10668.8 | C64: 9218.6 | D64: 9045 | E64: 7797 | F64: 7144.8 | G64: 6299.2 | H64: 6941.6 | I64: =8155.7 -> 8155.7 | J64: 9060 | K64: 10392 | L64: 10393 | M64: 10647
A65: Thakadu Industrial
A66: The Alec | B66: 8222 | C66: 6998 | D66: 7059 | E66: 5574 | F66: 5282 | G66: 4730 | H66: 5256 | I66: 6045 | J66: 7051 | K66: 8056 | L66: 8145 | M66: 8740
A67: Three Peaks | B67: 5698.8 | C67: 5080.8 | D67: 5209.7 | E67: 4357.5 | F67: 3906.6 | G67: 3553 | H67: 3801.5 | I67: 4316 | J67: 4437 | K67: 5034.3 | L67: 5106.1 | M67: 5754.2
A68: TPF Foods | B68: 5045.9 | C68: 4360.2 | D68: 4711.1 | E68: 4084.1 | F68: 4125.1 | G68: 3778.7 | H68: 4137.8 | I68: 4655.4 | J68: 4964.6 | K68: 5199.2 | L68: 4977 | M68: 5354.9
A69: Trouw Nutrition | B69: 15814.1 | C69: 14182.5 | D69: 15127.6 | E69: 13566.2 | F69: 13865.8 | G69: 12963.1 | H69: 14146.2 | I69: 15603.1 | J69: 15929.8 | K69: 16382.7 | L69: 15892.2 | M69: 16746.5
A70: U Save Botrivier | B70: 8111 | C70: 6915 | D70: 6721 | E70: 5701 | F70: 5135 | G70: 4368 | H70: 4517 | I70: 5248 | J70: 5835 | K70: 7211 | L70: 7571 | M70: 8107
A71: Watt Place Rotoflo | B71: 31142 | C71: 26504 | D71: 26827 | E71: 22270 | F71: 21135 | G71: 18949 | H71: 21000 | I71: 24518 | J71: 27252 | K71: 30285 | L71: 29971 | M71: 32254
A72: Zwartop Golf Course | B72: N/A | C72: N/A | D72: N/A | E72: N/A | F72: N/A | G72: N/A | H72: N/A | I72: N/A | J72: N/A | K72: N/A | L72: N/A | M72: N/A
A73: Shoprite Ekhaya | B73: 31534 | C73: 27088 | D73: 25946 | E73: 22097 | F73: 19717 | G73: 17225 | H73: 19287 | I73: 23158 | J73: 26490 | K73: 30317 | L73: 30935 | M73: 31977
A74: Grootpan | B74: 32305 | C74: 29685 | D74: 31046 | E74: 28456 | F74: 28669 | G74: 26032 | H74: 28480 | I74: 31722 | J74: 32846 | K74: 34908 | L74: 33468 | M74: 32717
A75: Roan Foods | B75: 20178 | C75: 17954 | D75: 19150 | E75: 18060 | F75: 18124 | G75: 15908 | H75: 16827 | I75: 19405 | J75: 19981 | K75: 22401 | L75: 20125 | M75: 20771
A76: Engen Kaalfontein | B76: 19301 | C76: 16753 | D76: 16260 | E76: 13800 | F76: 12669 | G76: 11099 | H76: 12207 | I76: 14565.3 | J76: 16481.3 | K76: 18948 | L76: 19155 | M76: 19406
A77: Checkers Lichtenburg | B77: 29390 | C77: 25795 | D77: 25594 | E77: 22145 | F77: 20838 | G77: 18631 | H77: 20290 | I77: 23679 | J77: 26288 | K77: 29851 | L77: 30171 | M77: 30447
A78: Alpine Heath Resort | B78: 32086 | C78: 28761 | D78: 30379 | E78: 30915 | F78: 33245 | G78: 31827 | H78: 31168 | I78: 35166 | J78: 31389 | K78: 31629 | L78: 32213 | M78: 32115
...

Sheet OG
A1: Site Name | B1: Offtake Guarantee | C1: Expected Utilisation% | D1: Age | E1: As-Built kWh | F1: Guaranteed Generation (kWh) | G1: Unavailability kWh | H1: Correct kWh | I1: Actual Generation (kWh) | J1: Shortfall (kWh) | K1: Performance Rate | L1: Notes
A2: Alpine Heath Residential | B2: YES | C2: {=IFERROR(INDEX('Expected Production'!$B$2:$B$79,MATCH(TRIM($A2),INDEX(TRIM('Expected Production'!$A$2:$A$79),0),0)),"Not found")} -> 0.9 | D2: {=_xlfn.IFNA(_xlfn.XLOOKUP(TRIM(A2),TRIM(site_tech_info!$A$2:$A$79),site_tech_info!$W$2:$W$79),"")} -> 1.8179329 | E2: {=IFERROR(SUM(INDEX('Simulated Production'!$B$2:$M$79,MATCH(TRIM($A2),INDEX(TRIM('Simulated Production'!$A$2:$A$79),0),0),0)),"Not found")} -> 63342 | F2: =(Table2[[#This Row],[As-Built kWh]]*Table2[[#This Row],[Expected Utilisation%]])*(1-0.007)^(Table2[[#This Row],[Age]]) -> 56284.423 | G2: =(4681+4732*(9/31)+4546*(10/31)+4620*(3/30)+4991+4762)*(1-0.007)^(Table2[[#This Row],[Age]]) -> 17511.201 | H2: =F2-G2 -> 38773.222 | I2: {=SUMPRODUCT((TRIM(measured[Site Name])=TRIM($A2))*(measured[Date]>=DATE(2025,7,1))*(measured[Date]<=DATE(2026,6,30))*measured[Measured Value (kWh)])} -> 34917.2 | J2: =I2-H2 -> -3856.022 | K2: =(Table2[[#This Row],[Actual Generation (kWh)]]/Table2[[#This Row],[Correct kWh]])*100 -> 90.054935 | L2: The system performed moderately. A few technical issues were experienced , the expected system production was corrected and system restored to normal production.
A3: Checkrite Inanda | B3: YES | C3: {=IFERROR(INDEX('Expected Production'!$B$2:$B$79,MATCH(TRIM($A3),INDEX(TRIM('Expected Production'!$A$2:$A$79),0),0)),"Not found")} -> 0.9 | D3: {=_xlfn.IFNA(_xlfn.XLOOKUP(TRIM(A3),TRIM(site_tech_info!$A$2:$A$79),site_tech_info!$W$2:$W$79),"")} -> 2.329911 | E3: {=IFERROR(SUM(INDEX('Simulated Production'!$B$2:$M$79,MATCH(TRIM($A3),INDEX(TRIM('Simulated Production'!$A$2:$A$79),0),0),0)),"Not found")} -> 94580 | F3: =(Table2[[#This Row],[As-Built kWh]]*Table2[[#This Row],[Expected Utilisation%]])*(1-0.007)^(Table2[[#This Row],[Age]]) -> 83740.17 | G3: =(8100*(1/2)+7806*(1/2))*(1-0.007)^(Table2[[#This Row],[Age]]) -> 7823.8948 | H3: =F3-G3 -> 75916.275 | I3: {=SUMPRODUCT((TRIM(measured[Site Name])=TRIM($A3))*(measured[Date]>=DATE(2025,7,1))*(measured[Date]<=DATE(2026,6,30))*measured[Measured Value (kWh)])} -> 76046.756 | J3: =I3-H3 -> 130.48045 | K3: =(Table2[[#This Row],[Actual Generation (kWh)]]/Table2[[#This Row],[Correct kWh]])*100 -> 100.17187 | L3: The system performed as expected. A few technical issues were experienced during Feb 2026, the expected system production was corrected and system restored to normal production.
A4: Demco | B4: YES | C4: {=IFERROR(INDEX('Expected Production'!$B$2:$B$79,MATCH(TRIM($A4),INDEX(TRIM('Expected Production'!$A$2:$A$79),0),0)),"Not found")} -> 0.8 | D4: {=_xlfn.IFNA(_xlfn.XLOOKUP(TRIM(A4),TRIM(site_tech_info!$A$2:$A$79),site_tech_info!$W$2:$W$79),"")} -> 2.3600274 | E4: {=IFERROR(SUM(INDEX('Simulated Production'!$B$2:$M$79,MATCH(TRIM($A4),INDEX(TRIM('Simulated Production'!$A$2:$A$79),0),0),0)),"Not found")} -> 428379 | F4: =(Table2[[#This Row],[As-Built kWh]]*Table2[[#This Row],[Expected Utilisation%]])*(1-0.007)^(Table2[[#This Row],[Age]]) -> 337068.6 | G4: =(23255*(7/30)+35066*(2/30))*(1-0.007)^(Table2[[#This Row],[Age]]) -> 7636.2489 | H4: =F4-G4 -> 329432.36 | I4: {=SUMPRODUCT((TRIM(measured[Site Name])=TRIM($A4))*(measured[Date]>=DATE(2025,7,1))*(measured[Date]<=DATE(2026,6,30))*measured[Measured Value (kWh)])} -> 166060.42 | J4: =I4-H4 -> -163371.94 | K4: =(Table2[[#This Row],[Actual Generation (kWh)]]/Table2[[#This Row],[Correct kWh]])*100 -> 50.408048 | L4: The system performed as expected. As previously experienced, the site demand is low and the system was not fully utilized.
A5: Golden Spot Resort | B5: YES | C5: {=IFERROR(INDEX('Expected Production'!$B$2:$B$79,MATCH(TRIM($A5),INDEX(TRIM('Expected Production'!$A$2:$A$79),0),0)),"Not found")} -> 0.9 | D5: {=_xlfn.IFNA(_xlfn.XLOOKUP(TRIM(A5),TRIM(site_tech_info!$A$2:$A$79),site_tech_info!$W$2:$W$79),"")} -> 3.4195756 | E5: {=IFERROR(SUM(INDEX('Simulated Production'!$B$2:$M$79,MATCH(TRIM($A5),INDEX(TRIM('Simulated Production'!$A$2:$A$79),0),0),0)),"Not found")} -> 45617 | F5: =(Table2[[#This Row],[As-Built kWh]]*Table2[[#This Row],[Expected Utilisation%]])*(1-0.007)^(Table2[[#This Row],[Age]]) -> 40080.853 | G5: =(4681+3499*(9/31)+2081*(10/31)+4317*(3/30)+4991*(18/31))*(1-0.007)^(Table2[[#This Row],[Age]]) -> 9467.6512 | H5: =F5-G5 -> 30613.202 | I5: {=SUMPRODUCT((TRIM(measured[Site Name])=TRIM($A5))*(measured[Date]>=DATE(2025,7,1))*(measured[Date]<=DATE(2026,6,30))*measured[Measured Value (kWh)])} -> 24341.6 | J5: =I5-H5 -> -6271.6017 | K5: =(Table2[[#This Row],[Actual Generation (kWh)]]/Table2[[#This Row],[Correct kWh]])*100 -> 79.513408
A6: Golden Spot Shops | B6: YES | C6: {=IFERROR(INDEX('Expected Production'!$B$2:$B$79,MATCH(TRIM($A6),INDEX(TRIM('Expected Production'!$A$2:$A$79),0),0)),"Not found")} -> 0.9 | D6: {=_xlfn.IFNA(_xlfn.XLOOKUP(TRIM(A6),TRIM(site_tech_info!$A$2:$A$79),site_tech_info!$W$2:$W$79),"")} -> 3.4223135 | E6: {=IFERROR(SUM(INDEX('Simulated Production'!$B$2:$M$79,MATCH(TRIM($A6),INDEX(TRIM('Simulated Production'!$A$2:$A$79),0),0),0)),"Not found")} -> 40942 | F6: =(Table2[[#This Row],[As-Built kWh]]*Table2[[#This Row],[Expected Utilisation%]])*(1-0.007)^(Table2[[#This Row],[Age]]) -> 35972.526 | G6: =(2974*(24/31)+3147*(2/30))*(1-0.007)^(Table2[[#This Row],[Age]]) -> 2452.5762 | H6: =F6-G6 -> 33519.95 | I6: {=SUMPRODUCT((TRIM(measured[Site Name])=TRIM($A6))*(measured[Date]>=DATE(2025,7,1))*(measured[Date]<=DATE(2026,6,30))*measured[Measured Value (kWh)])} -> 32105.5 | J6: =I6-H6 -> -1414.4498 | K6: =(Table2[[#This Row],[Actual Generation (kWh)]]/Table2[[#This Row],[Correct kWh]])*100 -> 95.780275 | L6: Testing
A7: Hilston Rotoflo | B7: YES | C7: {=IFERROR(INDEX('Expected Production'!$B$2:$B$79,MATCH(TRIM($A7),INDEX(TRIM('Expected Production'!$A$2:$A$79),0),0)),"Not found")} -> 0.85 | D7: {=_xlfn.IFNA(_xlfn.XLOOKUP(TRIM(A7),TRIM(site_tech_info!$A$2:$A$79),site_tech_info!$W$2:$W$79),"")} -> 3.4661191 | E7: {=IFERROR(SUM(INDEX('Simulated Production'!$B$2:$M$79,MATCH(TRIM($A7),INDEX(TRIM('Simulated Production'!$A$2:$A$79),0),0),0)),"Not found")} -> 319608 | F7: =(Table2[[#This Row],[As-Built kWh]]*Table2[[#This Row],[Expected Utilisation%]])*(1-0.007)^(Table2[[#This Row],[Age]]) -> 265132.09 | G7: 0 | H7: =F7-G7 -> 265132.09 | I7: {=SUMPRODUCT((TRIM(measured[Site Name])=TRIM($A7))*(measured[Date]>=DATE(2025,7,1))*(measured[Date]<=DATE(2026,6,30))*measured[Measured Value (kWh)])} -> 254905.02 | J7: =I7-H7 -> -10227.072 | K7: =(Table2[[#This Row],[Actual Generation (kWh)]]/Table2[[#This Row],[Correct kWh]])*100 -> 96.14265 | L7: The system performed as expected. System produced 96% of expected production due to 20 days of closure during December-Jan.
A8: Huis Herfsblaar | B8: YES | C8: {=IFERROR(INDEX('Expected Production'!$B$2:$B$79,MATCH(TRIM($A8),INDEX(TRIM('Expected Production'!$A$2:$A$79),0),0)),"Not found")} -> 0.9 | D8: {=_xlfn.IFNA(_xlfn.XLOOKUP(TRIM(A8),TRIM(site_tech_info!$A$2:$A$79),site_tech_info!$W$2:$W$79),"")} -> 2.3518138 | E8: {=IFERROR(SUM(INDEX('Simulated Production'!$B$2:$M$79,MATCH(TRIM($A8),INDEX(TRIM('Simulated Production'!$A$2:$A$79),0),0),0)),"Not found")} -> 355254 | F8: =(Table2[[#This Row],[As-Built kWh]]*Table2[[#This Row],[Expected Utilisation%]])*(1-0.007)^(Table2[[#This Row],[Age]]) -> 314489.89 | G8: =((22354*(0.5)+26969*(7/31))*(1-0.007)^(Table2[[#This Row],[Age]]))*(1-0.007)^(Table2[[#This Row],[Age]]) -> 16705.582 | H8: =F8-G8 -> 297784.31 | I8: {=SUMPRODUCT((TRIM(measured[Site Name])=TRIM($A8))*(measured[Date]>=DATE(2025,7,1))*(measured[Date]<=DATE(2026,6,30))*measured[Measured Value (kWh)])} -> 271722.18 | J8: =I8-H8 -> -26062.127 | K8: =(Table2[[#This Row],[Actual Generation (kWh)]]/Table2[[#This Row],[Correct kWh]])*100 -> 91.247985 | L8: The system performed as expected. A few technical issues were experienced during July - Aug 2025, the expected system production was corrected and system restored to normal production.
A9: Mdluli | B9: YES | C9: {=IFERROR(INDEX('Expected Production'!$B$2:$B$79,MATCH(TRIM($A9),INDEX(TRIM('Expected Production'!$A$2:$A$79),0),0)),"Not found")} -> 0.8 | D9: {=_xlfn.IFNA(_xlfn.XLOOKUP(TRIM(A9),TRIM(site_tech_info!$A$2:$A$79),site_tech_info!$W$2:$W$79),"")} -> 2.5270363 | E9: {=IFERROR(SUM(INDEX('Simulated Production'!$B$2:$M$79,MATCH(TRIM($A9),INDEX(TRIM('Simulated Production'!$A$2:$A$79),0),0),0)),"Not found")} -> 200775 | F9: =(Table2[[#This Row],[As-Built kWh]]*Table2[[#This Row],[Expected Utilisation%]])*(1-0.007)^(Table2[[#This Row],[Age]]) -> 157793.92 | G9: =('Expected Production'!I33*0.5+'Expected Production'!C33*0.8)*(1-0.007)^(Table2[[#This Row],[Age]]) -> 17807.233 | H9: =F9-G9 -> 139986.69 | I9: {=SUMPRODUCT((TRIM(measured[Site Name])=TRIM($A9))*(measured[Date]>=DATE(2025,7,1))*(measured[Date]<=DATE(2026,6,30))*measured[Measured Value (kWh)])} -> 147166.31 | J9: =I9-H9 -> 7179.6246 | K9: =(Table2[[#This Row],[Actual Generation (kWh)]]/Table2[[#This Row],[Correct kWh]])*100 -> 105.12879 | L9: The system performed as expected. A few technical issues were experienced during July - Aug 2025 and Jan 2026 which limited inverter production during repairs, the expected system production was corrected and system restored to normal production.
A10: Meredale Heights | B10: YES | C10: {=IFERROR(INDEX('Expected Production'!$B$2:$B$79,MATCH(TRIM($A10),INDEX(TRIM('Expected Production'!$A$2:$A$79),0),0)),"Not found")} -> 0.9 | D10: {=_xlfn.IFNA(_xlfn.XLOOKUP(TRIM(A10),TRIM(site_tech_info!$A$2:$A$79),site_tech_info!$W$2:$W$79),"")} -> 2.9404517 | E10: {=IFERROR(SUM(INDEX('Simulated Production'!$B$2:$M$79,MATCH(TRIM($A10),INDEX(TRIM('Simulated Production'!$A$2:$A$79),0),0),0)),"Not found")} -> 73186 | F10: =(Table2[[#This Row],[As-Built kWh]]*Table2[[#This Row],[Expected Utilisation%]])*(1-0.007)^(Table2[[#This Row],[Age]]) -> 64520.828 | G10: 0 | H10: =F10-G10 -> 64520.828 | I10: {=SUMPRODUCT((TRIM(measured[Site Name])=TRIM($A10))*(measured[Date]>=DATE(2025,7,1))*(measured[Date]<=DATE(2026,6,30))*measured[Measured Value (kWh)])} -> 61467.39 | J10: =I10-H10 -> -3053.4382 | K10: =(Table2[[#This Row],[Actual Generation (kWh)]]/Table2[[#This Row],[Correct kWh]])*100 -> 95.267516 | L10: The system performed as expected. As previously experienced, the site demand is low and the system was not fully utilized.
A11: Opal Students | B11: YES | C11: {=IFERROR(INDEX('Expected Production'!$B$2:$B$79,MATCH(TRIM($A11),INDEX(TRIM('Expected Production'!$A$2:$A$79),0),0)),"Not found")} -> 0.9 | D11: {=_xlfn.IFNA(_xlfn.XLOOKUP(TRIM(A11),TRIM(site_tech_info!$A$2:$A$79),site_tech_info!$W$2:$W$79),"")} -> 3.1430527 | E11: {=IFERROR(SUM(INDEX('Simulated Production'!$B$2:$M$79,MATCH(TRIM($A11),INDEX(TRIM('Simulated Production'!$A$2:$A$79),0),0),0)),"Not found")} -> 66026 | F11: =(Table2[[#This Row],[As-Built kWh]]*Table2[[#This Row],[Expected Utilisation%]])*(1-0.007)^(Table2[[#This Row],[Age]]) -> 58125.784 | G11: 0 | H11: =F11-G11 -> 58125.784 | I11: {=SUMPRODUCT((TRIM(measured[Site Name])=TRIM($A11))*(measured[Date]>=DATE(2025,7,1))*(measured[Date]<=DATE(2026,6,30))*measured[Measured Value (kWh)])} -> 46668.7 | J11: =I11-H11 -> -11457.084 | K11: =(Table2[[#This Row],[Actual Generation (kWh)]]/Table2[[#This Row],[Correct kWh]])*100 -> 80.289154 | L11: Testing
A12: Plastiplate | B12: YES | C12: {=IFERROR(INDEX('Expected Production'!$B$2:$B$79,MATCH(TRIM($A12),INDEX(TRIM('Expected Production'!$A$2:$A$79),0),0)),"Not found")} -> 0.75 | D12: {=_xlfn.IFNA(_xlfn.XLOOKUP(TRIM(A12),TRIM(site_tech_info!$A$2:$A$79),site_tech_info!$W$2:$W$79),"")} -> 4.4736482 | E12: {=IFERROR(SUM(INDEX('Simulated Production'!$B$2:$M$79,MATCH(TRIM($A12),INDEX(TRIM('Simulated Production'!$A$2:$A$79),0),0),0)),"Not found")} -> 125072.5 | F12: =(Table2[[#This Row],[As-Built kWh]]*Table2[[#This Row],[Expected Utilisation%]])*(1-0.007)^(Table2[[#This Row],[Age]]) -> 90902.349 | G12: =(5691*0.3*(1-0.007)^(Table2[[#This Row],[Age]]))*(1-0.007)^(Table2[[#This Row],[Age]]) -> 1603.2966 | H12: =F12-G12 -> 89299.052 | I12: {=SUMPRODUCT((TRIM(measured[Site Name])=TRIM($A12))*(measured[Date]>=DATE(2025,7,1))*(measured[Date]<=DATE(2026,6,30))*measured[Measured Value (kWh)])} -> 72438 | J12: =I12-H12 -> -16861.052 | K12: =(Table2[[#This Row],[Actual Generation (kWh)]]/Table2[[#This Row],[Correct kWh]])*100 -> 81.118442 | L12: Testing
A13: Riverside Lodge | B13: YES | C13: {=IFERROR(INDEX('Expected Production'!$B$2:$B$79,MATCH(TRIM($A13),INDEX(TRIM('Expected Production'!$A$2:$A$79),0),0)),"Not found")} -> 0.85 | D13: {=_xlfn.IFNA(_xlfn.XLOOKUP(TRIM(A13),TRIM(site_tech_info!$A$2:$A$79),site_tech_info!$W$2:$W$79),"")} -> 3.4606434 | E13: {=IFERROR(SUM(INDEX('Simulated Production'!$B$2:$M$79,MATCH(TRIM($A13),INDEX(TRIM('Simulated Production'!$A$2:$A$79),0),0),0)),"Not found")} -> 225937 | F13: =(Table2[[#This Row],[As-Built kWh]]*Table2[[#This Row],[Expected Utilisation%]])*(1-0.007)^(Table2[[#This Row],[Age]]) -> 187434.15 | G13: 0 | H13: =F13-G13 -> 187434.15 | I13: {=SUMPRODUCT((TRIM(measured[Site Name])=TRIM($A13))*(measured[Date]>=DATE(2025,7,1))*(measured[Date]<=DATE(2026,6,30))*measured[Measured Value (kWh)])} -> 176720.45 | J13: =I13-H13 -> -10713.7 | K13: =(Table2[[#This Row],[Actual Generation (kWh)]]/Table2[[#This Row],[Correct kWh]])*100 -> 94.284019 | L13: Testing
A14: The Alec | B14: YES | C14: {=IFERROR(INDEX('Expected Production'!$B$2:$B$79,MATCH(TRIM($A14),INDEX(TRIM('Expected Production'!$A$2:$A$79),0),0)),"Not found")} -> 0.925 | D14: {=_xlfn.IFNA(_xlfn.XLOOKUP(TRIM(A14),TRIM(site_tech_info!$A$2:$A$79),site_tech_info!$W$2:$W$79),"")} -> 3.4332649 | E14: {=IFERROR(SUM(INDEX('Simulated Production'!$B$2:$M$79,MATCH(TRIM($A14),INDEX(TRIM('Simulated Production'!$A$2:$A$79),0),0),0)),"Not found")} -> 81158 | F14: =(Table2[[#This Row],[As-Built kWh]]*Table2[[#This Row],[Expected Utilisation%]])*(1-0.007)^(Table2[[#This Row],[Age]]) -> 73282.29 | G14: 0 | H14: =F14-G14 -> 73282.29 | I14: {=SUMPRODUCT((TRIM(measured[Site Name])=TRIM($A14))*(measured[Date]>=DATE(2025,7,1))*(measured[Date]<=DATE(2026,6,30))*measured[Measured Value (kWh)])} -> 56043.3 | J14: =I14-H14 -> -17238.99 | K14: =(Table2[[#This Row],[Actual Generation (kWh)]]/Table2[[#This Row],[Correct kWh]])*100 -> 76.475913 | L14: Testing
A15: Watt Place Rotoflo | B15: YES | C15: {=IFERROR(INDEX('Expected Production'!$B$2:$B$79,MATCH(TRIM($A15),INDEX(TRIM('Expected Production'!$A$2:$A$79),0),0)),"Not found")} -> 0.9 | D15: {=_xlfn.IFNA(_xlfn.XLOOKUP(TRIM(A15),TRIM(site_tech_info!$A$2:$A$79),site_tech_info!$W$2:$W$79),"")} | E15: {=IFERROR(SUM(INDEX('Simulated Production'!$B$2:$M$79,MATCH(TRIM($A15),INDEX(TRIM('Simulated Production'!$A$2:$A$79),0),0),0)),"Not found")} -> 312107 | F15: =(Table2[[#This Row],[As-Built kWh]]*Table2[[#This Row],[Expected Utilisation%]])*(1-0.007)^(Table2[[#This Row],[Age]]) -> #VALUE! | G15: 0 | H15: =F15-G15 -> #VALUE! | I15: {=SUMPRODUCT((TRIM(measured[Site Name])=TRIM($A15))*(measured[Date]>=DATE(2025,7,1))*(measured[Date]<=DATE(2026,6,30))*measured[Measured Value (kWh)])} -> 237169.27 | J15: =I15-H15 -> #VALUE! | K15: =(Table2[[#This Row],[Actual Generation (kWh)]]/Table2[[#This Row],[Correct kWh]])*100 -> #VALUE! | L15: Testing
A16: SR Morula TF 1 | B16: YES | C16: {=IFERROR(INDEX('Expected Production'!$B$2:$B$79,MATCH(TRIM($A16),INDEX(TRIM('Expected Production'!$A$2:$A$79),0),0)),"Not found")} -> 0.9 | D16: {=_xlfn.IFNA(_xlfn.XLOOKUP(TRIM(A16),TRIM(site_tech_info!$A$2:$A$79),site_tech_info!$W$2:$W$79),"")} -> 1.1854894 | E16: {=IFERROR(SUM(INDEX('Simulated Production'!$B$2:$M$79,MATCH(TRIM($A16),INDEX(TRIM('Simulated Production'!$A$2:$A$79),0),0),0)),"Not found")} -> 102211 | F16: =(Table2[[#This Row],[As-Built kWh]]*Table2[[#This Row],[Expected Utilisation%]])*(1-0.007)^(Table2[[#This Row],[Age]]) -> 91227.025 | G16: =(6087*(1-0.007)^(Table2[[#This Row],[Age]]))*(1-0.007)^(Table2[[#This Row],[Age]]) -> 5986.4593 | H16: =F16-G16 -> 85240.566 | I16: {=SUMPRODUCT((TRIM(measured[Site Name])=TRIM($A16))*(measured[Date]>=DATE(2025,7,1))*(measured[Date]<=DATE(2026,6,30))*measured[Measured Value (kWh)])} -> 77775.48 | J16: =I16-H16 -> -7465.0859 | K16: =(Table2[[#This Row],[Actual Generation (kWh)]]/Table2[[#This Row],[Correct kWh]])*100 -> 91.242332 | L16: Testing
A17: SR Morula TF 2 | B17: YES | C17: {=IFERROR(INDEX('Expected Production'!$B$2:$B$79,MATCH(TRIM($A17),INDEX(TRIM('Expected Production'!$A$2:$A$79),0),0)),"Not found")} -> 0.9 | D17: {=_xlfn.IFNA(_xlfn.XLOOKUP(TRIM(A17),TRIM(site_tech_info!$A$2:$A$79),site_tech_info!$W$2:$W$79),"")} -> 1.1854894 | E17: {=IFERROR(SUM(INDEX('Simulated Production'!$B$2:$M$79,MATCH(TRIM($A17),INDEX(TRIM('Simulated Production'!$A$2:$A$79),0),0),0)),"Not found")} -> 105762.7 | F17: =(Table2[[#This Row],[As-Built kWh]]*Table2[[#This Row],[Expected Utilisation%]])*(1-0.007)^(Table2[[#This Row],[Age]]) -> 94397.046 | G17: =(6247*(1-0.007)^(Table2[[#This Row],[Age]]))*(1-0.007)^(Table2[[#This Row],[Age]]) -> 6143.8165 | H17: =F17-G17 -> 88253.23 | I17: {=SUMPRODUCT((TRIM(measured[Site Name])=TRIM($A17))*(measured[Date]>=DATE(2025,7,1))*(measured[Date]<=DATE(2026,6,30))*measured[Measured Value (kWh)])} -> 78264.64 | J17: =I17-H17 -> -9988.5897 | K17: =(Table2[[#This Row],[Actual Generation (kWh)]]/Table2[[#This Row],[Correct kWh]])*100 -> 88.681899 | L17: Testing
A18: Olievenhoutbosch 1 | B18: YES | C18: {=IFERROR(INDEX('Expected Production'!$B$2:$B$79,MATCH(TRIM($A18),INDEX(TRIM('Expected Production'!$A$2:$A$79),0),0)),"Not found")} -> 0.9 | D18: {=_xlfn.IFNA(_xlfn.XLOOKUP(TRIM(A18),TRIM(site_tech_info!$A$2:$A$79),site_tech_info!$W$2:$W$79),"")} -> 1.0896646 | E18: {=IFERROR(SUM(INDEX('Simulated Production'!$B$2:$M$79,MATCH(TRIM($A18),INDEX(TRIM('Simulated Production'!$A$2:$A$79),0),0),0)),"Not found")} -> 524973 | F18: =(Table2[[#This Row],[As-Built kWh]]*Table2[[#This Row],[Expected Utilisation%]])*(1-0.007)^(Table2[[#This Row],[Age]]) -> 468872.95 | G18: =(31229+36815+40778+47657*(5/30))*(1-0.007)^(Table2[[#This Row],[Age]]) -> 115874.47 | H18: =F18-G18 -> 352998.48 | I18: {=SUMPRODUCT((TRIM(measured[Site Name])=TRIM($A18))*(measured[Date]>=DATE(2025,7,1))*(measured[Date]<=DATE(2026,6,30))*measured[Measured Value (kWh)])} -> 300497.96 | J18: =I18-H18 -> -52500.526 | K18: =(Table2[[#This Row],[Actual Generation (kWh)]]/Table2[[#This Row],[Correct kWh]])*100 -> 85.127266 | L18: Testing
A19: Olievenhoutbosch 2 | B19: YES | C19: {=IFERROR(INDEX('Expected Production'!$B$2:$B$79,MATCH(TRIM($A19),INDEX(TRIM('Expected Production'!$A$2:$A$79),0),0)),"Not found")} -> 0.9 | D19: {=_xlfn.IFNA(_xlfn.XLOOKUP(TRIM(A19),TRIM(site_tech_info!$A$2:$A$79),site_tech_info!$W$2:$W$79),"")} -> 1.0896646 | E19: {=IFERROR(SUM(INDEX('Simulated Production'!$B$2:$M$79,MATCH(TRIM($A19),INDEX(TRIM('Simulated Production'!$A$2:$A$79),0),0),0)),"Not found")} -> 138565 | F19: =(Table2[[#This Row],[As-Built kWh]]*Table2[[#This Row],[Expected Utilisation%]])*(1-0.007)^(Table2[[#This Row],[Age]]) -> 123757.57 | G19: =(8307+9721+10756+12191*(5/30))*(1-0.007)^(Table2[[#This Row],[Age]]) -> 30580.855 | H19: =F19-G19 -> 93176.711 | I19: {=SUMPRODUCT((TRIM(measured[Site Name])=TRIM($A19))*(measured[Date]>=DATE(2025,7,1))*(measured[Date]<=DATE(2026,6,30))*measured[Measured Value (kWh)])} -> 81974.633 | J19: =I19-H19 -> -11202.079 | K19: =(Table2[[#This Row],[Actual Generation (kWh)]]/Table2[[#This Row],[Correct kWh]])*100 -> 87.977598 | L19: Testing
A20: IPID - Floor 6 | B20: YES | C20: {=IFERROR(INDEX('Expected Production'!$B$2:$B$79,MATCH(TRIM($A20),INDEX(TRIM('Expected Production'!$A$2:$A$79),0),0)),"Not found")} -> 0.9 | D20: {=_xlfn.IFNA(_xlfn.XLOOKUP(TRIM(A20),TRIM(site_tech_info!$A$2:$A$79),site_tech_info!$W$2:$W$79),"")} -> 1.0622861 | E20: {=IFERROR(SUM(INDEX('Simulated Production'!$B$2:$M$79,MATCH(TRIM($A20),INDEX(TRIM('Simulated Production'!$A$2:$A$79),0),0),0)),"Not found")} -> 89076 | F20: =(Table2[[#This Row],[As-Built kWh]]*Table2[[#This Row],[Expected Utilisation%]])*(1-0.007)^(Table2[[#This Row],[Age]]) -> 79572.398 | G20: =(5785+6585+7019+7479+7553+7553*(3/30))*(1-0.007)^(Table2[[#This Row],[Age]]) -> 34914.786 | H20: =F20-G20 -> 44657.612 | I20: {=SUMPRODUCT((TRIM(measured[Site Name])=TRIM($A20))*(measured[Date]>=DATE(2025,7,1))*(measured[Date]<=DATE(2026,6,30))*measured[Measured Value (kWh)])} -> 33061.7 | J20: =I20-H20 -> -11595.912 | K20: =(Table2[[#This Row],[Actual Generation (kWh)]]/Table2[[#This Row],[Correct kWh]])*100 -> 74.03374 | L20: Testing
A21: IPID - Floor 4 | B21: YES | C21: {=IFERROR(INDEX('Expected Production'!$B$2:$B$79,MATCH(TRIM($A21),INDEX(TRIM('Expected Production'!$A$2:$A$79),0),0)),"Not found")} -> 0.9 | D21: {=_xlfn.IFNA(_xlfn.XLOOKUP(TRIM(A21),TRIM(site_tech_info!$A$2:$A$79),site_tech_info!$W$2:$W$79),"")} -> 1.0622861 | E21: {=IFERROR(SUM(INDEX('Simulated Production'!$B$2:$M$79,MATCH(TRIM($A21),INDEX(TRIM('Simulated Production'!$A$2:$A$79),0),0),0)),"Not found")} -> 89076 | F21: =(Table2[[#This Row],[As-Built kWh]]*Table2[[#This Row],[Expected Utilisation%]])*(1-0.007)^(Table2[[#This Row],[Age]]) -> 79572.398 | G21: =(5785+6585+7019+7479+7553+7553*(3/30))*(1-0.007)^(Table2[[#This Row],[Age]]) -> 34914.786 | H21: =F21-G21 -> 44657.612 | I21: {=SUMPRODUCT((TRIM(measured[Site Name])=TRIM($A21))*(measured[Date]>=DATE(2025,7,1))*(measured[Date]<=DATE(2026,6,30))*measured[Measured Value (kWh)])} -> 47460.3 | J21: =I21-H21 -> 2802.6883 | K21: =(Table2[[#This Row],[Actual Generation (kWh)]]/Table2[[#This Row],[Correct kWh]])*100 -> 106.27595 | L21: Testing
A22: Engen Lotus Gardens | B22: YES | C22: {=IFERROR(INDEX('Expected Production'!$B$2:$B$79,MATCH(TRIM($A22),INDEX(TRIM('Expected Production'!$A$2:$A$79),0),0)),"Not found")} -> 0.9 | D22: {=_xlfn.IFNA(_xlfn.XLOOKUP(TRIM(A22),TRIM(site_tech_info!$A$2:$A$79),site_tech_info!$W$2:$W$79),"")} -> 1.0157426 | E22: {=IFERROR(SUM(INDEX('Simulated Production'!$B$2:$M$79,MATCH(TRIM($A22),INDEX(TRIM('Simulated Production'!$A$2:$A$79),0),0),0)),"Not found")} -> 31637 | F22: =(Table2[[#This Row],[As-Built kWh]]*Table2[[#This Row],[Expected Utilisation%]])*(1-0.007)^(Table2[[#This Row],[Age]]) -> 28270.86 | G22: =(2350+2520+2436+2426+2356+2437)*(1-0.007)^(Table2[[#This Row],[Age]]) -> 14421.73 | H22: =F22-G22 -> 13849.13 | I22: {=SUMPRODUCT((TRIM(measured[Site Name])=TRIM($A22))*(measured[Date]>=DATE(2025,7,1))*(measured[Date]<=DATE(2026,6,30))*measured[Measured Value (kWh)])} -> 17882.44 | J22: =I22-H22 -> 4033.3097 | K22: =(Table2[[#This Row],[Actual Generation (kWh)]]/Table2[[#This Row],[Correct kWh]])*100 -> 129.1232 | L22: Testing
A23: Engen Kaalfontein | B23: YES | C23: {=IFERROR(INDEX('Expected Production'!$B$2:$B$79,MATCH(TRIM($A23),INDEX(TRIM('Expected Production'!$A$2:$A$79),0),0)),"Not found")} -> 0.9 | D23: {=_xlfn.IFNA(_xlfn.XLOOKUP(TRIM(A23),TRIM(site_tech_info!$A$2:$A$79),site_tech_info!$W$2:$W$79),"")} -> 0.43805613 | E23: {=IFERROR(SUM(INDEX('Simulated Production'!$B$2:$M$79,MATCH(TRIM($A23),INDEX(TRIM('Simulated Production'!$A$2:$A$79),0),0),0)),"Not found")} -> 190644.6 | F23: =(Table2[[#This Row],[As-Built kWh]]*Table2[[#This Row],[Expected Utilisation%]])*(1-0.007)^(Table2[[#This Row],[Age]]) -> 171052.97 | G23: 171487.77 | H23: =F23-G23 -> -434.79869 | I23: {=SUMPRODUCT((TRIM(measured[Site Name])=TRIM($A23))*(measured[Date]>=DATE(2025,7,1))*(measured[Date]<=DATE(2026,6,30))*measured[Measured Value (kWh)])} -> 10169 | J23: =I23-H23 -> 10603.799 | K23: =(Table2[[#This Row],[Actual Generation (kWh)]]/Table2[[#This Row],[Correct kWh]])*100 -> -2338.7835 | L23: Testing
A24: Alpine Heath Resort | B24: YES | C24: {=IFERROR(INDEX('Expected Production'!$B$2:$B$79,MATCH(TRIM($A24),INDEX(TRIM('Expected Production'!$A$2:$A$79),0),0)),"Not found")} -> 0.9 | D24: {=_xlfn.IFNA(_xlfn.XLOOKUP(TRIM(A24),TRIM(site_tech_info!$A$2:$A$79),site_tech_info!$W$2:$W$79),"")} -> 0.49828884 | E24: {=IFERROR(SUM(INDEX('Simulated Production'!$B$2:$M$79,MATCH(TRIM($A24),INDEX(TRIM('Simulated Production'!$A$2:$A$79),0),0),0)),"Not found")} -> 380893 | F24: =(Table2[[#This Row],[As-Built kWh]]*Table2[[#This Row],[Expected Utilisation%]])*(1-0.007)^(Table2[[#This Row],[Age]]) -> 341605.89 | G24: =(28051+31649+28250+28466+28992+28904+28877+25885+27341+27824*(28/30))*(1-0.007)^(Table2[[#This Row],[Age]]) -> 281397.37 | H24: =F24-G24 -> 60208.517 | I24: {=SUMPRODUCT((TRIM(measured[Site Name])=TRIM($A24))*(measured[Date]>=DATE(2025,7,1))*(measured[Date]<=DATE(2026,6,30))*measured[Measured Value (kWh)])} -> 53212.2 | J24: =I24-H24 -> -6996.317 | K24: =(Table2[[#This Row],[Actual Generation (kWh)]]/Table2[[#This Row],[Correct kWh]])*100 -> 88.379855 | L24: Testing

Sheet measured
A1: Site Name | B1: Date | C1: Measured Value (kWh)
A2: 21 Melrose | B2: 45292 | C2: 1815
A3: 21 Melrose | B3: 45323 | C3: 2295
A4: 21 Melrose | B4: 45352 | C4: 2474
A5: 21 Melrose | B5: 45383 | C5: 2136
A6: 21 Melrose | B6: 45413 | C6: 2212
A7: 21 Melrose | B7: 45444 | C7: 1863
A8: 21 Melrose | B8: 45474 | C8: 1943
A9: 21 Melrose | B9: 45505 | C9: 1710
A10: 21 Melrose | B10: 45536 | C10: 1579
A11: 21 Melrose | B11: 45566 | C11: 1593
A12: 21 Melrose | B12: 45597 | C12: 1794
A13: 21 Melrose | B13: 45627 | C13: 1794
... A34: 21 Melrose | B34: 46266 | C34: 1161.6
A35: 21 Melrose | B35: 46296
A36: 21 Melrose | B36: 46327
A37: 21 Melrose | B37: 46357
A38: African Global Plastics | B38: 45292 | C38: 23024
A39: African Global Plastics | B39: 45323 | C39: 23235
A40: African Global Plastics | B40: 45352 | C40: 23235
A41: African Global Plastics | B41: 45383 | C41: 19307
A42: African Global Plastics | B42: 45413 | C42: 18418
A43: African Global Plastics | B43: 45444 | C43: 15949
A44: African Global Plastics | B44: 45474 | C44: 17174
A45: African Global Plastics | B45: 45505 | C45: 13588
A46: African Global Plastics | B46: 45536 | C46: 20254
A47: African Global Plastics | B47: 45566 | C47: 27693
A48: African Global Plastics | B48: 45597 | C48: 24041
A49: African Global Plastics | B49: 45627 | C49: 25076
... A70: African Global Plastics | B70: 46266 | C70: 12622.016
A71: African Global Plastics | B71: 46296
A72: African Global Plastics | B72: 46327
A73: African Global Plastics | B73: 46357
A74: Alpine Heath Residential | B74: 45292
A75: Alpine Heath Residential | B75: 45323
A76: Alpine Heath Residential | B76: 45352
A77: Alpine Heath Residential | B77: 45383
A78: Alpine Heath Residential | B78: 45413
A79: Alpine Heath Residential | B79: 45444
A80: Alpine Heath Residential | B80: 45474
...

Sheet Expected Production
A1: Site Name | B1: Expected Utilisation% | C1: Jan | D1: Feb | E1: Mar | F1: Apr | G1: May | H1: Jun | I1: Jul | J1: Aug | K1: Sep | L1: Oct | M1: Nov | N1: Dec
A2: 21 Melrose | B2: 0.9 | C2: =Table4[[#This Row],[Jan]]*$B2 -> 2370.6 | D2: =Table4[[#This Row],[Feb]]*$B2 -> 2680.2 | E2: =Table4[[#This Row],[Mar]]*$B2 -> 2183.4 | F2: =Table4[[#This Row],[Apr]]*$B2 -> 1873.8 | G2: =Table4[[#This Row],[May]]*$B2 -> 1822.5 | H2: =Table4[[#This Row],[Jun]]*$B2 -> 1629 | I2: =Table4[[#This Row],[Jul]]*$B2 -> 1814.4 | J2: =Table4[[#This Row],[Aug]]*$B2 -> 2116.8 | K2: =Table4[[#This Row],[Sep]]*$B2 -> 2275.2 | L2: =Table4[[#This Row],[Oct]]*$B2 -> 2407.5 | M2: =Table4[[#This Row],[Nov]]*$B2 -> 2356.2 | N2: =Table4[[#This Row],[Dec]]*$B2 -> 2482.2 | Q2: 2027
A3: African Global Plastics | B3: 0.85 | C3: =Table4[[#This Row],[Jan]]*$B3 -> 22515.905 | D3: =Table4[[#This Row],[Feb]]*$B3 -> 19786.13 | E3: =Table4[[#This Row],[Mar]]*$B3 -> 20148.4 | F3: =Table4[[#This Row],[Apr]]*$B3 -> 16764.89 | G3: =Table4[[#This Row],[May]]*$B3 -> 15972.095 | H3: =Table4[[#This Row],[Jun]]*$B3 -> 14367.21 | I3: =Table4[[#This Row],[Jul]]*$B3 -> 15907.665 | J3: =Table4[[#This Row],[Aug]]*$B3 -> 18527.365 | K3: =Table4[[#This Row],[Sep]]*$B3 -> 20404.335 | L3: =Table4[[#This Row],[Oct]]*$B3 -> 22320.66 | M3: =Table4[[#This Row],[Nov]]*$B3 -> 22520.665 | N3: =Table4[[#This Row],[Dec]]*$B3 -> 23777.985
A4: Alpine Heath Residential | B4: 0.9 | C4: =Table4[[#This Row],[Jan]]*$B4 -> 4801.5 | D4: =Table4[[#This Row],[Feb]]*$B4 -> 4303.8 | E4: =Table4[[#This Row],[Mar]]*$B4 -> 4545.9 | F4: =Table4[[#This Row],[Apr]]*$B4 -> 4619.7 | G4: =Table4[[#This Row],[May]]*$B4 -> 4990.5 | H4: =Table4[[#This Row],[Jun]]*$B4 -> 4761.9 | I4: =Table4[[#This Row],[Jul]]*$B4 -> 4680.9 | J4: =Table4[[#This Row],[Aug]]*$B4 -> 5249.7 | K4: =Table4[[#This Row],[Sep]]*$B4 -> 4694.4 | L4: =Table4[[#This Row],[Oct]]*$B4 -> 4732.2 | M4: =Table4[[#This Row],[Nov]]*$B4 -> 4822.2 | N4: =Table4[[#This Row],[Dec]]*$B4 -> 4805.1
A5: Bendstore Plaza Shops | B5: 0.85 | C5: =Table4[[#This Row],[Jan]]*$B5 -> 16262.2 | D5: =Table4[[#This Row],[Feb]]*$B5 -> 13986.75 | E5: =Table4[[#This Row],[Mar]]*$B5 -> 15463.2 | F5: =Table4[[#This Row],[Apr]]*$B5 -> 14886.05 | G5: =Table4[[#This Row],[May]]*$B5 -> 14411.75 | H5: =Table4[[#This Row],[Jun]]*$B5 -> 13050.05 | I5: =Table4[[#This Row],[Jul]]*$B5 -> 13735.15 | J5: =Table4[[#This Row],[Aug]]*$B5 -> 15350.15 | K5: =Table4[[#This Row],[Sep]]*$B5 -> 15431.75 | L5: =Table4[[#This Row],[Oct]]*$B5 -> 14821.45 | M5: =Table4[[#This Row],[Nov]]*$B5 -> 14695.65 | N5: =Table4[[#This Row],[Dec]]*$B5 -> 16154.25
A6: Bendstore Spar | B6: 0.9 | C6: =Table4[[#This Row],[Jan]]*$B6 -> 51314.735 | D6: =Table4[[#This Row],[Feb]]*$B6 -> 44103.291 | E6: =Table4[[#This Row],[Mar]]*$B6 -> 48739.27 | F6: =Table4[[#This Row],[Apr]]*$B6 -> 46849.899 | G6: =Table4[[#This Row],[May]]*$B6 -> 45273.233 | H6: =Table4[[#This Row],[Jun]]*$B6 -> 40943.972 | I6: =Table4[[#This Row],[Jul]]*$B6 -> 43112.803 | J6: =Table4[[#This Row],[Aug]]*$B6 -> 48266.503 | K6: =Table4[[#This Row],[Sep]]*$B6 -> 48602.891 | L6: =Table4[[#This Row],[Oct]]*$B6 -> 46748.911 | M6: =Table4[[#This Row],[Nov]]*$B6 -> 46388.482 | N6: =Table4[[#This Row],[Dec]]*$B6 -> 50640.311
A7: Beyerskloof | B7: 0.9 | C7: =Table4[[#This Row],[Jan]]*$B7 -> 13787.1 | D7: =Table4[[#This Row],[Feb]]*$B7 -> 11359.8 | E7: =Table4[[#This Row],[Mar]]*$B7 -> 10881 | F7: =Table4[[#This Row],[Apr]]*$B7 -> 7828.2 | G7: =Table4[[#This Row],[May]]*$B7 -> 5953.5 | H7: =Table4[[#This Row],[Jun]]*$B7 -> 5166 | I7: =Table4[[#This Row],[Jul]]*$B7 -> 5564.7 | J7: =Table4[[#This Row],[Aug]]*$B7 -> 6960.6 | K7: =Table4[[#This Row],[Sep]]*$B7 -> 8946 | L7: =Table4[[#This Row],[Oct]]*$B7 -> 11314.8 | M7: =Table4[[#This Row],[Nov]]*$B7 -> 12713.4 | N7: =Table4[[#This Row],[Dec]]*$B7 -> 13878.9
A8: BP Parys | B8: 0.9 | C8: =Table4[[#This Row],[Jan]]*$B8 -> 8151.3 | D8: =Table4[[#This Row],[Feb]]*$B8 -> 7235.1 | E8: =Table4[[#This Row],[Mar]]*$B8 -> 7075.8 | F8: =Table4[[#This Row],[Apr]]*$B8 -> 5754.6 | G8: =Table4[[#This Row],[May]]*$B8 -> 5424.3 | H8: =Table4[[#This Row],[Jun]]*$B8 -> 4787.1 | I8: =Table4[[#This Row],[Jul]]*$B8 -> 5360.4 | J8: =Table4[[#This Row],[Aug]]*$B8 -> 6363 | K8: =Table4[[#This Row],[Sep]]*$B8 -> 7218.9 | L8: =Table4[[#This Row],[Oct]]*$B8 -> 7839 | M8: =Table4[[#This Row],[Nov]]*$B8 -> 8191.8 | N8: =Table4[[#This Row],[Dec]]*$B8 -> 8227.8
A9: Buffalo Rock | B9: 0.9 | C9: =Table4[[#This Row],[Jan]]*$B9 -> 2202.3 | D9: =Table4[[#This Row],[Feb]]*$B9 -> 1983.6 | E9: =Table4[[#This Row],[Mar]]*$B9 -> 2127.6 | F9: =Table4[[#This Row],[Apr]]*$B9 -> 1767.6 | G9: =Table4[[#This Row],[May]]*$B9 -> 1631.7 | H9: =Table4[[#This Row],[Jun]]*$B9 -> 1480.5 | I9: =Table4[[#This Row],[Jul]]*$B9 -> 1612.8 | J9: =Table4[[#This Row],[Aug]]*$B9 -> 1764 | K9: =Table4[[#This Row],[Sep]]*$B9 -> 1868.4 | L9: =Table4[[#This Row],[Oct]]*$B9 -> 1900.8 | M9: =Table4[[#This Row],[Nov]]*$B9 -> 1835.1 | N9: =Table4[[#This Row],[Dec]]*$B9 -> 1986.3
A10: Checkers De Aar | B10: 0.9 | C10: =Table4[[#This Row],[Jan]]*$B10 -> 26689.5 | D10: =Table4[[#This Row],[Feb]]*$B10 -> 20674.8 | E10: =Table4[[#This Row],[Mar]]*$B10 -> 20095.2 | F10: =Table4[[#This Row],[Apr]]*$B10 -> 16286.4 | G10: =Table4[[#This Row],[May]]*$B10 -> 13518.9 | H10: =Table4[[#This Row],[Jun]]*$B10 -> 11864.7 | I10: =Table4[[#This Row],[Jul]]*$B10 -> 13589.1 | J10: =Table4[[#This Row],[Aug]]*$B10 -> 17109 | K10: =Table4[[#This Row],[Sep]]*$B10 -> 19506.6 | L10: =Table4[[#This Row],[Oct]]*$B10 -> 24081.3 | M10: =Table4[[#This Row],[Nov]]*$B10 -> 25889.4 | N10: =Table4[[#This Row],[Dec]]*$B10 -> 27992.7
A11: Checkers Silverlakes Gen | B11: 0.9 | C11: =Table4[[#This Row],[Jan]]*$B11 -> 21105 | D11: =Table4[[#This Row],[Feb]]*$B11 -> 18220.5 | E11: =Table4[[#This Row],[Mar]]*$B11 -> 18368.1 | F11: =Table4[[#This Row],[Apr]]*$B11 -> 15103.8 | G11: =Table4[[#This Row],[May]]*$B11 -> 14130 | H11: =Table4[[#This Row],[Jun]]*$B11 -> 12619.8 | I11: =Table4[[#This Row],[Jul]]*$B11 -> 14002.2 | J11: =Table4[[#This Row],[Aug]]*$B11 -> 16641.9 | K11: =Table4[[#This Row],[Sep]]*$B11 -> 18626.4 | L11: =Table4[[#This Row],[Oct]]*$B11 -> 20503.8 | M11: =Table4[[#This Row],[Nov]]*$B11 -> 20601 | N11: =Table4[[#This Row],[Dec]]*$B11 -> 22024.8
A12: Checkers Silverlakes No Gen | B12: 0.9 | C12: =Table4[[#This Row],[Jan]]*$B12 -> 21105 | D12: =Table4[[#This Row],[Feb]]*$B12 -> 18220.5 | E12: =Table4[[#This Row],[Mar]]*$B12 -> 18368.1 | F12: =Table4[[#This Row],[Apr]]*$B12 -> 15103.8 | G12: =Table4[[#This Row],[May]]*$B12 -> 14130 | H12: =Table4[[#This Row],[Jun]]*$B12 -> 12619.8 | I12: =Table4[[#This Row],[Jul]]*$B12 -> 14002.2 | J12: =Table4[[#This Row],[Aug]]*$B12 -> 16641.9 | K12: =Table4[[#This Row],[Sep]]*$B12 -> 18626.4 | L12: =Table4[[#This Row],[Oct]]*$B12 -> 20503.8 | M12: =Table4[[#This Row],[Nov]]*$B12 -> 20601 | N12: =Table4[[#This Row],[Dec]]*$B12 -> 22024.8
A13: Checkrite Inanda | B13: 0.9 | C13: =Table4[[#This Row],[Jan]]*$B13 -> 8664.3 | D13: =Table4[[#This Row],[Feb]]*$B13 -> 8100 | E13: =Table4[[#This Row],[Mar]]*$B13 -> 7805.7 | F13: =Table4[[#This Row],[Apr]]*$B13 -> 6534 | G13: =Table4[[#This Row],[May]]*$B13 -> 5592.6 | H13: =Table4[[#This Row],[Jun]]*$B13 -> 5059.8 | I13: =Table4[[#This Row],[Jul]]*$B13 -> 5372.1 | J13: =Table4[[#This Row],[Aug]]*$B13 -> 6485.4 | K13: =Table4[[#This Row],[Sep]]*$B13 -> 6914.7 | L13: =Table4[[#This Row],[Oct]]*$B13 -> 8033.4 | M13: =Table4[[#This Row],[Nov]]*$B13 -> 8012.7 | N13: =Table4[[#This Row],[Dec]]*$B13 -> 8547.3
A14: Club Houghton | B14: 0.9 | C14: =Table4[[#This Row],[Jan]]*$B14 -> 5767.2 | D14: =Table4[[#This Row],[Feb]]*$B14 -> 4828.5 | E14: =Table4[[#This Row],[Mar]]*$B14 -> 4913.1 | F14: =Table4[[#This Row],[Apr]]*$B14 -> 4149.9 | G14: =Table4[[#This Row],[May]]*$B14 -> 3937.5 | H14: =Table4[[#This Row],[Jun]]*$B14 -> 3463.2 | I14: =Table4[[#This Row],[Jul]]*$B14 -> 3874.5 | J14: =Table4[[#This Row],[Aug]]*$B14 -> 4560.3 | K14: =Table4[[#This Row],[Sep]]*$B14 -> 5033.7 | L14: =Table4[[#This Row],[Oct]]*$B14 -> 5613.3 | M14: =Table4[[#This Row],[Nov]]*$B14 -> 5712.3 | N14: =Table4[[#This Row],[Dec]]*$B14 -> 6027.3
... A64: SR Morula TF 2 | B64: 0.9 | C64: =Table4[[#This Row],[Jan]]*$B64 -> 9601.92 | D64: =Table4[[#This Row],[Feb]]*$B64 -> 8296.74 | E64: =Table4[[#This Row],[Mar]]*$B64 -> 8140.5 | F64: =Table4[[#This Row],[Apr]]*$B64 -> 7017.3 | G64: =Table4[[#This Row],[May]]*$B64 -> 6430.32 | H64: =Table4[[#This Row],[Jun]]*$B64 -> 5669.28 | I64: =Table4[[#This Row],[Jul]]*$B64 -> 6247.44 | J64: =Table4[[#This Row],[Aug]]*$B64 -> 7340.13 | K64: =Table4[[#This Row],[Sep]]*$B64 -> 8154 | L64: =Table4[[#This Row],[Oct]]*$B64 -> 9352.8 | M64: =Table4[[#This Row],[Nov]]*$B64 -> 9353.7 | N64: =Table4[[#This Row],[Dec]]*$B64 -> 9582.3
