Workbook
Name DC_CCC: 'SANS Data'!$B$68:$D$82
Name DC_Method: 'SANS Data'!$B$67:$D$67
Name DC_Prot: 'SANS Data'!$G$68:$G$99
Name DC_R: 'SANS Data'!$E$68:$E$82
Name DC_Size: 'SANS Data'!$A$68:$A$82
Name DC_Types: 'SANS Data'!$A$61:$A$64
Name DC_TypeTbl: 'SANS Data'!$A$61:$G$64
Name Dev_t: 'SANS Data'!$X$42:$X$44
Name Dev_Type: 'SANS Data'!$W$42:$W$44
Name Fac_Al: 'SANS Data'!$B$5
Name Fac_AlmV: 'SANS Data'!$B$6
Name Fac_BrkSF: 'SANS Data'!$X$52
Name Fac_CuAlpha: 'SANS Data'!$B$56
Name Fac_DCDerate: 'SANS Data'!$B$54
Name Fac_DCMaxRuns: 'SANS Data'!$B$57
Name Fac_DCMaxV: 'SANS Data'!$B$58
Name Fac_DCTemp: 'SANS Data'!$B$55
Name Fac_Derate: 'SANS Data'!$B$7
Name Fac_MaxRuns: 'SANS Data'!$B$9
Name Fac_MaxSize: 'SANS Data'!$B$10
Name Fac_Rubber: 'SANS Data'!$B$11
Name Fac_Trefoil: 'Cable Data'!$B$28
Name Fac_VdLimit: 'SANS Data'!$B$8
Name Fac_XLPE: 'SANS Data'!$B$4
Name Grp_Cg: 'SANS Data'!$Z$14:$AE$29
Name Grp_Eff: 'SANS Data'!$AH$14:$AM$29
Name Grp_Key: 'SANS Data'!$W$14:$W$29
Name Grp_N: 'SANS Data'!$Z$13:$AE$13
Name Ir_Min: 'SANS Data'!$X$48:$X$50
Name Ir_Step: 'SANS Data'!$Y$48:$Y$50
Name Ir_Type: 'SANS Data'!$W$48:$W$50
Name List_Spacing: 'SANS Data'!$AO$14:$AO$20
Name Map_Cores: 'SANS Data'!$T$14:$V$18
Name Map_Install: 'SANS Data'!$Q$14:$S$21
Name SANS_Breaker: 'SANS Data'!$O$14:$O$42
Name SANS_BrkType: 'SANS Data'!$P$14:$P$42
Name SANS_CCC: 'Cable Data'!$B$7:$K$25
Name SANS_CCC_Rub: 'Cable Data'!$L$7:$U$25
Name SANS_CCCkey: 'Cable Data'!$B$6:$K$6
Name SANS_mV: 'Cable Data'!$W$7:$AD$25
Name SANS_Size: 'Cable Data'!$A$7:$A$25
Name SC_k: 'SANS Data'!$Z$33:$Z$38
Name SC_kKey: 'SANS Data'!$W$33:$W$38

Sheet Cables Sizes
D1: =UPPER(IF($R$1="","Project Name",$R$1))&CHAR(10)&"AC POWER CABLE SCHEDULE" -> PROJECT NAME AC POWER CABLE SCHEDULE | P1: Project Name | V1: Date
P2: Project Number | V2: Revision | X2: 00
P3: Document Number | V3: Designed
P4: Address | V4: Checked
P5: Coordinates | V5: Approved
P6: Client | V6: Rev. Description
A8: AC CABLES – SIZING TO SANS 10142-1 / IEC 60364-5-52
B10: AC Cable Inputs | P10: Calculated Outputs (SANS 10142-1) | AC10: Calculation helpers – do not edit
A11: # | B11: Design Current Ib (A) | C11: Termination Point A | D11: Termination Point B | E11: Installation Method | F11: Cable Distance (m) | G11: System Voltage (V) | H11: Cable Protection | I11: Conductor Insulation | J11: Conductor (Cu/Al) | K11: Cores | L11: Other Derating Ca (ambient/soil) (blank = default) | M11: Spacing between runs (blank = touching) | N11: Fault Level Ik (kA) (blank = not checked) | O11: Fault Clearing Time t (s) (blank = device default) | P11: Cables in Parallel | Q11: Recommended Size (mm2) | R11: Grouping Factor Cg (runs) | S11: Cable CCC – total (A) | T11: Voltage Drop (V) | U11: Voltage Drop (%) | V11: Circuit Breaker Size (A) | W11: Breaker Type | X11: Trip Setting Ir (A) | Y11: Earth Conductor (mm2) | Z11: Cable SC Withstand per run (kA) | AA11: Status | AC11: Inputs OK | AD11: Ref Method | AE11: Loaded | AF11: CCC col | AG11: Insul fac | AH11: Cu/Al fac | AI11: Ca used | AJ11: Breaker raw | AK11: Req base CCC | AL11: mV col | AM11: Al mV fac | AN11: Max base mV | AO11: Runs needed | AP11: Size by CCC | AQ11: Size by VD | AR11: Rec size | AS11: Grp key | AT11: Runs by CCC | AU11: Runs by VD | AV11: Cg used | AW11: k | AX11: t used | AY11: Min S for SC | AZ11: Size by SC | BA11: Single-core | BB11: CCC key | BC11: Input issue
A12: 1 | B12: 2000 | C12: A | D12: B | E12: On Tray/Ladder | F12: 200 | G12: 400 | H12: Armoured | I12: XLPE | J12: Copper | K12: Single-core (3ph trefoil) | P12: =IF($B12="","",IF(NOT($AC12),"",IF(ISNUMBER($AR12),$AO12,""))) -> 5 | Q12: =IF($B12="","",IF(NOT($AC12),"Check inputs",IFERROR($AR12,"Single-core / busbar"))) -> 630 | R12: =IF(OR($B12="",NOT(ISNUMBER($AR12))),"",$AV12) -> 0.75 | S12: {=IF(OR($B12="",NOT(ISNUMBER($AR12))),"",INDEX(IF($I12="Rubber",SANS_CCC_Rub,SANS_CCC),MATCH($AR12,SANS_Size,0),$AF12)*$AG12*$AH12*$AI12*$AV12*$AO12)} -> 4104 | T12: =IF($U12="","",$U12*$G12) -> 11.6 | U12: {=IF(OR($B12="",NOT(ISNUMBER($AR12))),"",INDEX(SANS_mV,MATCH($AR12,SANS_Size,0),$AL12)*$AM12*($B12/$AO12)*$F12/1000/$G12)} -> 0.029 | V12: =IF($B12="","",IF(NOT($AC12),"",IF($AJ12=0,"Exceeds range",$AJ12))) -> 2500 | W12: =IF(OR($B12="",NOT(ISNUMBER($V12))),"",INDEX(SANS_BrkType,MATCH($V12,SANS_Breaker,0))) -> ACB | X12: =IF(OR($B12="",NOT(ISNUMBER($V12))),"",IFERROR(MIN(1,MAX(INDEX(Ir_Min,MATCH($W12,Ir_Type,0)),CEILING(ROUND($B12*Fac_BrkSF/$V12,6),INDEX(Ir_Step,MATCH($W12,Ir_Type,0)))))*$V12,$V12)) -> 2500 | Y12: =IF(NOT(ISNUMBER($AR12)),"",IF($AR12<=16,$AR12,IF($AR12<=35,16,_xlfn.MINIFS(SANS_Size,SANS_Size,">="&$AR12/2)))) -> 400 | Z12: =IF(OR($B12="",NOT(ISNUMBER($AR12))),"",IF($N12="","Not checked",$AW12*$AR12/SQRT($AX12)/1000)) -> Not checked | AA12: {=IF($B12="","",_xlfn.IFS(NOT($AC12),"FAIL – "&$BC12,NOT(ISNUMBER($AR12)),"FAIL – exceeds range",$U12>Fac_VdLimit,"FAIL – volt drop",IF(ISNUMBER($X12),$X12,$V12)<$B12*Fac_BrkSF,"FAIL – breaker < Ib × SF",$S12<IF(ISNUMBER($X12),$X12,$V12),"FAIL – CCC < Ir setting",AND(ISNUMBER($Z12),$N12>$Z12),"FAIL – short circuit",AND($AE12=2,$G12>250),"CHECK – 1ph: use 230 V",AND($AE12=3,$G12<300),"CHECK – 3ph: use 400 V",TRUE,"OK"))} -> OK | AC12: =IF($B12="","",IFERROR(AND(ISNUMBER($B12),$B12>0,ISNUMBER($F12),$F12>0,ISNUMBER($G12),$G12>0,ISNUMBER(MATCH($E12,INDEX(Map_Install,0,1),0)),ISNUMBER(MATCH($K12,INDEX(Map_Cores,0,1),0)),OR($I12="PVC",$I12="XLPE",$I12="Rubber"),OR($J12="Copper",$J12="Aluminium"),OR($L12="",AND(ISNUMBER($L12),$L12>0,$L12<=1.5)),ISNUMBER(MATCH(VLOOKUP($E12,Map_Install,3,FALSE)&"|"&IF($M12="","Touching",$M12),Grp_Key,0)),OR($N12="",AND(ISNUMBER($N12),$N12>0)),OR($O12="",AND(ISNUMBER($O12),$O12>0,$O12<=5)),ISNUMBER(MATCH($BB12,SANS_CCCkey,0)),COUNT(INDEX(IF($I12="Rubber",SANS_CCC_Rub,SANS_CCC),0,MATCH($BB12,SANS_CCCkey,0)))>0,NOT(AND($I12="Rubber",$J12="Aluminium")),NOT(AND(OR($I12="Rubber",$BA12=TRUE),OR(VLOOKUP($E12,Map_Install,2,FALSE)="B",VLOOKUP($E12,Map_Install,2,FALSE)="D")))),FALSE)) -> TRUE | AD12: =IF(OR($B12="",$AC12<>TRUE),"",IF($BA12=TRUE,"F",VLOOKUP($E12,Map_Install,2,FALSE))) -> F | AE12: =IF(OR($B12="",$AC12<>TRUE),"",VLOOKUP($K12,Map_Cores,2,FALSE)) -> 3 | AF12: =IF(OR($B12="",$AC12<>TRUE),"",MATCH($AD12&"|"&$AE12,SANS_CCCkey,0)) -> 10 | AG12: =IF(OR($B12="",$AC12<>TRUE),"",IF($I12="XLPE",Fac_XLPE,1)) -> 1.28 | AH12: =IF(OR($B12="",$AC12<>TRUE),"",IF($J12="Aluminium",Fac_Al,1)) -> 1 | AI12: =IF(OR($B12="",$AC12<>TRUE),"",IF($L12="",Fac_Derate,$L12)) -> 1 | AJ12: =IF(OR($B12="",$AC12<>TRUE),"",_xlfn.MINIFS(SANS_Breaker,SANS_Breaker,">="&$B12*Fac_BrkSF)) -> 2500 | AK12: =IF(OR($B12="",$AC12<>TRUE),"",IF($AJ12=0,0,IFERROR(MIN(1,MAX(INDEX(Ir_Min,MATCH(INDEX(SANS_BrkType,MATCH($AJ12,SANS_Breaker,0)),Ir_Type,0)),CEILING(ROUND($B12*Fac_BrkSF/$AJ12,6),INDEX(Ir_Step,MATCH(INDEX(SANS_BrkType,MATCH($AJ12,SANS_Breaker,0)),Ir_Type,0)))))*$AJ12,$AJ12))/($AI12*$AG12*$AH12)) -> 1953.125 | AL12: =IF(OR($B12="",$AC12<>TRUE),"",IF($I12="Rubber",4,0)+IF($BA12=TRUE,2,0)+IF($AE12=2,1,2)) -> 4 | AM12: =IF(OR($B12="",$AC12<>TRUE),"",IF($J12="Aluminium",Fac_AlmV,1)) -> 1 | AN12: =IF(OR($B12="",$AC12<>TRUE),"",Fac_VdLimit*$G12*1000/($B12*$F12*$AM12)) -> 0.03 | AO12: =IF(OR($B12="",$AC12<>TRUE),"",IF($AT12=0,0,MAX($AT12,$AU12))) -> 5 | AP12: =IF(OR(OR($B12="",$AC12<>TRUE),NOT(ISNUMBER($AV12))),"",_xlfn.MINIFS(SANS_Size,INDEX(IF($I12="Rubber",SANS_CCC_Rub,SANS_CCC),0,$AF12),">="&$AK12/($AO12*$AV12),SANS_Size,"<="&Fac_MaxSize)) -> 300 | AQ12: =IF(OR(OR($B12="",$AC12<>TRUE),NOT(ISNUMBER($AV12))),"",_xlfn.MINIFS(SANS_Size,INDEX(SANS_mV,0,$AL12),"<="&$AN12*$AO12,SANS_Size,"<="&Fac_MaxSize)) -> 630 | AR12: =IF(OR($B12="",$AC12<>TRUE),"",IF(OR($AJ12=0,$AO12=0,$AO12>Fac_MaxRuns,$AP12=0,$AQ12=0),NA(),MAX($AP12,$AQ12,$AZ12))) -> 630 | AS12: =IF(OR($B12="",$AC12<>TRUE),"",VLOOKUP($E12,Map_Install,3,FALSE)&"|"&IF($M12="","Touching",$M12)) -> AIR-TRAY|Touching | AT12: =IF(OR($B12="",$AC12<>TRUE),"",_xlfn.MINIFS(Grp_N,INDEX(Grp_Eff,MATCH($AS12,Grp_Key,0),0),">="&$AK12/_xlfn.MAXIFS(INDEX(IF($I12="Rubber",SANS_CCC_Rub,SANS_CCC),0,$AF12),SANS_Size,"<="&Fac_MaxSize),Grp_N,"<="&Fac_MaxRuns)) -> 3 | AU12: =IF(OR($B12="",$AC12<>TRUE),"",MAX(1,ROUNDUP(_xlfn.MINIFS(INDEX(SANS_mV,0,$AL12),SANS_Size,"<="&Fac_MaxSize)/$AN12,0))) -> 5 | AV12: {=IF(OR($B12="",$AC12<>TRUE),"",IFERROR(IF(OR($AO12=0,$AO12>Fac_MaxRuns),"",INDEX(Grp_Cg,MATCH($AS12,Grp_Key,0),$AO12)),""))} -> 0.75 | AW12: =IF(OR($B12="",$AC12<>TRUE),"",INDEX(SC_k,MATCH($J12&"|"&$I12,SC_kKey,0))) -> 143 | AX12: =IF(OR($B12="",$AC12<>TRUE),"",IF($O12="",IFERROR(INDEX(Dev_t,MATCH(INDEX(SANS_BrkType,MATCH($AJ12,SANS_Breaker,0)),Dev_Type,0)),0.4),$O12)) -> 0.4 | AY12: =IF(OR(OR($B12="",$AC12<>TRUE),$N12=""),"",$N12*1000*SQRT($AX12)/$AW12) | AZ12: =IF(OR($B12="",$AC12<>TRUE),"",IF($N12="",0,IF(_xlfn.MINIFS(SANS_Size,SANS_Size,">="&$AY12,SANS_Size,"<="&Fac_MaxSize,INDEX(IF($I12="Rubber",SANS_CCC_Rub,SANS_CCC),0,$AF12),">0")=0,NA(),_xlfn.MINIFS(SANS_Size,SANS_Size,">="&$AY12,SANS_Size,"<="&Fac_MaxSize,INDEX(IF($I12="Rubber",SANS_CCC_Rub,SANS_CCC),0,$AF12),">0")))) -> 0 | BA12: =IF($B12="","",IFERROR(INDEX(Map_Cores,MATCH($K12,INDEX(Map_Cores,0,1),0),3)=1,FALSE)) -> TRUE | BB12: =IF($B12="","",IFERROR(IF($BA12=TRUE,"F",VLOOKUP($E12,Map_Install,2,FALSE))&"|"&VLOOKUP($K12,Map_Cores,2,FALSE),"")) -> F|3 | BC12: {=IF(OR($B12="",$AC12=TRUE),"",IFERROR(_xlfn.IFS(AND($I12="Rubber",$J12="Aluminium"),"H07RN-F is copper only",AND($I12="Rubber",OR(VLOOKUP($E12,Map_Install,2,FALSE)="B",VLOOKUP($E12,Map_Install,2,FALSE)="D")),"rubber flex not rated in conduit/buried",AND($BA12=TRUE,OR(VLOOKUP($E12,Map_Install,2,FALSE)="B",VLOOKUP($E12,Map_Install,2,FALSE)="D")),"single-core: air/surface/tray only – use multicore",TRUE,"check inputs (spacing valid for install?)"),"check inputs"))}
A13: 2 | P13: =IF($B13="","",IF(NOT($AC13),"",IF(ISNUMBER($AR13),$AO13,""))) | Q13: =IF($B13="","",IF(NOT($AC13),"Check inputs",IFERROR($AR13,"Single-core / busbar"))) | R13: =IF(OR($B13="",NOT(ISNUMBER($AR13))),"",$AV13) | S13: {=IF(OR($B13="",NOT(ISNUMBER($AR13))),"",INDEX(IF($I13="Rubber",SANS_CCC_Rub,SANS_CCC),MATCH($AR13,SANS_Size,0),$AF13)*$AG13*$AH13*$AI13*$AV13*$AO13)} | T13: =IF($U13="","",$U13*$G13) | U13: {=IF(OR($B13="",NOT(ISNUMBER($AR13))),"",INDEX(SANS_mV,MATCH($AR13,SANS_Size,0),$AL13)*$AM13*($B13/$AO13)*$F13/1000/$G13)} | V13: =IF($B13="","",IF(NOT($AC13),"",IF($AJ13=0,"Exceeds range",$AJ13))) | W13: =IF(OR($B13="",NOT(ISNUMBER($V13))),"",INDEX(SANS_BrkType,MATCH($V13,SANS_Breaker,0))) | X13: =IF(OR($B13="",NOT(ISNUMBER($V13))),"",IFERROR(MIN(1,MAX(INDEX(Ir_Min,MATCH($W13,Ir_Type,0)),CEILING(ROUND($B13*Fac_BrkSF/$V13,6),INDEX(Ir_Step,MATCH($W13,Ir_Type,0)))))*$V13,$V13)) | Y13: =IF(NOT(ISNUMBER($AR13)),"",IF($AR13<=16,$AR13,IF($AR13<=35,16,_xlfn.MINIFS(SANS_Size,SANS_Size,">="&$AR13/2)))) | Z13: =IF(OR($B13="",NOT(ISNUMBER($AR13))),"",IF($N13="","Not checked",$AW13*$AR13/SQRT($AX13)/1000)) | AA13: {=IF($B13="","",_xlfn.IFS(NOT($AC13),"FAIL – "&$BC13,NOT(ISNUMBER($AR13)),"FAIL – exceeds range",$U13>Fac_VdLimit,"FAIL – volt drop",IF(ISNUMBER($X13),$X13,$V13)<$B13*Fac_BrkSF,"FAIL – breaker < Ib × SF",$S13<IF(ISNUMBER($X13),$X13,$V13),"FAIL – CCC < Ir setting",AND(ISNUMBER($Z13),$N13>$Z13),"FAIL – short circuit",AND($AE13=2,$G13>250),"CHECK – 1ph: use 230 V",AND($AE13=3,$G13<300),"CHECK – 3ph: use 400 V",TRUE,"OK"))} | AC13: =IF($B13="","",IFERROR(AND(ISNUMBER($B13),$B13>0,ISNUMBER($F13),$F13>0,ISNUMBER($G13),$G13>0,ISNUMBER(MATCH($E13,INDEX(Map_Install,0,1),0)),ISNUMBER(MATCH($K13,INDEX(Map_Cores,0,1),0)),OR($I13="PVC",$I13="XLPE",$I13="Rubber"),OR($J13="Copper",$J13="Aluminium"),OR($L13="",AND(ISNUMBER($L13),$L13>0,$L13<=1.5)),ISNUMBER(MATCH(VLOOKUP($E13,Map_Install,3,FALSE)&"|"&IF($M13="","Touching",$M13),Grp_Key,0)),OR($N13="",AND(ISNUMBER($N13),$N13>0)),OR($O13="",AND(ISNUMBER($O13),$O13>0,$O13<=5)),ISNUMBER(MATCH($BB13,SANS_CCCkey,0)),COUNT(INDEX(IF($I13="Rubber",SANS_CCC_Rub,SANS_CCC),0,MATCH($BB13,SANS_CCCkey,0)))>0,NOT(AND($I13="Rubber",$J13="Aluminium")),NOT(AND(OR($I13="Rubber",$BA13=TRUE),OR(VLOOKUP($E13,Map_Install,2,FALSE)="B",VLOOKUP($E13,Map_Install,2,FALSE)="D")))),FALSE)) | AD13: =IF(OR($B13="",$AC13<>TRUE),"",IF($BA13=TRUE,"F",VLOOKUP($E13,Map_Install,2,FALSE))) | AE13: =IF(OR($B13="",$AC13<>TRUE),"",VLOOKUP($K13,Map_Cores,2,FALSE)) | AF13: =IF(OR($B13="",$AC13<>TRUE),"",MATCH($AD13&"|"&$AE13,SANS_CCCkey,0)) | AG13: =IF(OR($B13="",$AC13<>TRUE),"",IF($I13="XLPE",Fac_XLPE,1)) | AH13: =IF(OR($B13="",$AC13<>TRUE),"",IF($J13="Aluminium",Fac_Al,1)) | AI13: =IF(OR($B13="",$AC13<>TRUE),"",IF($L13="",Fac_Derate,$L13)) | AJ13: =IF(OR($B13="",$AC13<>TRUE),"",_xlfn.MINIFS(SANS_Breaker,SANS_Breaker,">="&$B13*Fac_BrkSF)) | AK13: =IF(OR($B13="",$AC13<>TRUE),"",IF($AJ13=0,0,IFERROR(MIN(1,MAX(INDEX(Ir_Min,MATCH(INDEX(SANS_BrkType,MATCH($AJ13,SANS_Breaker,0)),Ir_Type,0)),CEILING(ROUND($B13*Fac_BrkSF/$AJ13,6),INDEX(Ir_Step,MATCH(INDEX(SANS_BrkType,MATCH($AJ13,SANS_Breaker,0)),Ir_Type,0)))))*$AJ13,$AJ13))/($AI13*$AG13*$AH13)) | AL13: =IF(OR($B13="",$AC13<>TRUE),"",IF($I13="Rubber",4,0)+IF($BA13=TRUE,2,0)+IF($AE13=2,1,2)) | AM13: =IF(OR($B13="",$AC13<>TRUE),"",IF($J13="Aluminium",Fac_AlmV,1)) | AN13: =IF(OR($B13="",$AC13<>TRUE),"",Fac_VdLimit*$G13*1000/($B13*$F13*$AM13)) | AO13: =IF(OR($B13="",$AC13<>TRUE),"",IF($AT13=0,0,MAX($AT13,$AU13))) | AP13: =IF(OR(OR($B13="",$AC13<>TRUE),NOT(ISNUMBER($AV13))),"",_xlfn.MINIFS(SANS_Size,INDEX(IF($I13="Rubber",SANS_CCC_Rub,SANS_CCC),0,$AF13),">="&$AK13/($AO13*$AV13),SANS_Size,"<="&Fac_MaxSize)) | AQ13: =IF(OR(OR($B13="",$AC13<>TRUE),NOT(ISNUMBER($AV13))),"",_xlfn.MINIFS(SANS_Size,INDEX(SANS_mV,0,$AL13),"<="&$AN13*$AO13,SANS_Size,"<="&Fac_MaxSize)) | AR13: =IF(OR($B13="",$AC13<>TRUE),"",IF(OR($AJ13=0,$AO13=0,$AO13>Fac_MaxRuns,$AP13=0,$AQ13=0),NA(),MAX($AP13,$AQ13,$AZ13))) | AS13: =IF(OR($B13="",$AC13<>TRUE),"",VLOOKUP($E13,Map_Install,3,FALSE)&"|"&IF($M13="","Touching",$M13)) | AT13: =IF(OR($B13="",$AC13<>TRUE),"",_xlfn.MINIFS(Grp_N,INDEX(Grp_Eff,MATCH($AS13,Grp_Key,0),0),">="&$AK13/_xlfn.MAXIFS(INDEX(IF($I13="Rubber",SANS_CCC_Rub,SANS_CCC),0,$AF13),SANS_Size,"<="&Fac_MaxSize),Grp_N,"<="&Fac_MaxRuns)) | AU13: =IF(OR($B13="",$AC13<>TRUE),"",MAX(1,ROUNDUP(_xlfn.MINIFS(INDEX(SANS_mV,0,$AL13),SANS_Size,"<="&Fac_MaxSize)/$AN13,0))) | AV13: {=IF(OR($B13="",$AC13<>TRUE),"",IFERROR(IF(OR($AO13=0,$AO13>Fac_MaxRuns),"",INDEX(Grp_Cg,MATCH($AS13,Grp_Key,0),$AO13)),""))} | AW13: =IF(OR($B13="",$AC13<>TRUE),"",INDEX(SC_k,MATCH($J13&"|"&$I13,SC_kKey,0))) | AX13: =IF(OR($B13="",$AC13<>TRUE),"",IF($O13="",IFERROR(INDEX(Dev_t,MATCH(INDEX(SANS_BrkType,MATCH($AJ13,SANS_Breaker,0)),Dev_Type,0)),0.4),$O13)) | AY13: =IF(OR(OR($B13="",$AC13<>TRUE),$N13=""),"",$N13*1000*SQRT($AX13)/$AW13) | AZ13: =IF(OR($B13="",$AC13<>TRUE),"",IF($N13="",0,IF(_xlfn.MINIFS(SANS_Size,SANS_Size,">="&$AY13,SANS_Size,"<="&Fac_MaxSize,INDEX(IF($I13="Rubber",SANS_CCC_Rub,SANS_CCC),0,$AF13),">0")=0,NA(),_xlfn.MINIFS(SANS_Size,SANS_Size,">="&$AY13,SANS_Size,"<="&Fac_MaxSize,INDEX(IF($I13="Rubber",SANS_CCC_Rub,SANS_CCC),0,$AF13),">0")))) | BA13: =IF($B13="","",IFERROR(INDEX(Map_Cores,MATCH($K13,INDEX(Map_Cores,0,1),0),3)=1,FALSE)) | BB13: =IF($B13="","",IFERROR(IF($BA13=TRUE,"F",VLOOKUP($E13,Map_Install,2,FALSE))&"|"&VLOOKUP($K13,Map_Cores,2,FALSE),"")) | BC13: {=IF(OR($B13="",$AC13=TRUE),"",IFERROR(_xlfn.IFS(AND($I13="Rubber",$J13="Aluminium"),"H07RN-F is copper only",AND($I13="Rubber",OR(VLOOKUP($E13,Map_Install,2,FALSE)="B",VLOOKUP($E13,Map_Install,2,FALSE)="D")),"rubber flex not rated in conduit/buried",AND($BA13=TRUE,OR(VLOOKUP($E13,Map_Install,2,FALSE)="B",VLOOKUP($E13,Map_Install,2,FALSE)="D")),"single-core: air/surface/tray only – use multicore",TRUE,"check inputs (spacing valid for install?)"),"check inputs"))}
A14: 3 | P14: =IF($B14="","",IF(NOT($AC14),"",IF(ISNUMBER($AR14),$AO14,""))) | Q14: =IF($B14="","",IF(NOT($AC14),"Check inputs",IFERROR($AR14,"Single-core / busbar"))) | R14: =IF(OR($B14="",NOT(ISNUMBER($AR14))),"",$AV14) | S14: {=IF(OR($B14="",NOT(ISNUMBER($AR14))),"",INDEX(IF($I14="Rubber",SANS_CCC_Rub,SANS_CCC),MATCH($AR14,SANS_Size,0),$AF14)*$AG14*$AH14*$AI14*$AV14*$AO14)} | T14: =IF($U14="","",$U14*$G14) | U14: {=IF(OR($B14="",NOT(ISNUMBER($AR14))),"",INDEX(SANS_mV,MATCH($AR14,SANS_Size,0),$AL14)*$AM14*($B14/$AO14)*$F14/1000/$G14)} | V14: =IF($B14="","",IF(NOT($AC14),"",IF($AJ14=0,"Exceeds range",$AJ14))) | W14: =IF(OR($B14="",NOT(ISNUMBER($V14))),"",INDEX(SANS_BrkType,MATCH($V14,SANS_Breaker,0))) | X14: =IF(OR($B14="",NOT(ISNUMBER($V14))),"",IFERROR(MIN(1,MAX(INDEX(Ir_Min,MATCH($W14,Ir_Type,0)),CEILING(ROUND($B14*Fac_BrkSF/$V14,6),INDEX(Ir_Step,MATCH($W14,Ir_Type,0)))))*$V14,$V14)) | Y14: =IF(NOT(ISNUMBER($AR14)),"",IF($AR14<=16,$AR14,IF($AR14<=35,16,_xlfn.MINIFS(SANS_Size,SANS_Size,">="&$AR14/2)))) | Z14: =IF(OR($B14="",NOT(ISNUMBER($AR14))),"",IF($N14="","Not checked",$AW14*$AR14/SQRT($AX14)/1000)) | AA14: {=IF($B14="","",_xlfn.IFS(NOT($AC14),"FAIL – "&$BC14,NOT(ISNUMBER($AR14)),"FAIL – exceeds range",$U14>Fac_VdLimit,"FAIL – volt drop",IF(ISNUMBER($X14),$X14,$V14)<$B14*Fac_BrkSF,"FAIL – breaker < Ib × SF",$S14<IF(ISNUMBER($X14),$X14,$V14),"FAIL – CCC < Ir setting",AND(ISNUMBER($Z14),$N14>$Z14),"FAIL – short circuit",AND($AE14=2,$G14>250),"CHECK – 1ph: use 230 V",AND($AE14=3,$G14<300),"CHECK – 3ph: use 400 V",TRUE,"OK"))} | AC14: =IF($B14="","",IFERROR(AND(ISNUMBER($B14),$B14>0,ISNUMBER($F14),$F14>0,ISNUMBER($G14),$G14>0,ISNUMBER(MATCH($E14,INDEX(Map_Install,0,1),0)),ISNUMBER(MATCH($K14,INDEX(Map_Cores,0,1),0)),OR($I14="PVC",$I14="XLPE",$I14="Rubber"),OR($J14="Copper",$J14="Aluminium"),OR($L14="",AND(ISNUMBER($L14),$L14>0,$L14<=1.5)),ISNUMBER(MATCH(VLOOKUP($E14,Map_Install,3,FALSE)&"|"&IF($M14="","Touching",$M14),Grp_Key,0)),OR($N14="",AND(ISNUMBER($N14),$N14>0)),OR($O14="",AND(ISNUMBER($O14),$O14>0,$O14<=5)),ISNUMBER(MATCH($BB14,SANS_CCCkey,0)),COUNT(INDEX(IF($I14="Rubber",SANS_CCC_Rub,SANS_CCC),0,MATCH($BB14,SANS_CCCkey,0)))>0,NOT(AND($I14="Rubber",$J14="Aluminium")),NOT(AND(OR($I14="Rubber",$BA14=TRUE),OR(VLOOKUP($E14,Map_Install,2,FALSE)="B",VLOOKUP($E14,Map_Install,2,FALSE)="D")))),FALSE)) | AD14: =IF(OR($B14="",$AC14<>TRUE),"",IF($BA14=TRUE,"F",VLOOKUP($E14,Map_Install,2,FALSE))) | AE14: =IF(OR($B14="",$AC14<>TRUE),"",VLOOKUP($K14,Map_Cores,2,FALSE)) | AF14: =IF(OR($B14="",$AC14<>TRUE),"",MATCH($AD14&"|"&$AE14,SANS_CCCkey,0)) | AG14: =IF(OR($B14="",$AC14<>TRUE),"",IF($I14="XLPE",Fac_XLPE,1)) | AH14: =IF(OR($B14="",$AC14<>TRUE),"",IF($J14="Aluminium",Fac_Al,1)) | AI14: =IF(OR($B14="",$AC14<>TRUE),"",IF($L14="",Fac_Derate,$L14)) | AJ14: =IF(OR($B14="",$AC14<>TRUE),"",_xlfn.MINIFS(SANS_Breaker,SANS_Breaker,">="&$B14*Fac_BrkSF)) | AK14: =IF(OR($B14="",$AC14<>TRUE),"",IF($AJ14=0,0,IFERROR(MIN(1,MAX(INDEX(Ir_Min,MATCH(INDEX(SANS_BrkType,MATCH($AJ14,SANS_Breaker,0)),Ir_Type,0)),CEILING(ROUND($B14*Fac_BrkSF/$AJ14,6),INDEX(Ir_Step,MATCH(INDEX(SANS_BrkType,MATCH($AJ14,SANS_Breaker,0)),Ir_Type,0)))))*$AJ14,$AJ14))/($AI14*$AG14*$AH14)) | AL14: =IF(OR($B14="",$AC14<>TRUE),"",IF($I14="Rubber",4,0)+IF($BA14=TRUE,2,0)+IF($AE14=2,1,2)) | AM14: =IF(OR($B14="",$AC14<>TRUE),"",IF($J14="Aluminium",Fac_AlmV,1)) | AN14: =IF(OR($B14="",$AC14<>TRUE),"",Fac_VdLimit*$G14*1000/($B14*$F14*$AM14)) | AO14: =IF(OR($B14="",$AC14<>TRUE),"",IF($AT14=0,0,MAX($AT14,$AU14))) | AP14: =IF(OR(OR($B14="",$AC14<>TRUE),NOT(ISNUMBER($AV14))),"",_xlfn.MINIFS(SANS_Size,INDEX(IF($I14="Rubber",SANS_CCC_Rub,SANS_CCC),0,$AF14),">="&$AK14/($AO14*$AV14),SANS_Size,"<="&Fac_MaxSize)) | AQ14: =IF(OR(OR($B14="",$AC14<>TRUE),NOT(ISNUMBER($AV14))),"",_xlfn.MINIFS(SANS_Size,INDEX(SANS_mV,0,$AL14),"<="&$AN14*$AO14,SANS_Size,"<="&Fac_MaxSize)) | AR14: =IF(OR($B14="",$AC14<>TRUE),"",IF(OR($AJ14=0,$AO14=0,$AO14>Fac_MaxRuns,$AP14=0,$AQ14=0),NA(),MAX($AP14,$AQ14,$AZ14))) | AS14: =IF(OR($B14="",$AC14<>TRUE),"",VLOOKUP($E14,Map_Install,3,FALSE)&"|"&IF($M14="","Touching",$M14)) | AT14: =IF(OR($B14="",$AC14<>TRUE),"",_xlfn.MINIFS(Grp_N,INDEX(Grp_Eff,MATCH($AS14,Grp_Key,0),0),">="&$AK14/_xlfn.MAXIFS(INDEX(IF($I14="Rubber",SANS_CCC_Rub,SANS_CCC),0,$AF14),SANS_Size,"<="&Fac_MaxSize),Grp_N,"<="&Fac_MaxRuns)) | AU14: =IF(OR($B14="",$AC14<>TRUE),"",MAX(1,ROUNDUP(_xlfn.MINIFS(INDEX(SANS_mV,0,$AL14),SANS_Size,"<="&Fac_MaxSize)/$AN14,0))) | AV14: {=IF(OR($B14="",$AC14<>TRUE),"",IFERROR(IF(OR($AO14=0,$AO14>Fac_MaxRuns),"",INDEX(Grp_Cg,MATCH($AS14,Grp_Key,0),$AO14)),""))} | AW14: =IF(OR($B14="",$AC14<>TRUE),"",INDEX(SC_k,MATCH($J14&"|"&$I14,SC_kKey,0))) | AX14: =IF(OR($B14="",$AC14<>TRUE),"",IF($O14="",IFERROR(INDEX(Dev_t,MATCH(INDEX(SANS_BrkType,MATCH($AJ14,SANS_Breaker,0)),Dev_Type,0)),0.4),$O14)) | AY14: =IF(OR(OR($B14="",$AC14<>TRUE),$N14=""),"",$N14*1000*SQRT($AX14)/$AW14) | AZ14: =IF(OR($B14="",$AC14<>TRUE),"",IF($N14="",0,IF(_xlfn.MINIFS(SANS_Size,SANS_Size,">="&$AY14,SANS_Size,"<="&Fac_MaxSize,INDEX(IF($I14="Rubber",SANS_CCC_Rub,SANS_CCC),0,$AF14),">0")=0,NA(),_xlfn.MINIFS(SANS_Size,SANS_Size,">="&$AY14,SANS_Size,"<="&Fac_MaxSize,INDEX(IF($I14="Rubber",SANS_CCC_Rub,SANS_CCC),0,$AF14),">0")))) | BA14: =IF($B14="","",IFERROR(INDEX(Map_Cores,MATCH($K14,INDEX(Map_Cores,0,1),0),3)=1,FALSE)) | BB14: =IF($B14="","",IFERROR(IF($BA14=TRUE,"F",VLOOKUP($E14,Map_Install,2,FALSE))&"|"&VLOOKUP($K14,Map_Cores,2,FALSE),"")) | BC14: {=IF(OR($B14="",$AC14=TRUE),"",IFERROR(_xlfn.IFS(AND($I14="Rubber",$J14="Aluminium"),"H07RN-F is copper only",AND($I14="Rubber",OR(VLOOKUP($E14,Map_Install,2,FALSE)="B",VLOOKUP($E14,Map_Install,2,FALSE)="D")),"rubber flex not rated in conduit/buried",AND($BA14=TRUE,OR(VLOOKUP($E14,Map_Install,2,FALSE)="B",VLOOKUP($E14,Map_Install,2,FALSE)="D")),"single-core: air/surface/tray only – use multicore",TRUE,"check inputs (spacing valid for install?)"),"check inputs"))}
A15: 4 | P15: =IF($B15="","",IF(NOT($AC15),"",IF(ISNUMBER($AR15),$AO15,""))) | Q15: =IF($B15="","",IF(NOT($AC15),"Check inputs",IFERROR($AR15,"Single-core / busbar"))) | R15: =IF(OR($B15="",NOT(ISNUMBER($AR15))),"",$AV15) | S15: {=IF(OR($B15="",NOT(ISNUMBER($AR15))),"",INDEX(IF($I15="Rubber",SANS_CCC_Rub,SANS_CCC),MATCH($AR15,SANS_Size,0),$AF15)*$AG15*$AH15*$AI15*$AV15*$AO15)} | T15: =IF($U15="","",$U15*$G15) | U15: {=IF(OR($B15="",NOT(ISNUMBER($AR15))),"",INDEX(SANS_mV,MATCH($AR15,SANS_Size,0),$AL15)*$AM15*($B15/$AO15)*$F15/1000/$G15)} | V15: =IF($B15="","",IF(NOT($AC15),"",IF($AJ15=0,"Exceeds range",$AJ15))) | W15: =IF(OR($B15="",NOT(ISNUMBER($V15))),"",INDEX(SANS_BrkType,MATCH($V15,SANS_Breaker,0))) | X15: =IF(OR($B15="",NOT(ISNUMBER($V15))),"",IFERROR(MIN(1,MAX(INDEX(Ir_Min,MATCH($W15,Ir_Type,0)),CEILING(ROUND($B15*Fac_BrkSF/$V15,6),INDEX(Ir_Step,MATCH($W15,Ir_Type,0)))))*$V15,$V15)) | Y15: =IF(NOT(ISNUMBER($AR15)),"",IF($AR15<=16,$AR15,IF($AR15<=35,16,_xlfn.MINIFS(SANS_Size,SANS_Size,">="&$AR15/2)))) | Z15: =IF(OR($B15="",NOT(ISNUMBER($AR15))),"",IF($N15="","Not checked",$AW15*$AR15/SQRT($AX15)/1000)) | AA15: {=IF($B15="","",_xlfn.IFS(NOT($AC15),"FAIL – "&$BC15,NOT(ISNUMBER($AR15)),"FAIL – exceeds range",$U15>Fac_VdLimit,"FAIL – volt drop",IF(ISNUMBER($X15),$X15,$V15)<$B15*Fac_BrkSF,"FAIL – breaker < Ib × SF",$S15<IF(ISNUMBER($X15),$X15,$V15),"FAIL – CCC < Ir setting",AND(ISNUMBER($Z15),$N15>$Z15),"FAIL – short circuit",AND($AE15=2,$G15>250),"CHECK – 1ph: use 230 V",AND($AE15=3,$G15<300),"CHECK – 3ph: use 400 V",TRUE,"OK"))} | AC15: =IF($B15="","",IFERROR(AND(ISNUMBER($B15),$B15>0,ISNUMBER($F15),$F15>0,ISNUMBER($G15),$G15>0,ISNUMBER(MATCH($E15,INDEX(Map_Install,0,1),0)),ISNUMBER(MATCH($K15,INDEX(Map_Cores,0,1),0)),OR($I15="PVC",$I15="XLPE",$I15="Rubber"),OR($J15="Copper",$J15="Aluminium"),OR($L15="",AND(ISNUMBER($L15),$L15>0,$L15<=1.5)),ISNUMBER(MATCH(VLOOKUP($E15,Map_Install,3,FALSE)&"|"&IF($M15="","Touching",$M15),Grp_Key,0)),OR($N15="",AND(ISNUMBER($N15),$N15>0)),OR($O15="",AND(ISNUMBER($O15),$O15>0,$O15<=5)),ISNUMBER(MATCH($BB15,SANS_CCCkey,0)),COUNT(INDEX(IF($I15="Rubber",SANS_CCC_Rub,SANS_CCC),0,MATCH($BB15,SANS_CCCkey,0)))>0,NOT(AND($I15="Rubber",$J15="Aluminium")),NOT(AND(OR($I15="Rubber",$BA15=TRUE),OR(VLOOKUP($E15,Map_Install,2,FALSE)="B",VLOOKUP($E15,Map_Install,2,FALSE)="D")))),FALSE)) | AD15: =IF(OR($B15="",$AC15<>TRUE),"",IF($BA15=TRUE,"F",VLOOKUP($E15,Map_Install,2,FALSE))) | AE15: =IF(OR($B15="",$AC15<>TRUE),"",VLOOKUP($K15,Map_Cores,2,FALSE)) | AF15: =IF(OR($B15="",$AC15<>TRUE),"",MATCH($AD15&"|"&$AE15,SANS_CCCkey,0)) | AG15: =IF(OR($B15="",$AC15<>TRUE),"",IF($I15="XLPE",Fac_XLPE,1)) | AH15: =IF(OR($B15="",$AC15<>TRUE),"",IF($J15="Aluminium",Fac_Al,1)) | AI15: =IF(OR($B15="",$AC15<>TRUE),"",IF($L15="",Fac_Derate,$L15)) | AJ15: =IF(OR($B15="",$AC15<>TRUE),"",_xlfn.MINIFS(SANS_Breaker,SANS_Breaker,">="&$B15*Fac_BrkSF)) | AK15: =IF(OR($B15="",$AC15<>TRUE),"",IF($AJ15=0,0,IFERROR(MIN(1,MAX(INDEX(Ir_Min,MATCH(INDEX(SANS_BrkType,MATCH($AJ15,SANS_Breaker,0)),Ir_Type,0)),CEILING(ROUND($B15*Fac_BrkSF/$AJ15,6),INDEX(Ir_Step,MATCH(INDEX(SANS_BrkType,MATCH($AJ15,SANS_Breaker,0)),Ir_Type,0)))))*$AJ15,$AJ15))/($AI15*$AG15*$AH15)) | AL15: =IF(OR($B15="",$AC15<>TRUE),"",IF($I15="Rubber",4,0)+IF($BA15=TRUE,2,0)+IF($AE15=2,1,2)) | AM15: =IF(OR($B15="",$AC15<>TRUE),"",IF($J15="Aluminium",Fac_AlmV,1)) | AN15: =IF(OR($B15="",$AC15<>TRUE),"",Fac_VdLimit*$G15*1000/($B15*$F15*$AM15)) | AO15: =IF(OR($B15="",$AC15<>TRUE),"",IF($AT15=0,0,MAX($AT15,$AU15))) | AP15: =IF(OR(OR($B15="",$AC15<>TRUE),NOT(ISNUMBER($AV15))),"",_xlfn.MINIFS(SANS_Size,INDEX(IF($I15="Rubber",SANS_CCC_Rub,SANS_CCC),0,$AF15),">="&$AK15/($AO15*$AV15),SANS_Size,"<="&Fac_MaxSize)) | AQ15: =IF(OR(OR($B15="",$AC15<>TRUE),NOT(ISNUMBER($AV15))),"",_xlfn.MINIFS(SANS_Size,INDEX(SANS_mV,0,$AL15),"<="&$AN15*$AO15,SANS_Size,"<="&Fac_MaxSize)) | AR15: =IF(OR($B15="",$AC15<>TRUE),"",IF(OR($AJ15=0,$AO15=0,$AO15>Fac_MaxRuns,$AP15=0,$AQ15=0),NA(),MAX($AP15,$AQ15,$AZ15))) | AS15: =IF(OR($B15="",$AC15<>TRUE),"",VLOOKUP($E15,Map_Install,3,FALSE)&"|"&IF($M15="","Touching",$M15)) | AT15: =IF(OR($B15="",$AC15<>TRUE),"",_xlfn.MINIFS(Grp_N,INDEX(Grp_Eff,MATCH($AS15,Grp_Key,0),0),">="&$AK15/_xlfn.MAXIFS(INDEX(IF($I15="Rubber",SANS_CCC_Rub,SANS_CCC),0,$AF15),SANS_Size,"<="&Fac_MaxSize),Grp_N,"<="&Fac_MaxRuns)) | AU15: =IF(OR($B15="",$AC15<>TRUE),"",MAX(1,ROUNDUP(_xlfn.MINIFS(INDEX(SANS_mV,0,$AL15),SANS_Size,"<="&Fac_MaxSize)/$AN15,0))) | AV15: {=IF(OR($B15="",$AC15<>TRUE),"",IFERROR(IF(OR($AO15=0,$AO15>Fac_MaxRuns),"",INDEX(Grp_Cg,MATCH($AS15,Grp_Key,0),$AO15)),""))} | AW15: =IF(OR($B15="",$AC15<>TRUE),"",INDEX(SC_k,MATCH($J15&"|"&$I15,SC_kKey,0))) | AX15: =IF(OR($B15="",$AC15<>TRUE),"",IF($O15="",IFERROR(INDEX(Dev_t,MATCH(INDEX(SANS_BrkType,MATCH($AJ15,SANS_Breaker,0)),Dev_Type,0)),0.4),$O15)) | AY15: =IF(OR(OR($B15="",$AC15<>TRUE),$N15=""),"",$N15*1000*SQRT($AX15)/$AW15) | AZ15: =IF(OR($B15="",$AC15<>TRUE),"",IF($N15="",0,IF(_xlfn.MINIFS(SANS_Size,SANS_Size,">="&$AY15,SANS_Size,"<="&Fac_MaxSize,INDEX(IF($I15="Rubber",SANS_CCC_Rub,SANS_CCC),0,$AF15),">0")=0,NA(),_xlfn.MINIFS(SANS_Size,SANS_Size,">="&$AY15,SANS_Size,"<="&Fac_MaxSize,INDEX(IF($I15="Rubber",SANS_CCC_Rub,SANS_CCC),0,$AF15),">0")))) | BA15: =IF($B15="","",IFERROR(INDEX(Map_Cores,MATCH($K15,INDEX(Map_Cores,0,1),0),3)=1,FALSE)) | BB15: =IF($B15="","",IFERROR(IF($BA15=TRUE,"F",VLOOKUP($E15,Map_Install,2,FALSE))&"|"&VLOOKUP($K15,Map_Cores,2,FALSE),"")) | BC15: {=IF(OR($B15="",$AC15=TRUE),"",IFERROR(_xlfn.IFS(AND($I15="Rubber",$J15="Aluminium"),"H07RN-F is copper only",AND($I15="Rubber",OR(VLOOKUP($E15,Map_Install,2,FALSE)="B",VLOOKUP($E15,Map_Install,2,FALSE)="D")),"rubber flex not rated in conduit/buried",AND($BA15=TRUE,OR(VLOOKUP($E15,Map_Install,2,FALSE)="B",VLOOKUP($E15,Map_Install,2,FALSE)="D")),"single-core: air/surface/tray only – use multicore",TRUE,"check inputs (spacing valid for install?)"),"check inputs"))}
A16: 5 | P16: =IF($B16="","",IF(NOT($AC16),"",IF(ISNUMBER($AR16),$AO16,""))) | Q16: =IF($B16="","",IF(NOT($AC16),"Check inputs",IFERROR($AR16,"Single-core / busbar"))) | R16: =IF(OR($B16="",NOT(ISNUMBER($AR16))),"",$AV16) | S16: {=IF(OR($B16="",NOT(ISNUMBER($AR16))),"",INDEX(IF($I16="Rubber",SANS_CCC_Rub,SANS_CCC),MATCH($AR16,SANS_Size,0),$AF16)*$AG16*$AH16*$AI16*$AV16*$AO16)} | T16: =IF($U16="","",$U16*$G16) | U16: {=IF(OR($B16="",NOT(ISNUMBER($AR16))),"",INDEX(SANS_mV,MATCH($AR16,SANS_Size,0),$AL16)*$AM16*($B16/$AO16)*$F16/1000/$G16)} | V16: =IF($B16="","",IF(NOT($AC16),"",IF($AJ16=0,"Exceeds range",$AJ16))) | W16: =IF(OR($B16="",NOT(ISNUMBER($V16))),"",INDEX(SANS_BrkType,MATCH($V16,SANS_Breaker,0))) | X16: =IF(OR($B16="",NOT(ISNUMBER($V16))),"",IFERROR(MIN(1,MAX(INDEX(Ir_Min,MATCH($W16,Ir_Type,0)),CEILING(ROUND($B16*Fac_BrkSF/$V16,6),INDEX(Ir_Step,MATCH($W16,Ir_Type,0)))))*$V16,$V16)) | Y16: =IF(NOT(ISNUMBER($AR16)),"",IF($AR16<=16,$AR16,IF($AR16<=35,16,_xlfn.MINIFS(SANS_Size,SANS_Size,">="&$AR16/2)))) | Z16: =IF(OR($B16="",NOT(ISNUMBER($AR16))),"",IF($N16="","Not checked",$AW16*$AR16/SQRT($AX16)/1000)) | AA16: {=IF($B16="","",_xlfn.IFS(NOT($AC16),"FAIL – "&$BC16,NOT(ISNUMBER($AR16)),"FAIL – exceeds range",$U16>Fac_VdLimit,"FAIL – volt drop",IF(ISNUMBER($X16),$X16,$V16)<$B16*Fac_BrkSF,"FAIL – breaker < Ib × SF",$S16<IF(ISNUMBER($X16),$X16,$V16),"FAIL – CCC < Ir setting",AND(ISNUMBER($Z16),$N16>$Z16),"FAIL – short circuit",AND($AE16=2,$G16>250),"CHECK – 1ph: use 230 V",AND($AE16=3,$G16<300),"CHECK – 3ph: use 400 V",TRUE,"OK"))} | AC16: =IF($B16="","",IFERROR(AND(ISNUMBER($B16),$B16>0,ISNUMBER($F16),$F16>0,ISNUMBER($G16),$G16>0,ISNUMBER(MATCH($E16,INDEX(Map_Install,0,1),0)),ISNUMBER(MATCH($K16,INDEX(Map_Cores,0,1),0)),OR($I16="PVC",$I16="XLPE",$I16="Rubber"),OR($J16="Copper",$J16="Aluminium"),OR($L16="",AND(ISNUMBER($L16),$L16>0,$L16<=1.5)),ISNUMBER(MATCH(VLOOKUP($E16,Map_Install,3,FALSE)&"|"&IF($M16="","Touching",$M16),Grp_Key,0)),OR($N16="",AND(ISNUMBER($N16),$N16>0)),OR($O16="",AND(ISNUMBER($O16),$O16>0,$O16<=5)),ISNUMBER(MATCH($BB16,SANS_CCCkey,0)),COUNT(INDEX(IF($I16="Rubber",SANS_CCC_Rub,SANS_CCC),0,MATCH($BB16,SANS_CCCkey,0)))>0,NOT(AND($I16="Rubber",$J16="Aluminium")),NOT(AND(OR($I16="Rubber",$BA16=TRUE),OR(VLOOKUP($E16,Map_Install,2,FALSE)="B",VLOOKUP($E16,Map_Install,2,FALSE)="D")))),FALSE)) | AD16: =IF(OR($B16="",$AC16<>TRUE),"",IF($BA16=TRUE,"F",VLOOKUP($E16,Map_Install,2,FALSE))) | AE16: =IF(OR($B16="",$AC16<>TRUE),"",VLOOKUP($K16,Map_Cores,2,FALSE)) | AF16: =IF(OR($B16="",$AC16<>TRUE),"",MATCH($AD16&"|"&$AE16,SANS_CCCkey,0)) | AG16: =IF(OR($B16="",$AC16<>TRUE),"",IF($I16="XLPE",Fac_XLPE,1)) | AH16: =IF(OR($B16="",$AC16<>TRUE),"",IF($J16="Aluminium",Fac_Al,1)) | AI16: =IF(OR($B16="",$AC16<>TRUE),"",IF($L16="",Fac_Derate,$L16)) | AJ16: =IF(OR($B16="",$AC16<>TRUE),"",_xlfn.MINIFS(SANS_Breaker,SANS_Breaker,">="&$B16*Fac_BrkSF)) | AK16: =IF(OR($B16="",$AC16<>TRUE),"",IF($AJ16=0,0,IFERROR(MIN(1,MAX(INDEX(Ir_Min,MATCH(INDEX(SANS_BrkType,MATCH($AJ16,SANS_Breaker,0)),Ir_Type,0)),CEILING(ROUND($B16*Fac_BrkSF/$AJ16,6),INDEX(Ir_Step,MATCH(INDEX(SANS_BrkType,MATCH($AJ16,SANS_Breaker,0)),Ir_Type,0)))))*$AJ16,$AJ16))/($AI16*$AG16*$AH16)) | AL16: =IF(OR($B16="",$AC16<>TRUE),"",IF($I16="Rubber",4,0)+IF($BA16=TRUE,2,0)+IF($AE16=2,1,2)) | AM16: =IF(OR($B16="",$AC16<>TRUE),"",IF($J16="Aluminium",Fac_AlmV,1)) | AN16: =IF(OR($B16="",$AC16<>TRUE),"",Fac_VdLimit*$G16*1000/($B16*$F16*$AM16)) | AO16: =IF(OR($B16="",$AC16<>TRUE),"",IF($AT16=0,0,MAX($AT16,$AU16))) | AP16: =IF(OR(OR($B16="",$AC16<>TRUE),NOT(ISNUMBER($AV16))),"",_xlfn.MINIFS(SANS_Size,INDEX(IF($I16="Rubber",SANS_CCC_Rub,SANS_CCC),0,$AF16),">="&$AK16/($AO16*$AV16),SANS_Size,"<="&Fac_MaxSize)) | AQ16: =IF(OR(OR($B16="",$AC16<>TRUE),NOT(ISNUMBER($AV16))),"",_xlfn.MINIFS(SANS_Size,INDEX(SANS_mV,0,$AL16),"<="&$AN16*$AO16,SANS_Size,"<="&Fac_MaxSize)) | AR16: =IF(OR($B16="",$AC16<>TRUE),"",IF(OR($AJ16=0,$AO16=0,$AO16>Fac_MaxRuns,$AP16=0,$AQ16=0),NA(),MAX($AP16,$AQ16,$AZ16))) | AS16: =IF(OR($B16="",$AC16<>TRUE),"",VLOOKUP($E16,Map_Install,3,FALSE)&"|"&IF($M16="","Touching",$M16)) | AT16: =IF(OR($B16="",$AC16<>TRUE),"",_xlfn.MINIFS(Grp_N,INDEX(Grp_Eff,MATCH($AS16,Grp_Key,0),0),">="&$AK16/_xlfn.MAXIFS(INDEX(IF($I16="Rubber",SANS_CCC_Rub,SANS_CCC),0,$AF16),SANS_Size,"<="&Fac_MaxSize),Grp_N,"<="&Fac_MaxRuns)) | AU16: =IF(OR($B16="",$AC16<>TRUE),"",MAX(1,ROUNDUP(_xlfn.MINIFS(INDEX(SANS_mV,0,$AL16),SANS_Size,"<="&Fac_MaxSize)/$AN16,0))) | AV16: {=IF(OR($B16="",$AC16<>TRUE),"",IFERROR(IF(OR($AO16=0,$AO16>Fac_MaxRuns),"",INDEX(Grp_Cg,MATCH($AS16,Grp_Key,0),$AO16)),""))} | AW16: =IF(OR($B16="",$AC16<>TRUE),"",INDEX(SC_k,MATCH($J16&"|"&$I16,SC_kKey,0))) | AX16: =IF(OR($B16="",$AC16<>TRUE),"",IF($O16="",IFERROR(INDEX(Dev_t,MATCH(INDEX(SANS_BrkType,MATCH($AJ16,SANS_Breaker,0)),Dev_Type,0)),0.4),$O16)) | AY16: =IF(OR(OR($B16="",$AC16<>TRUE),$N16=""),"",$N16*1000*SQRT($AX16)/$AW16) | AZ16: =IF(OR($B16="",$AC16<>TRUE),"",IF($N16="",0,IF(_xlfn.MINIFS(SANS_Size,SANS_Size,">="&$AY16,SANS_Size,"<="&Fac_MaxSize,INDEX(IF($I16="Rubber",SANS_CCC_Rub,SANS_CCC),0,$AF16),">0")=0,NA(),_xlfn.MINIFS(SANS_Size,SANS_Size,">="&$AY16,SANS_Size,"<="&Fac_MaxSize,INDEX(IF($I16="Rubber",SANS_CCC_Rub,SANS_CCC),0,$AF16),">0")))) | BA16: =IF($B16="","",IFERROR(INDEX(Map_Cores,MATCH($K16,INDEX(Map_Cores,0,1),0),3)=1,FALSE)) | BB16: =IF($B16="","",IFERROR(IF($BA16=TRUE,"F",VLOOKUP($E16,Map_Install,2,FALSE))&"|"&VLOOKUP($K16,Map_Cores,2,FALSE),"")) | BC16: {=IF(OR($B16="",$AC16=TRUE),"",IFERROR(_xlfn.IFS(AND($I16="Rubber",$J16="Aluminium"),"H07RN-F is copper only",AND($I16="Rubber",OR(VLOOKUP($E16,Map_Install,2,FALSE)="B",VLOOKUP($E16,Map_Install,2,FALSE)="D")),"rubber flex not rated in conduit/buried",AND($BA16=TRUE,OR(VLOOKUP($E16,Map_Install,2,FALSE)="B",VLOOKUP($E16,Map_Install,2,FALSE)="D")),"single-core: air/surface/tray only – use multicore",TRUE,"check inputs (spacing valid for install?)"),"check inputs"))}
A17: 6 | P17: =IF($B17="","",IF(NOT($AC17),"",IF(ISNUMBER($AR17),$AO17,""))) | Q17: =IF($B17="","",IF(NOT($AC17),"Check inputs",IFERROR($AR17,"Single-core / busbar"))) | R17: =IF(OR($B17="",NOT(ISNUMBER($AR17))),"",$AV17) | S17: {=IF(OR($B17="",NOT(ISNUMBER($AR17))),"",INDEX(IF($I17="Rubber",SANS_CCC_Rub,SANS_CCC),MATCH($AR17,SANS_Size,0),$AF17)*$AG17*$AH17*$AI17*$AV17*$AO17)} | T17: =IF($U17="","",$U17*$G17) | U17: {=IF(OR($B17="",NOT(ISNUMBER($AR17))),"",INDEX(SANS_mV,MATCH($AR17,SANS_Size,0),$AL17)*$AM17*($B17/$AO17)*$F17/1000/$G17)} | V17: =IF($B17="","",IF(NOT($AC17),"",IF($AJ17=0,"Exceeds range",$AJ17))) | W17: =IF(OR($B17="",NOT(ISNUMBER($V17))),"",INDEX(SANS_BrkType,MATCH($V17,SANS_Breaker,0))) | X17: =IF(OR($B17="",NOT(ISNUMBER($V17))),"",IFERROR(MIN(1,MAX(INDEX(Ir_Min,MATCH($W17,Ir_Type,0)),CEILING(ROUND($B17*Fac_BrkSF/$V17,6),INDEX(Ir_Step,MATCH($W17,Ir_Type,0)))))*$V17,$V17)) | Y17: =IF(NOT(ISNUMBER($AR17)),"",IF($AR17<=16,$AR17,IF($AR17<=35,16,_xlfn.MINIFS(SANS_Size,SANS_Size,">="&$AR17/2)))) | Z17: =IF(OR($B17="",NOT(ISNUMBER($AR17))),"",IF($N17="","Not checked",$AW17*$AR17/SQRT($AX17)/1000)) | AA17: {=IF($B17="","",_xlfn.IFS(NOT($AC17),"FAIL – "&$BC17,NOT(ISNUMBER($AR17)),"FAIL – exceeds range",$U17>Fac_VdLimit,"FAIL – volt drop",IF(ISNUMBER($X17),$X17,$V17)<$B17*Fac_BrkSF,"FAIL – breaker < Ib × SF",$S17<IF(ISNUMBER($X17),$X17,$V17),"FAIL – CCC < Ir setting",AND(ISNUMBER($Z17),$N17>$Z17),"FAIL – short circuit",AND($AE17=2,$G17>250),"CHECK – 1ph: use 230 V",AND($AE17=3,$G17<300),"CHECK – 3ph: use 400 V",TRUE,"OK"))} | AC17: =IF($B17="","",IFERROR(AND(ISNUMBER($B17),$B17>0,ISNUMBER($F17),$F17>0,ISNUMBER($G17),$G17>0,ISNUMBER(MATCH($E17,INDEX(Map_Install,0,1),0)),ISNUMBER(MATCH($K17,INDEX(Map_Cores,0,1),0)),OR($I17="PVC",$I17="XLPE",$I17="Rubber"),OR($J17="Copper",$J17="Aluminium"),OR($L17="",AND(ISNUMBER($L17),$L17>0,$L17<=1.5)),ISNUMBER(MATCH(VLOOKUP($E17,Map_Install,3,FALSE)&"|"&IF($M17="","Touching",$M17),Grp_Key,0)),OR($N17="",AND(ISNUMBER($N17),$N17>0)),OR($O17="",AND(ISNUMBER($O17),$O17>0,$O17<=5)),ISNUMBER(MATCH($BB17,SANS_CCCkey,0)),COUNT(INDEX(IF($I17="Rubber",SANS_CCC_Rub,SANS_CCC),0,MATCH($BB17,SANS_CCCkey,0)))>0,NOT(AND($I17="Rubber",$J17="Aluminium")),NOT(AND(OR($I17="Rubber",$BA17=TRUE),OR(VLOOKUP($E17,Map_Install,2,FALSE)="B",VLOOKUP($E17,Map_Install,2,FALSE)="D")))),FALSE)) | AD17: =IF(OR($B17="",$AC17<>TRUE),"",IF($BA17=TRUE,"F",VLOOKUP($E17,Map_Install,2,FALSE))) | AE17: =IF(OR($B17="",$AC17<>TRUE),"",VLOOKUP($K17,Map_Cores,2,FALSE)) | AF17: =IF(OR($B17="",$AC17<>TRUE),"",MATCH($AD17&"|"&$AE17,SANS_CCCkey,0)) | AG17: =IF(OR($B17="",$AC17<>TRUE),"",IF($I17="XLPE",Fac_XLPE,1)) | AH17: =IF(OR($B17="",$AC17<>TRUE),"",IF($J17="Aluminium",Fac_Al,1)) | AI17: =IF(OR($B17="",$AC17<>TRUE),"",IF($L17="",Fac_Derate,$L17)) | AJ17: =IF(OR($B17="",$AC17<>TRUE),"",_xlfn.MINIFS(SANS_Breaker,SANS_Breaker,">="&$B17*Fac_BrkSF)) | AK17: =IF(OR($B17="",$AC17<>TRUE),"",IF($AJ17=0,0,IFERROR(MIN(1,MAX(INDEX(Ir_Min,MATCH(INDEX(SANS_BrkType,MATCH($AJ17,SANS_Breaker,0)),Ir_Type,0)),CEILING(ROUND($B17*Fac_BrkSF/$AJ17,6),INDEX(Ir_Step,MATCH(INDEX(SANS_BrkType,MATCH($AJ17,SANS_Breaker,0)),Ir_Type,0)))))*$AJ17,$AJ17))/($AI17*$AG17*$AH17)) | AL17: =IF(OR($B17="",$AC17<>TRUE),"",IF($I17="Rubber",4,0)+IF($BA17=TRUE,2,0)+IF($AE17=2,1,2)) | AM17: =IF(OR($B17="",$AC17<>TRUE),"",IF($J17="Aluminium",Fac_AlmV,1)) | AN17: =IF(OR($B17="",$AC17<>TRUE),"",Fac_VdLimit*$G17*1000/($B17*$F17*$AM17)) | AO17: =IF(OR($B17="",$AC17<>TRUE),"",IF($AT17=0,0,MAX($AT17,$AU17))) | AP17: =IF(OR(OR($B17="",$AC17<>TRUE),NOT(ISNUMBER($AV17))),"",_xlfn.MINIFS(SANS_Size,INDEX(IF($I17="Rubber",SANS_CCC_Rub,SANS_CCC),0,$AF17),">="&$AK17/($AO17*$AV17),SANS_Size,"<="&Fac_MaxSize)) | AQ17: =IF(OR(OR($B17="",$AC17<>TRUE),NOT(ISNUMBER($AV17))),"",_xlfn.MINIFS(SANS_Size,INDEX(SANS_mV,0,$AL17),"<="&$AN17*$AO17,SANS_Size,"<="&Fac_MaxSize)) | AR17: =IF(OR($B17="",$AC17<>TRUE),"",IF(OR($AJ17=0,$AO17=0,$AO17>Fac_MaxRuns,$AP17=0,$AQ17=0),NA(),MAX($AP17,$AQ17,$AZ17))) | AS17: =IF(OR($B17="",$AC17<>TRUE),"",VLOOKUP($E17,Map_Install,3,FALSE)&"|"&IF($M17="","Touching",$M17)) | AT17: =IF(OR($B17="",$AC17<>TRUE),"",_xlfn.MINIFS(Grp_N,INDEX(Grp_Eff,MATCH($AS17,Grp_Key,0),0),">="&$AK17/_xlfn.MAXIFS(INDEX(IF($I17="Rubber",SANS_CCC_Rub,SANS_CCC),0,$AF17),SANS_Size,"<="&Fac_MaxSize),Grp_N,"<="&Fac_MaxRuns)) | AU17: =IF(OR($B17="",$AC17<>TRUE),"",MAX(1,ROUNDUP(_xlfn.MINIFS(INDEX(SANS_mV,0,$AL17),SANS_Size,"<="&Fac_MaxSize)/$AN17,0))) | AV17: {=IF(OR($B17="",$AC17<>TRUE),"",IFERROR(IF(OR($AO17=0,$AO17>Fac_MaxRuns),"",INDEX(Grp_Cg,MATCH($AS17,Grp_Key,0),$AO17)),""))} | AW17: =IF(OR($B17="",$AC17<>TRUE),"",INDEX(SC_k,MATCH($J17&"|"&$I17,SC_kKey,0))) | AX17: =IF(OR($B17="",$AC17<>TRUE),"",IF($O17="",IFERROR(INDEX(Dev_t,MATCH(INDEX(SANS_BrkType,MATCH($AJ17,SANS_Breaker,0)),Dev_Type,0)),0.4),$O17)) | AY17: =IF(OR(OR($B17="",$AC17<>TRUE),$N17=""),"",$N17*1000*SQRT($AX17)/$AW17) | AZ17: =IF(OR($B17="",$AC17<>TRUE),"",IF($N17="",0,IF(_xlfn.MINIFS(SANS_Size,SANS_Size,">="&$AY17,SANS_Size,"<="&Fac_MaxSize,INDEX(IF($I17="Rubber",SANS_CCC_Rub,SANS_CCC),0,$AF17),">0")=0,NA(),_xlfn.MINIFS(SANS_Size,SANS_Size,">="&$AY17,SANS_Size,"<="&Fac_MaxSize,INDEX(IF($I17="Rubber",SANS_CCC_Rub,SANS_CCC),0,$AF17),">0")))) | BA17: =IF($B17="","",IFERROR(INDEX(Map_Cores,MATCH($K17,INDEX(Map_Cores,0,1),0),3)=1,FALSE)) | BB17: =IF($B17="","",IFERROR(IF($BA17=TRUE,"F",VLOOKUP($E17,Map_Install,2,FALSE))&"|"&VLOOKUP($K17,Map_Cores,2,FALSE),"")) | BC17: {=IF(OR($B17="",$AC17=TRUE),"",IFERROR(_xlfn.IFS(AND($I17="Rubber",$J17="Aluminium"),"H07RN-F is copper only",AND($I17="Rubber",OR(VLOOKUP($E17,Map_Install,2,FALSE)="B",VLOOKUP($E17,Map_Install,2,FALSE)="D")),"rubber flex not rated in conduit/buried",AND($BA17=TRUE,OR(VLOOKUP($E17,Map_Install,2,FALSE)="B",VLOOKUP($E17,Map_Install,2,FALSE)="D")),"single-core: air/surface/tray only – use multicore",TRUE,"check inputs (spacing valid for install?)"),"check inputs"))}
A18: 7 | P18: =IF($B18="","",IF(NOT($AC18),"",IF(ISNUMBER($AR18),$AO18,""))) | Q18: =IF($B18="","",IF(NOT($AC18),"Check inputs",IFERROR($AR18,"Single-core / busbar"))) | R18: =IF(OR($B18="",NOT(ISNUMBER($AR18))),"",$AV18) | S18: {=IF(OR($B18="",NOT(ISNUMBER($AR18))),"",INDEX(IF($I18="Rubber",SANS_CCC_Rub,SANS_CCC),MATCH($AR18,SANS_Size,0),$AF18)*$AG18*$AH18*$AI18*$AV18*$AO18)} | T18: =IF($U18="","",$U18*$G18) | U18: {=IF(OR($B18="",NOT(ISNUMBER($AR18))),"",INDEX(SANS_mV,MATCH($AR18,SANS_Size,0),$AL18)*$AM18*($B18/$AO18)*$F18/1000/$G18)} | V18: =IF($B18="","",IF(NOT($AC18),"",IF($AJ18=0,"Exceeds range",$AJ18))) | W18: =IF(OR($B18="",NOT(ISNUMBER($V18))),"",INDEX(SANS_BrkType,MATCH($V18,SANS_Breaker,0))) | X18: =IF(OR($B18="",NOT(ISNUMBER($V18))),"",IFERROR(MIN(1,MAX(INDEX(Ir_Min,MATCH($W18,Ir_Type,0)),CEILING(ROUND($B18*Fac_BrkSF/$V18,6),INDEX(Ir_Step,MATCH($W18,Ir_Type,0)))))*$V18,$V18)) | Y18: =IF(NOT(ISNUMBER($AR18)),"",IF($AR18<=16,$AR18,IF($AR18<=35,16,_xlfn.MINIFS(SANS_Size,SANS_Size,">="&$AR18/2)))) | Z18: =IF(OR($B18="",NOT(ISNUMBER($AR18))),"",IF($N18="","Not checked",$AW18*$AR18/SQRT($AX18)/1000)) | AA18: {=IF($B18="","",_xlfn.IFS(NOT($AC18),"FAIL – "&$BC18,NOT(ISNUMBER($AR18)),"FAIL – exceeds range",$U18>Fac_VdLimit,"FAIL – volt drop",IF(ISNUMBER($X18),$X18,$V18)<$B18*Fac_BrkSF,"FAIL – breaker < Ib × SF",$S18<IF(ISNUMBER($X18),$X18,$V18),"FAIL – CCC < Ir setting",AND(ISNUMBER($Z18),$N18>$Z18),"FAIL – short circuit",AND($AE18=2,$G18>250),"CHECK – 1ph: use 230 V",AND($AE18=3,$G18<300),"CHECK – 3ph: use 400 V",TRUE,"OK"))} | AC18: =IF($B18="","",IFERROR(AND(ISNUMBER($B18),$B18>0,ISNUMBER($F18),$F18>0,ISNUMBER($G18),$G18>0,ISNUMBER(MATCH($E18,INDEX(Map_Install,0,1),0)),ISNUMBER(MATCH($K18,INDEX(Map_Cores,0,1),0)),OR($I18="PVC",$I18="XLPE",$I18="Rubber"),OR($J18="Copper",$J18="Aluminium"),OR($L18="",AND(ISNUMBER($L18),$L18>0,$L18<=1.5)),ISNUMBER(MATCH(VLOOKUP($E18,Map_Install,3,FALSE)&"|"&IF($M18="","Touching",$M18),Grp_Key,0)),OR($N18="",AND(ISNUMBER($N18),$N18>0)),OR($O18="",AND(ISNUMBER($O18),$O18>0,$O18<=5)),ISNUMBER(MATCH($BB18,SANS_CCCkey,0)),COUNT(INDEX(IF($I18="Rubber",SANS_CCC_Rub,SANS_CCC),0,MATCH($BB18,SANS_CCCkey,0)))>0,NOT(AND($I18="Rubber",$J18="Aluminium")),NOT(AND(OR($I18="Rubber",$BA18=TRUE),OR(VLOOKUP($E18,Map_Install,2,FALSE)="B",VLOOKUP($E18,Map_Install,2,FALSE)="D")))),FALSE)) | AD18: =IF(OR($B18="",$AC18<>TRUE),"",IF($BA18=TRUE,"F",VLOOKUP($E18,Map_Install,2,FALSE))) | AE18: =IF(OR($B18="",$AC18<>TRUE),"",VLOOKUP($K18,Map_Cores,2,FALSE)) | AF18: =IF(OR($B18="",$AC18<>TRUE),"",MATCH($AD18&"|"&$AE18,SANS_CCCkey,0)) | AG18: =IF(OR($B18="",$AC18<>TRUE),"",IF($I18="XLPE",Fac_XLPE,1)) | AH18: =IF(OR($B18="",$AC18<>TRUE),"",IF($J18="Aluminium",Fac_Al,1)) | AI18: =IF(OR($B18="",$AC18<>TRUE),"",IF($L18="",Fac_Derate,$L18)) | AJ18: =IF(OR($B18="",$AC18<>TRUE),"",_xlfn.MINIFS(SANS_Breaker,SANS_Breaker,">="&$B18*Fac_BrkSF)) | AK18: =IF(OR($B18="",$AC18<>TRUE),"",IF($AJ18=0,0,IFERROR(MIN(1,MAX(INDEX(Ir_Min,MATCH(INDEX(SANS_BrkType,MATCH($AJ18,SANS_Breaker,0)),Ir_Type,0)),CEILING(ROUND($B18*Fac_BrkSF/$AJ18,6),INDEX(Ir_Step,MATCH(INDEX(SANS_BrkType,MATCH($AJ18,SANS_Breaker,0)),Ir_Type,0)))))*$AJ18,$AJ18))/($AI18*$AG18*$AH18)) | AL18: =IF(OR($B18="",$AC18<>TRUE),"",IF($I18="Rubber",4,0)+IF($BA18=TRUE,2,0)+IF($AE18=2,1,2)) | AM18: =IF(OR($B18="",$AC18<>TRUE),"",IF($J18="Aluminium",Fac_AlmV,1)) | AN18: =IF(OR($B18="",$AC18<>TRUE),"",Fac_VdLimit*$G18*1000/($B18*$F18*$AM18)) | AO18: =IF(OR($B18="",$AC18<>TRUE),"",IF($AT18=0,0,MAX($AT18,$AU18))) | AP18: =IF(OR(OR($B18="",$AC18<>TRUE),NOT(ISNUMBER($AV18))),"",_xlfn.MINIFS(SANS_Size,INDEX(IF($I18="Rubber",SANS_CCC_Rub,SANS_CCC),0,$AF18),">="&$AK18/($AO18*$AV18),SANS_Size,"<="&Fac_MaxSize)) | AQ18: =IF(OR(OR($B18="",$AC18<>TRUE),NOT(ISNUMBER($AV18))),"",_xlfn.MINIFS(SANS_Size,INDEX(SANS_mV,0,$AL18),"<="&$AN18*$AO18,SANS_Size,"<="&Fac_MaxSize)) | AR18: =IF(OR($B18="",$AC18<>TRUE),"",IF(OR($AJ18=0,$AO18=0,$AO18>Fac_MaxRuns,$AP18=0,$AQ18=0),NA(),MAX($AP18,$AQ18,$AZ18))) | AS18: =IF(OR($B18="",$AC18<>TRUE),"",VLOOKUP($E18,Map_Install,3,FALSE)&"|"&IF($M18="","Touching",$M18)) | AT18: =IF(OR($B18="",$AC18<>TRUE),"",_xlfn.MINIFS(Grp_N,INDEX(Grp_Eff,MATCH($AS18,Grp_Key,0),0),">="&$AK18/_xlfn.MAXIFS(INDEX(IF($I18="Rubber",SANS_CCC_Rub,SANS_CCC),0,$AF18),SANS_Size,"<="&Fac_MaxSize),Grp_N,"<="&Fac_MaxRuns)) | AU18: =IF(OR($B18="",$AC18<>TRUE),"",MAX(1,ROUNDUP(_xlfn.MINIFS(INDEX(SANS_mV,0,$AL18),SANS_Size,"<="&Fac_MaxSize)/$AN18,0))) | AV18: {=IF(OR($B18="",$AC18<>TRUE),"",IFERROR(IF(OR($AO18=0,$AO18>Fac_MaxRuns),"",INDEX(Grp_Cg,MATCH($AS18,Grp_Key,0),$AO18)),""))} | AW18: =IF(OR($B18="",$AC18<>TRUE),"",INDEX(SC_k,MATCH($J18&"|"&$I18,SC_kKey,0))) | AX18: =IF(OR($B18="",$AC18<>TRUE),"",IF($O18="",IFERROR(INDEX(Dev_t,MATCH(INDEX(SANS_BrkType,MATCH($AJ18,SANS_Breaker,0)),Dev_Type,0)),0.4),$O18)) | AY18: =IF(OR(OR($B18="",$AC18<>TRUE),$N18=""),"",$N18*1000*SQRT($AX18)/$AW18) | AZ18: =IF(OR($B18="",$AC18<>TRUE),"",IF($N18="",0,IF(_xlfn.MINIFS(SANS_Size,SANS_Size,">="&$AY18,SANS_Size,"<="&Fac_MaxSize,INDEX(IF($I18="Rubber",SANS_CCC_Rub,SANS_CCC),0,$AF18),">0")=0,NA(),_xlfn.MINIFS(SANS_Size,SANS_Size,">="&$AY18,SANS_Size,"<="&Fac_MaxSize,INDEX(IF($I18="Rubber",SANS_CCC_Rub,SANS_CCC),0,$AF18),">0")))) | BA18: =IF($B18="","",IFERROR(INDEX(Map_Cores,MATCH($K18,INDEX(Map_Cores,0,1),0),3)=1,FALSE)) | BB18: =IF($B18="","",IFERROR(IF($BA18=TRUE,"F",VLOOKUP($E18,Map_Install,2,FALSE))&"|"&VLOOKUP($K18,Map_Cores,2,FALSE),"")) | BC18: {=IF(OR($B18="",$AC18=TRUE),"",IFERROR(_xlfn.IFS(AND($I18="Rubber",$J18="Aluminium"),"H07RN-F is copper only",AND($I18="Rubber",OR(VLOOKUP($E18,Map_Install,2,FALSE)="B",VLOOKUP($E18,Map_Install,2,FALSE)="D")),"rubber flex not rated in conduit/buried",AND($BA18=TRUE,OR(VLOOKUP($E18,Map_Install,2,FALSE)="B",VLOOKUP($E18,Map_Install,2,FALSE)="D")),"single-core: air/surface/tray only – use multicore",TRUE,"check inputs (spacing valid for install?)"),"check inputs"))}
A19: 8 | P19: =IF($B19="","",IF(NOT($AC19),"",IF(ISNUMBER($AR19),$AO19,""))) | Q19: =IF($B19="","",IF(NOT($AC19),"Check inputs",IFERROR($AR19,"Single-core / busbar"))) | R19: =IF(OR($B19="",NOT(ISNUMBER($AR19))),"",$AV19) | S19: {=IF(OR($B19="",NOT(ISNUMBER($AR19))),"",INDEX(IF($I19="Rubber",SANS_CCC_Rub,SANS_CCC),MATCH($AR19,SANS_Size,0),$AF19)*$AG19*$AH19*$AI19*$AV19*$AO19)} | T19: =IF($U19="","",$U19*$G19) | U19: {=IF(OR($B19="",NOT(ISNUMBER($AR19))),"",INDEX(SANS_mV,MATCH($AR19,SANS_Size,0),$AL19)*$AM19*($B19/$AO19)*$F19/1000/$G19)} | V19: =IF($B19="","",IF(NOT($AC19),"",IF($AJ19=0,"Exceeds range",$AJ19))) | W19: =IF(OR($B19="",NOT(ISNUMBER($V19))),"",INDEX(SANS_BrkType,MATCH($V19,SANS_Breaker,0))) | X19: =IF(OR($B19="",NOT(ISNUMBER($V19))),"",IFERROR(MIN(1,MAX(INDEX(Ir_Min,MATCH($W19,Ir_Type,0)),CEILING(ROUND($B19*Fac_BrkSF/$V19,6),INDEX(Ir_Step,MATCH($W19,Ir_Type,0)))))*$V19,$V19)) | Y19: =IF(NOT(ISNUMBER($AR19)),"",IF($AR19<=16,$AR19,IF($AR19<=35,16,_xlfn.MINIFS(SANS_Size,SANS_Size,">="&$AR19/2)))) | Z19: =IF(OR($B19="",NOT(ISNUMBER($AR19))),"",IF($N19="","Not checked",$AW19*$AR19/SQRT($AX19)/1000)) | AA19: {=IF($B19="","",_xlfn.IFS(NOT($AC19),"FAIL – "&$BC19,NOT(ISNUMBER($AR19)),"FAIL – exceeds range",$U19>Fac_VdLimit,"FAIL – volt drop",IF(ISNUMBER($X19),$X19,$V19)<$B19*Fac_BrkSF,"FAIL – breaker < Ib × SF",$S19<IF(ISNUMBER($X19),$X19,$V19),"FAIL – CCC < Ir setting",AND(ISNUMBER($Z19),$N19>$Z19),"FAIL – short circuit",AND($AE19=2,$G19>250),"CHECK – 1ph: use 230 V",AND($AE19=3,$G19<300),"CHECK – 3ph: use 400 V",TRUE,"OK"))} | AC19: =IF($B19="","",IFERROR(AND(ISNUMBER($B19),$B19>0,ISNUMBER($F19),$F19>0,ISNUMBER($G19),$G19>0,ISNUMBER(MATCH($E19,INDEX(Map_Install,0,1),0)),ISNUMBER(MATCH($K19,INDEX(Map_Cores,0,1),0)),OR($I19="PVC",$I19="XLPE",$I19="Rubber"),OR($J19="Copper",$J19="Aluminium"),OR($L19="",AND(ISNUMBER($L19),$L19>0,$L19<=1.5)),ISNUMBER(MATCH(VLOOKUP($E19,Map_Install,3,FALSE)&"|"&IF($M19="","Touching",$M19),Grp_Key,0)),OR($N19="",AND(ISNUMBER($N19),$N19>0)),OR($O19="",AND(ISNUMBER($O19),$O19>0,$O19<=5)),ISNUMBER(MATCH($BB19,SANS_CCCkey,0)),COUNT(INDEX(IF($I19="Rubber",SANS_CCC_Rub,SANS_CCC),0,MATCH($BB19,SANS_CCCkey,0)))>0,NOT(AND($I19="Rubber",$J19="Aluminium")),NOT(AND(OR($I19="Rubber",$BA19=TRUE),OR(VLOOKUP($E19,Map_Install,2,FALSE)="B",VLOOKUP($E19,Map_Install,2,FALSE)="D")))),FALSE)) | AD19: =IF(OR($B19="",$AC19<>TRUE),"",IF($BA19=TRUE,"F",VLOOKUP($E19,Map_Install,2,FALSE))) | AE19: =IF(OR($B19="",$AC19<>TRUE),"",VLOOKUP($K19,Map_Cores,2,FALSE)) | AF19: =IF(OR($B19="",$AC19<>TRUE),"",MATCH($AD19&"|"&$AE19,SANS_CCCkey,0)) | AG19: =IF(OR($B19="",$AC19<>TRUE),"",IF($I19="XLPE",Fac_XLPE,1)) | AH19: =IF(OR($B19="",$AC19<>TRUE),"",IF($J19="Aluminium",Fac_Al,1)) | AI19: =IF(OR($B19="",$AC19<>TRUE),"",IF($L19="",Fac_Derate,$L19)) | AJ19: =IF(OR($B19="",$AC19<>TRUE),"",_xlfn.MINIFS(SANS_Breaker,SANS_Breaker,">="&$B19*Fac_BrkSF)) | AK19: =IF(OR($B19="",$AC19<>TRUE),"",IF($AJ19=0,0,IFERROR(MIN(1,MAX(INDEX(Ir_Min,MATCH(INDEX(SANS_BrkType,MATCH($AJ19,SANS_Breaker,0)),Ir_Type,0)),CEILING(ROUND($B19*Fac_BrkSF/$AJ19,6),INDEX(Ir_Step,MATCH(INDEX(SANS_BrkType,MATCH($AJ19,SANS_Breaker,0)),Ir_Type,0)))))*$AJ19,$AJ19))/($AI19*$AG19*$AH19)) | AL19: =IF(OR($B19="",$AC19<>TRUE),"",IF($I19="Rubber",4,0)+IF($BA19=TRUE,2,0)+IF($AE19=2,1,2)) | AM19: =IF(OR($B19="",$AC19<>TRUE),"",IF($J19="Aluminium",Fac_AlmV,1)) | AN19: =IF(OR($B19="",$AC19<>TRUE),"",Fac_VdLimit*$G19*1000/($B19*$F19*$AM19)) | AO19: =IF(OR($B19="",$AC19<>TRUE),"",IF($AT19=0,0,MAX($AT19,$AU19))) | AP19: =IF(OR(OR($B19="",$AC19<>TRUE),NOT(ISNUMBER($AV19))),"",_xlfn.MINIFS(SANS_Size,INDEX(IF($I19="Rubber",SANS_CCC_Rub,SANS_CCC),0,$AF19),">="&$AK19/($AO19*$AV19),SANS_Size,"<="&Fac_MaxSize)) | AQ19: =IF(OR(OR($B19="",$AC19<>TRUE),NOT(ISNUMBER($AV19))),"",_xlfn.MINIFS(SANS_Size,INDEX(SANS_mV,0,$AL19),"<="&$AN19*$AO19,SANS_Size,"<="&Fac_MaxSize)) | AR19: =IF(OR($B19="",$AC19<>TRUE),"",IF(OR($AJ19=0,$AO19=0,$AO19>Fac_MaxRuns,$AP19=0,$AQ19=0),NA(),MAX($AP19,$AQ19,$AZ19))) | AS19: =IF(OR($B19="",$AC19<>TRUE),"",VLOOKUP($E19,Map_Install,3,FALSE)&"|"&IF($M19="","Touching",$M19)) | AT19: =IF(OR($B19="",$AC19<>TRUE),"",_xlfn.MINIFS(Grp_N,INDEX(Grp_Eff,MATCH($AS19,Grp_Key,0),0),">="&$AK19/_xlfn.MAXIFS(INDEX(IF($I19="Rubber",SANS_CCC_Rub,SANS_CCC),0,$AF19),SANS_Size,"<="&Fac_MaxSize),Grp_N,"<="&Fac_MaxRuns)) | AU19: =IF(OR($B19="",$AC19<>TRUE),"",MAX(1,ROUNDUP(_xlfn.MINIFS(INDEX(SANS_mV,0,$AL19),SANS_Size,"<="&Fac_MaxSize)/$AN19,0))) | AV19: {=IF(OR($B19="",$AC19<>TRUE),"",IFERROR(IF(OR($AO19=0,$AO19>Fac_MaxRuns),"",INDEX(Grp_Cg,MATCH($AS19,Grp_Key,0),$AO19)),""))} | AW19: =IF(OR($B19="",$AC19<>TRUE),"",INDEX(SC_k,MATCH($J19&"|"&$I19,SC_kKey,0))) | AX19: =IF(OR($B19="",$AC19<>TRUE),"",IF($O19="",IFERROR(INDEX(Dev_t,MATCH(INDEX(SANS_BrkType,MATCH($AJ19,SANS_Breaker,0)),Dev_Type,0)),0.4),$O19)) | AY19: =IF(OR(OR($B19="",$AC19<>TRUE),$N19=""),"",$N19*1000*SQRT($AX19)/$AW19) | AZ19: =IF(OR($B19="",$AC19<>TRUE),"",IF($N19="",0,IF(_xlfn.MINIFS(SANS_Size,SANS_Size,">="&$AY19,SANS_Size,"<="&Fac_MaxSize,INDEX(IF($I19="Rubber",SANS_CCC_Rub,SANS_CCC),0,$AF19),">0")=0,NA(),_xlfn.MINIFS(SANS_Size,SANS_Size,">="&$AY19,SANS_Size,"<="&Fac_MaxSize,INDEX(IF($I19="Rubber",SANS_CCC_Rub,SANS_CCC),0,$AF19),">0")))) | BA19: =IF($B19="","",IFERROR(INDEX(Map_Cores,MATCH($K19,INDEX(Map_Cores,0,1),0),3)=1,FALSE)) | BB19: =IF($B19="","",IFERROR(IF($BA19=TRUE,"F",VLOOKUP($E19,Map_Install,2,FALSE))&"|"&VLOOKUP($K19,Map_Cores,2,FALSE),"")) | BC19: {=IF(OR($B19="",$AC19=TRUE),"",IFERROR(_xlfn.IFS(AND($I19="Rubber",$J19="Aluminium"),"H07RN-F is copper only",AND($I19="Rubber",OR(VLOOKUP($E19,Map_Install,2,FALSE)="B",VLOOKUP($E19,Map_Install,2,FALSE)="D")),"rubber flex not rated in conduit/buried",AND($BA19=TRUE,OR(VLOOKUP($E19,Map_Install,2,FALSE)="B",VLOOKUP($E19,Map_Install,2,FALSE)="D")),"single-core: air/surface/tray only – use multicore",TRUE,"check inputs (spacing valid for install?)"),"check inputs"))}
A20: 9 | P20: =IF($B20="","",IF(NOT($AC20),"",IF(ISNUMBER($AR20),$AO20,""))) | Q20: =IF($B20="","",IF(NOT($AC20),"Check inputs",IFERROR($AR20,"Single-core / busbar"))) | R20: =IF(OR($B20="",NOT(ISNUMBER($AR20))),"",$AV20) | S20: {=IF(OR($B20="",NOT(ISNUMBER($AR20))),"",INDEX(IF($I20="Rubber",SANS_CCC_Rub,SANS_CCC),MATCH($AR20,SANS_Size,0),$AF20)*$AG20*$AH20*$AI20*$AV20*$AO20)} | T20: =IF($U20="","",$U20*$G20) | U20: {=IF(OR($B20="",NOT(ISNUMBER($AR20))),"",INDEX(SANS_mV,MATCH($AR20,SANS_Size,0),$AL20)*$AM20*($B20/$AO20)*$F20/1000/$G20)} | V20: =IF($B20="","",IF(NOT($AC20),"",IF($AJ20=0,"Exceeds range",$AJ20))) | W20: =IF(OR($B20="",NOT(ISNUMBER($V20))),"",INDEX(SANS_BrkType,MATCH($V20,SANS_Breaker,0))) | X20: =IF(OR($B20="",NOT(ISNUMBER($V20))),"",IFERROR(MIN(1,MAX(INDEX(Ir_Min,MATCH($W20,Ir_Type,0)),CEILING(ROUND($B20*Fac_BrkSF/$V20,6),INDEX(Ir_Step,MATCH($W20,Ir_Type,0)))))*$V20,$V20)) | Y20: =IF(NOT(ISNUMBER($AR20)),"",IF($AR20<=16,$AR20,IF($AR20<=35,16,_xlfn.MINIFS(SANS_Size,SANS_Size,">="&$AR20/2)))) | Z20: =IF(OR($B20="",NOT(ISNUMBER($AR20))),"",IF($N20="","Not checked",$AW20*$AR20/SQRT($AX20)/1000)) | AA20: {=IF($B20="","",_xlfn.IFS(NOT($AC20),"FAIL – "&$BC20,NOT(ISNUMBER($AR20)),"FAIL – exceeds range",$U20>Fac_VdLimit,"FAIL – volt drop",IF(ISNUMBER($X20),$X20,$V20)<$B20*Fac_BrkSF,"FAIL – breaker < Ib × SF",$S20<IF(ISNUMBER($X20),$X20,$V20),"FAIL – CCC < Ir setting",AND(ISNUMBER($Z20),$N20>$Z20),"FAIL – short circuit",AND($AE20=2,$G20>250),"CHECK – 1ph: use 230 V",AND($AE20=3,$G20<300),"CHECK – 3ph: use 400 V",TRUE,"OK"))} | AC20: =IF($B20="","",IFERROR(AND(ISNUMBER($B20),$B20>0,ISNUMBER($F20),$F20>0,ISNUMBER($G20),$G20>0,ISNUMBER(MATCH($E20,INDEX(Map_Install,0,1),0)),ISNUMBER(MATCH($K20,INDEX(Map_Cores,0,1),0)),OR($I20="PVC",$I20="XLPE",$I20="Rubber"),OR($J20="Copper",$J20="Aluminium"),OR($L20="",AND(ISNUMBER($L20),$L20>0,$L20<=1.5)),ISNUMBER(MATCH(VLOOKUP($E20,Map_Install,3,FALSE)&"|"&IF($M20="","Touching",$M20),Grp_Key,0)),OR($N20="",AND(ISNUMBER($N20),$N20>0)),OR($O20="",AND(ISNUMBER($O20),$O20>0,$O20<=5)),ISNUMBER(MATCH($BB20,SANS_CCCkey,0)),COUNT(INDEX(IF($I20="Rubber",SANS_CCC_Rub,SANS_CCC),0,MATCH($BB20,SANS_CCCkey,0)))>0,NOT(AND($I20="Rubber",$J20="Aluminium")),NOT(AND(OR($I20="Rubber",$BA20=TRUE),OR(VLOOKUP($E20,Map_Install,2,FALSE)="B",VLOOKUP($E20,Map_Install,2,FALSE)="D")))),FALSE)) | AD20: =IF(OR($B20="",$AC20<>TRUE),"",IF($BA20=TRUE,"F",VLOOKUP($E20,Map_Install,2,FALSE))) | AE20: =IF(OR($B20="",$AC20<>TRUE),"",VLOOKUP($K20,Map_Cores,2,FALSE)) | AF20: =IF(OR($B20="",$AC20<>TRUE),"",MATCH($AD20&"|"&$AE20,SANS_CCCkey,0)) | AG20: =IF(OR($B20="",$AC20<>TRUE),"",IF($I20="XLPE",Fac_XLPE,1)) | AH20: =IF(OR($B20="",$AC20<>TRUE),"",IF($J20="Aluminium",Fac_Al,1)) | AI20: =IF(OR($B20="",$AC20<>TRUE),"",IF($L20="",Fac_Derate,$L20)) | AJ20: =IF(OR($B20="",$AC20<>TRUE),"",_xlfn.MINIFS(SANS_Breaker,SANS_Breaker,">="&$B20*Fac_BrkSF)) | AK20: =IF(OR($B20="",$AC20<>TRUE),"",IF($AJ20=0,0,IFERROR(MIN(1,MAX(INDEX(Ir_Min,MATCH(INDEX(SANS_BrkType,MATCH($AJ20,SANS_Breaker,0)),Ir_Type,0)),CEILING(ROUND($B20*Fac_BrkSF/$AJ20,6),INDEX(Ir_Step,MATCH(INDEX(SANS_BrkType,MATCH($AJ20,SANS_Breaker,0)),Ir_Type,0)))))*$AJ20,$AJ20))/($AI20*$AG20*$AH20)) | AL20: =IF(OR($B20="",$AC20<>TRUE),"",IF($I20="Rubber",4,0)+IF($BA20=TRUE,2,0)+IF($AE20=2,1,2)) | AM20: =IF(OR($B20="",$AC20<>TRUE),"",IF($J20="Aluminium",Fac_AlmV,1)) | AN20: =IF(OR($B20="",$AC20<>TRUE),"",Fac_VdLimit*$G20*1000/($B20*$F20*$AM20)) | AO20: =IF(OR($B20="",$AC20<>TRUE),"",IF($AT20=0,0,MAX($AT20,$AU20))) | AP20: =IF(OR(OR($B20="",$AC20<>TRUE),NOT(ISNUMBER($AV20))),"",_xlfn.MINIFS(SANS_Size,INDEX(IF($I20="Rubber",SANS_CCC_Rub,SANS_CCC),0,$AF20),">="&$AK20/($AO20*$AV20),SANS_Size,"<="&Fac_MaxSize)) | AQ20: =IF(OR(OR($B20="",$AC20<>TRUE),NOT(ISNUMBER($AV20))),"",_xlfn.MINIFS(SANS_Size,INDEX(SANS_mV,0,$AL20),"<="&$AN20*$AO20,SANS_Size,"<="&Fac_MaxSize)) | AR20: =IF(OR($B20="",$AC20<>TRUE),"",IF(OR($AJ20=0,$AO20=0,$AO20>Fac_MaxRuns,$AP20=0,$AQ20=0),NA(),MAX($AP20,$AQ20,$AZ20))) | AS20: =IF(OR($B20="",$AC20<>TRUE),"",VLOOKUP($E20,Map_Install,3,FALSE)&"|"&IF($M20="","Touching",$M20)) | AT20: =IF(OR($B20="",$AC20<>TRUE),"",_xlfn.MINIFS(Grp_N,INDEX(Grp_Eff,MATCH($AS20,Grp_Key,0),0),">="&$AK20/_xlfn.MAXIFS(INDEX(IF($I20="Rubber",SANS_CCC_Rub,SANS_CCC),0,$AF20),SANS_Size,"<="&Fac_MaxSize),Grp_N,"<="&Fac_MaxRuns)) | AU20: =IF(OR($B20="",$AC20<>TRUE),"",MAX(1,ROUNDUP(_xlfn.MINIFS(INDEX(SANS_mV,0,$AL20),SANS_Size,"<="&Fac_MaxSize)/$AN20,0))) | AV20: {=IF(OR($B20="",$AC20<>TRUE),"",IFERROR(IF(OR($AO20=0,$AO20>Fac_MaxRuns),"",INDEX(Grp_Cg,MATCH($AS20,Grp_Key,0),$AO20)),""))} | AW20: =IF(OR($B20="",$AC20<>TRUE),"",INDEX(SC_k,MATCH($J20&"|"&$I20,SC_kKey,0))) | AX20: =IF(OR($B20="",$AC20<>TRUE),"",IF($O20="",IFERROR(INDEX(Dev_t,MATCH(INDEX(SANS_BrkType,MATCH($AJ20,SANS_Breaker,0)),Dev_Type,0)),0.4),$O20)) | AY20: =IF(OR(OR($B20="",$AC20<>TRUE),$N20=""),"",$N20*1000*SQRT($AX20)/$AW20) | AZ20: =IF(OR($B20="",$AC20<>TRUE),"",IF($N20="",0,IF(_xlfn.MINIFS(SANS_Size,SANS_Size,">="&$AY20,SANS_Size,"<="&Fac_MaxSize,INDEX(IF($I20="Rubber",SANS_CCC_Rub,SANS_CCC),0,$AF20),">0")=0,NA(),_xlfn.MINIFS(SANS_Size,SANS_Size,">="&$AY20,SANS_Size,"<="&Fac_MaxSize,INDEX(IF($I20="Rubber",SANS_CCC_Rub,SANS_CCC),0,$AF20),">0")))) | BA20: =IF($B20="","",IFERROR(INDEX(Map_Cores,MATCH($K20,INDEX(Map_Cores,0,1),0),3)=1,FALSE)) | BB20: =IF($B20="","",IFERROR(IF($BA20=TRUE,"F",VLOOKUP($E20,Map_Install,2,FALSE))&"|"&VLOOKUP($K20,Map_Cores,2,FALSE),"")) | BC20: {=IF(OR($B20="",$AC20=TRUE),"",IFERROR(_xlfn.IFS(AND($I20="Rubber",$J20="Aluminium"),"H07RN-F is copper only",AND($I20="Rubber",OR(VLOOKUP($E20,Map_Install,2,FALSE)="B",VLOOKUP($E20,Map_Install,2,FALSE)="D")),"rubber flex not rated in conduit/buried",AND($BA20=TRUE,OR(VLOOKUP($E20,Map_Install,2,FALSE)="B",VLOOKUP($E20,Map_Install,2,FALSE)="D")),"single-core: air/surface/tray only – use multicore",TRUE,"check inputs (spacing valid for install?)"),"check inputs"))}
