Workbook
Name AfricaCountries: CountryList!$A$1:$A$54

Sheet site_tech_info
A1: Site Name | B1: PV Capacity (W) | C1: PV Inverter Size (kW) | D1: Battery Size (Wh) | E1: Battery Name | F1: Battery Inverter/Hybrid Size | G1: Generator Size | H1: Genset/Grid set point kit | I1: Country | J1: Province | K1: Location | L1: Meter | M1: Contract Type | N1: Business Type | O1: Operational Satus | P1: Sales Type | Q1: Investment Party | R1: Project Number | S1: Commisioned Date | T1: Installer Name | U1: Platform | V1: Offtake Guarantee | W1: Age | X1: Soiling Intensity | Y1: Shading
A2: Vaal Maseru Klerksdorp | B2: 40000 | D2: 0 | E2: Solar MD | F2: Sunsynk | G2: null | H2: null | I2: South Africa | J2: Free state | K2: Cnr of Mikro and Von Wielligh Streets, Klerksdorp | L2: null | M2: PPA | N2: Commercial | O2: Decommissioned | Q2: SSI | R2: P00044 | S2: null | T2: SA Energy | U2: null | V2: NO | W2: =IF(ISNUMBER(S2),(TODAY()-S2)/365.25,"") | X2: Unknown
A3: 21 Melrose | B3: 14000 | C3: 36 | D3: 35808 | E3: Sunsynk | F3: 3x12kW | G3: None | H3: None | I3: South Africa | J3: Gauteng | K3: 21 Melrose St Melrose | L3: N/A | M3: RTO | N3: Residential | O3: Reduced Demand | Q3: Anuva | R3: P00062 | S3: 45171 | T3: SA Energy | U3: Sunsynk | V3: NO | W3: =IF(ISNUMBER(S3),(TODAY()-S3)/365.25,"") -> 2.9596167 | X3: Low
A4: African Global Plastics | B4: 178000 | C4: =2*80 -> 160 | D4: 0 | E4: N/A | F4: N/A | G4: None | H4: None | I4: South Africa | J4: Gauteng | K4: 1st St & 11th road, Kew, Sandton, 2090 | L4: Alester Meter | M4: PPA | N4: Manufacture | O4: Producing | Q4: SSI | R4: P00008 | S4: null | T4: SA Energy | U4: mypower24 | V4: NO | W4: =IF(ISNUMBER(S4),(TODAY()-S4)/365.25,"") | X4: Medium
A5: Alpine Heath Residential | B5: 36000 | C5: =1*33 -> 33 | D5: 0 | E5: N/A | F5: N/A | G5: None | H5: None | I5: South Africa | J5: KZN | K5: Busingatha, South Africa | L5: Eastron Meter | M5: PPA | N5: Residential | O5: Reduced Demand | Q5: 12B Fund | R5: null | S5: 45658 | T5: SA Energy | U5: isolarCloud | V5: YES | W5: =IF(ISNUMBER(S5),(TODAY()-S5)/365.25,"") -> 1.6262834 | X5: Low
A6: Bendstore Plaza Shops | B6: 110000 | C6: =1*110 -> 110 | D6: 0 | E6: N/A | F6: N/A | G6: N/A | H6: N/A | I6: South Africa | J6: Limpopo | K6: Stand 87, Bendstore Plaza, Giyani Main Rd, Giyani-BA, Giyani, 0832 | L6: null | M6: PPA | N6: Retail | O6: Reduced Demand | Q6: Anuva | R6: P00072 | S6: null | T6: SA Energy | U6: null | V6: NO | W6: =IF(ISNUMBER(S6),(TODAY()-S6)/365.25,"") | X6: Low
A7: Bendstore Spar | B7: 400000 | C7: null | D7: 0 | E7: N/A | F7: N/A | G7: null | H7: null | I7: South Africa | J7: Limpopo | K7: null | L7: null | M7: PPA | N7: Retail | O7: Producing | Q7: Anuva | R7: null | S7: null | T7: SA Energy | U7: null | V7: NO | W7: =IF(ISNUMBER(S7),(TODAY()-S7)/365.25,"") | X7: Low
A8: Beyerskloof | B8: 78000 | C8: null | D8: 0 | E8: N/A | F8: N/A | G8: null | H8: null | I8: South Africa | J8: Western Cape | K8: Koelenhof Street, R304, Koelenhof, Stellenbosch, 7600 | L8: null | M8: PPA | N8: Manufacture | O8: Reduced Demand | Q8: SSI | R8: null | S8: null | T8: Solar Synergy | U8: null | V8: NO | W8: =IF(ISNUMBER(S8),(TODAY()-S8)/365.25,"") | X8: Low
A9: BP Parys | B9: 544000 | C9: 50 | D9: 0 | E9: N/A | F9: N/A | G9: N/A | H9: N/A | I9: South Africa | J9: Free state | K9: 63 Bree St, Parys, 9585 | L9: Eastron Meter | M9: RTO | N9: Retail | O9: Reduced Demand | Q9: SSI | R9: null | T9: SA Energy | U9: null | V9: NO | W9: =IF(ISNUMBER(S9),(TODAY()-S9)/365.25,"") | X9: Low
A10: Buffalo Rock | B10: 15000 | C10: N/A | E10: null | F10: 2x12kW | G10: N/A | H10: N/A | I10: South Africa | J10: Mpumalanga | K10: Hazyview Ehlanzeni District Municipality MP | L10: null | M10: RTO | N10: Residential | O10: Reduced Demand | Q10: SSI | R10: P00054 | S10: 45448 | T10: SA Energy | U10: Sunsynk | V10: NO | W10: =IF(ISNUMBER(S10),(TODAY()-S10)/365.25,"") -> 2.201232 | X10: Low
A11: Checkers De Aar | B11: 154000 | C11: 125 | D11: 0 | E11: N/A | F11: N/A | G11: N/A | H11: NuVo | I11: South Africa | J11: Northern Cape | K11: 21 Alexander St, De Aar, 7000, South Africa | M11: PPA | N11: Retail | O11: Producing | Q11: 12B Fund | R11: P00038 | S11: null | T11: SA Energy | U11: iSolarCloud & NuVo | V11: NO | W11: =IF(ISNUMBER(S11),(TODAY()-S11)/365.25,"") | X11: Low
A12: Checkers Silverlakes Gen | B12: 152000 | C12: 125 | D12: 0 | E12: N/A | F12: N/A | G12: 500 | H12: Nuvo | I12: South Africa | J12: Gauteng | K12: Chamberlain Shopping Cntr (Six Fountains Cnr Solomon Mahlangu Dr, Bendeman Blvd, &, Pretoria, 0081 | L12: Eastron Meter | M12: PPA | N12: Retail | O12: Producing | Q12: 12B Fund | R12: null | S12: 45841 | T12: SA Energy | U12: isolarCloud | V12: NO | W12: =IF(ISNUMBER(S12),(TODAY()-S12)/365.25,"") -> 1.1252567 | X12: Low
A13: Checkers Silverlakes No Gen | B13: 142000 | C13: 125 | D13: 0 | E13: N/A | F13: N/A | G13: N/A | H13: N/A | I13: South Africa | J13: Gauteng | K13: Chamberlain Shopping Cntr (Six Fountains Cnr Solomon Mahlangu Dr, Bendeman Blvd, &, Pretoria, 0081 | L13: Eastron Meter | M13: PPA | N13: Retail | O13: Producing | Q13: 12B Fund | R13: null | S13: 46206 | T13: SA Energy | U13: isolarCloud | V13: NO | W13: =IF(ISNUMBER(S13),(TODAY()-S13)/365.25,"") -> 0.12594114 | X13: Low
A14: Checkrite Inanda | B14: 70000 | C14: =2*33 -> 66 | D14: 0 | E14: N/A | F14: N/A | G14: N/A | H14: N/A | I14: South Africa | J14: Gauteng | K14: 6th Ave, Springs New, Springs, 1560 | L14: null | M14: PPA | N14: Retail | O14: Producing | Q14: 12B Fund | R14: P00056 | S14: 45318 | T14: SA Energy | U14: iSolarCloud | V14: YES | W14: =IF(ISNUMBER(S14),(TODAY()-S14)/365.25,"") -> 2.5571526 | X14: Low
A15: Club Houghton | B15: 60000 | C15: N/A | D15: 84000 | E15: N/A | F15: 6x12kW Sunsynk Inverters | G15: N/A | H15: null | I15: South Africa | J15: Gauteng | K15: Osborn Rd, Houghton Estate, Johannesburg, 2198, South Africa | L15: N/A | M15: PPA | N15: Residential | O15: Reduced Demand | Q15: Anuva | R15: P00067 | S15: null | T15: SA Energy | U15: Sunsysnk;SolarMd | V15: NO | W15: =IF(ISNUMBER(S15),(TODAY()-S15)/365.25,"") | X15: Low
A16: Coldstar International | B16: 41000 | C16: 36 | D16: 0 | E16: N/A | F16: N/A | G16: N/A | H16: N/A | I16: South Africa | J16: KZN | K16: Coldstar International, 3 Rana Rd, Isipingo Rail, Isipingo, 4110 | client miss use data | L16: N/A | M16: PPA | N16: Commercial | O16: Reduced Demand | Q16: Anuva | R16: P00051 | T16: SA Energy | U16: iSolarCloud | V16: NO | W16: =IF(ISNUMBER(S16),(TODAY()-S16)/365.25,"") | X16: Low
A17: Cultura Fresh | B17: 65000 | C17: null | D17: 0 | E17: N/A | F17: N/A | G17: N/A | H17: null | I17: South Africa | J17: Western Cape | K17: null | L17: null | M17: PPA | N17: Agricultural | O17: Reduced Demand | Q17: 12B Fund | R17: null | S17: null | T17: Solar Synergy | U17: null | V17: NO | W17: =IF(ISNUMBER(S17),(TODAY()-S17)/365.25,"") | X17: Low
A18: Demco | B18: 235000 | C18: =2*110 -> 220 | D18: 0 | E18: N/A | F18: N/A | G18: N/A | H18: N/A | I18: South Africa | J18: Gauteng | K18: Industries East, 12 -14 Moller Street, Germiston. 1401 | L18: Alester Meter | M18: PPA | N18: Manufacture | O18: Reduced Demand | Q18: 12B Fund | R18: P00035 | S18: 45047 | T18: SA Energy | U18: iSolarCloud | V18: YES | W18: =IF(ISNUMBER(S18),(TODAY()-S18)/365.25,"") -> 3.2991102 | X18: Low
A19: Giba Gorge Main | B19: 180000 | C19: 160 | D19: 0 | E19: N/A | F19: N/A | G19: N/A | H19: N/A | I19: South Africa | J19: KZN | K19: 5QCJ+XM2 Clifton Canyon, Pinetown Rural | L19: Alester Meter | M19: PPA | N19: Manufacture | O19: Reduced Demand | Q19: SSI | R19: P00069 | S19: null | T19: SA Energy | U19: soliscloud | V19: NO | W19: =IF(ISNUMBER(S19),(TODAY()-S19)/365.25,"") | X19: Low
A20: Giba Gorge Storage | B20: 106000 | C20: null | D20: 0 | E20: N/A | F20: N/A | G20: N/A | H20: null | I20: South Africa | J20: KZN | K20: 5QCJ+XM2 Clifton Canyon, Pinetown Rural | L20: Alester Meter | M20: PPA | N20: Commercial | O20: Reduced Demand | Q20: SSI | R20: null | S20: null | T20: SA Energy | U20: SolisCloud | V20: NO | W20: =IF(ISNUMBER(S20),(TODAY()-S20)/365.25,"") | X20: Low
A21: Golden Spot Resort | B21: 30000 | C21: 33 | D21: 0 | E21: N/A | F21: N/A | G21: N/A | H21: N/A | I21: South Africa | J21: Mpumalanga | K21: HR2M+GQ7 Alkmaar (-25.4487127, 30.8344204) | L21: null | M21: PPA | N21: Residential | O21: Reduced Demand | Q21: SSI | R21: P00071 | S21: 45072 | T21: SA Energy | U21: iSolarCloud | V21: YES | W21: =IF(ISNUMBER(S21),(TODAY()-S21)/365.25,"") -> 3.2306639 | X21: Low
A22: Golden Spot Shops | B22: 30000 | C22: 33 | D22: 0 | E22: N/A | F22: N/A | G22: N/A | H22: N/A | I22: South Africa | J22: Mpumalanga | K22: HR2M+GQ7 Alkmaar (-25.4487127, 30.8344204) | L22: null | M22: PPA | N22: Retail | O22: Producing | Q22: SSI | R22: P00060 | S22: 45072 | T22: SA Energy | U22: iSolarCloud | V22: YES | W22: =IF(ISNUMBER(S22),(TODAY()-S22)/365.25,"") -> 3.2306639 | X22: Low
A23: HB Dunn | B23: 24000 | C23: N/A | D23: 127400 | E23: N/A | F23: 1x50 kW | G23: N/A | H23: N/A | I23: South Africa | J23: Mpumalanga | K23: Kriel Nkangala District Municipality MP | L23: null | M23: RTO | N23: Residential | O23: Reduced Demand | Q23: SSI | R23: P00045 | T23: SA Energy | U23: Sunsynk | V23: NO | W23: =IF(ISNUMBER(S23),(TODAY()-S23)/365.25,"") | X23: Low
A24: Helderberg Collage | B24: 223000 | C24: null | D24: 0 | E24: N/A | F24: N/A | G24: N/A | H24: null | I24: South Africa | J24: Western Cape | K24: null | L24: null | M24: PPA | N24: Residential | O24: Producing | Q24: SSI | R24: null | S24: null | T24: SA Energy | U24: null | V24: NO | W24: =IF(ISNUMBER(S24),(TODAY()-S24)/365.25,"") | X24: Low
A25: Hilston Rotoflo | B25: 240000 | C25: 240 | D25: 0 | E25: N/A | F25: N/A | G25: N/A | H25: N/A | I25: South Africa | J25: Gauteng | K25: 28 Hilston Rd, Kya Sand, Randburg, 2163 | L25: null | M25: PPA | N25: Residential | O25: Producing | Q25: Anuva | R25: P00055 | S25: 45175 | T25: SA Energy | U25: isolarCloud | V25: YES | W25: =IF(ISNUMBER(S25),(TODAY()-S25)/365.25,"") -> 2.9486653 | X25: Low
A26: Huis Herfsblaar | B26: 215000 | C26: =2*110 -> 220 | D26: 0 | E26: N/A | F26: N/A | G26: N/A | H26: N/A | I26: South Africa | J26: Gauteng | K26: Edging Pretoria, 1244 Webb Rd, Queenswood, Pretoria, 0186, South Africa | L26: Eastron Meter | M26: PPA | N26: Commercial | O26: Producing | Q26: 12B Fund | R26: P00034 | S26: 45463 | T26: SA Energy | U26: iSolarCloud | V26: YES | W26: =IF(ISNUMBER(S26),(TODAY()-S26)/365.25,"") -> 2.1601643 | X26: Low
A27: Kool Village | B27: 79000 | C27: null | D27: 0 | E27: N/A | F27: N/A | G27: N/A | H27: null | I27: South Africa | J27: Northern Cape | K27: Kool Village, 89 Virginia Way, Virginia, 9430 | L27: null | M27: null | N27: Commercial | O27: Producing | Q27: Anuva | R27: null | S27: null | T27: SA Energy | U27: null | V27: NO | W27: =IF(ISNUMBER(S27),(TODAY()-S27)/365.25,"") | X27: Low
A28: Mambha Cash & Carry | B28: 184000 | C28: null | D28: 0 | E28: N/A | F28: N/A | G28: N/A | H28: null | I28: South Africa | J28: KZN | K28: null | L28: null | M28: PPA | N28: Retail | O28: Producing | Q28: Anuva | R28: P00015 | S28: null | T28: SA Energy | U28: mypower24 | V28: NO | W28: =IF(ISNUMBER(S28),(TODAY()-S28)/365.25,"") | X28: Medium
A29: Mathe Group Company | B29: 518000 | C29: =4*110 -> 440 | D29: 0 | E29: N/A | F29: N/A | G29: N/A | H29: N/A | I29: South Africa | J29: KZN | K29: 4/160 Buckman Blvd, Cato Ridge, 3699, South Africa | L29: null | M29: PPA | N29: Manufacture | O29: Producing | Q29: Anuva | R29: P00059 | S29: 44662 | T29: SA Energy | U29: iSolarCloud | W29: =IF(ISNUMBER(S29),(TODAY()-S29)/365.25,"") -> 4.3531828 | X29: Low
A30: Mdluli | B30: 114000 | C30: null | D30: 0 | E30: N/A | F30: N/A | G30: N/A | H30: null | I30: South Africa | J30: Mpumalanga | K30: Makoko, South Africa,1251 | L30: null | M30: PPA | N30: Residential | O30: Reduced Demand | Q30: 12B Fund | R30: P00083 | S30: 45352 | T30: SA Energy | U30: mypower24&IsolarCloud | V30: YES | W30: =IF(ISNUMBER(S30),(TODAY()-S30)/365.25,"") -> 2.4640657 | X30: Low
A31: Meredale Heights | B31: 33000 | C31: =1*33 -> 33 | D31: 0 | E31: N/A | F31: N/A | G31: N/A | H31: N/A | I31: South Africa | J31: Gauteng | K31: 40 thomas street | L31: null | M31: PPA | N31: Residential | O31: Producing | Q31: Anuva | R31: P00052 | S31: 44963 | T31: SA Energy | U31: iSolarCloud | V31: YES | W31: =IF(ISNUMBER(S31),(TODAY()-S31)/365.25,"") -> 3.5290897 | X31: Low
A32: Monument Park Checkers | B32: 281000 | C32: =2*125 -> 250 | D32: 0 | E32: N/A | F32: N/A | G32: N/A | H32: NuVo | I32: South Africa | J32: Gauteng | K32: 242 Voortrekker Rd, Monument, Krugersdorp, 1739, South Africa | L32: null | M32: PPA | N32: Retail | O32: Producing | Q32: Anuva | R32: P00037 | S32: null | T32: SA Energy | U32: isloarcloud &Nuvo | V32: NO | W32: =IF(ISNUMBER(S32),(TODAY()-S32)/365.25,"") | X32: Low
A33: Nkambeni Industrial | B33: 158400 | C33: 125 | D33: 0 | E33: Solar MD | F33: Atess PCS500 | G33: N/A | H33: null | I33: South Africa | J33: Mpumalanga | K33: 139 Numbi Rd Numbi Gate Kruger National Park, Hazyview, 1350 | L33: null | M33: RTO | N33: Residential | O33: Reduced Demand | Q33: SSI | R33: P00040 | S33: null | T33: SA Energy | U33: null | V33: NO | W33: =IF(ISNUMBER(S33),(TODAY()-S33)/365.25,"") | X33: Low
A34: Opal Students | B34: 35000 | C34: =1*33 -> 33 | D34: 0 | E34: N/A | F34: N/A | G34: N/A | H34: N/A | I34: South Africa | J34: Gauteng | K34: Opal students | L34: null | M34: RTO | N34: Retail | O34: Producing | Q34: Anuva | R34: P00057 | S34: 45174 | T34: SA Energy | U34: iSolarCloud | V34: YES | W34: =IF(ISNUMBER(S34),(TODAY()-S34)/365.25,"") -> 2.9514031 | X34: Low
A35: Orthochem Bethlehem | B35: 220000 | C35: null | D35: 0 | E35: N/A | F35: N/A | G35: N/A | H35: null | I35: South Africa | J35: Free state | K35: 6 Sauer Street Bethlehem Free State 9700 | L35: null | M35: PPA | N35: Manufacture | O35: Producing | Q35: SSI | R35: P00063 | S35: null | T35: SA Energy | U35: isolarcloud, & NuVO | V35: NO | W35: =IF(ISNUMBER(S35),(TODAY()-S35)/365.25,"") | X35: Low
A36: Plastiplate | B36: 66000 | C36: =2*33 -> 66 | D36: 0 | E36: N/A | F36: N/A | G36: N/A | H36: N/A | I36: South Africa | J36: Gauteng | K36: 6 adderley, Roodepoort, 1724, South Africa | L36: null | M36: PPA | N36: Manufacture | O36: Producing | Q36: Anuva | R36: P00061 | S36: 44688 | T36: SA Energy | U36: iSolarCloud | V36: YES | W36: =IF(ISNUMBER(S36),(TODAY()-S36)/365.25,"") -> 4.2819986 | X36: Low
A37: PNB Unlimited | B37: 95000 | C37: null | D37: 0 | E37: N/A | F37: N/A | G37: N/A | H37: null | I37: South Africa | J37: North West | K37: 8X4H+VXW Amaoti | L37: null | M37: PPA | N37: Commercial | O37: Producing | Q37: SSI | R37: null | S37: null | T37: SA Energy | U37: null | V37: NO | W37: =IF(ISNUMBER(S37),(TODAY()-S37)/365.25,"") | X37: Low
A38: Q-lity Meat | B38: 35000 | C38: 30 | D38: 0 | E38: N/A | F38: N/A | G38: N/A | H38: NuVo | I38: South Africa | J38: Gauteng | K38: null | L38: null | M38: PPA | N38: Retail | O38: Producing | Q38: SSI | R38: P00007 | S38: null | T38: SA Energy | U38: isloarcloud &Nuvo | V38: NO | W38: =IF(ISNUMBER(S38),(TODAY()-S38)/365.25,"") | X38: Low
A39: Quintondale | B39: 40000 | C39: 33 | D39: 0 | E39: N/A | F39: N/A | G39: N/A | H39: N/A | I39: South Africa | J39: Gauteng | K39: 43 Orchards Street, Johannesburg, Johannesburg, Gauteng 2192, South Africa | L39: null | M39: PPA | N39: Residential | O39: Reduced Demand | Q39: SSI | R39: P00065 | S39: null | T39: SA Energy | U39: null | V39: NO | W39: =IF(ISNUMBER(S39),(TODAY()-S39)/365.25,"") | X39: Low
A40: Riverside Lodge | B40: 110000 | C40: =2*50 -> 100 | D40: 0 | E40: N/A | F40: N/A | G40: N/A | H40: N/A | I40: South Africa | J40: North West | K40: Hartbeespoort, South Africa | L40: null | M40: PPA | N40: Residential | O40: Producing | Q40: Anuva | R40: P00053 | S40: 45265 | T40: SA Energy | U40: iSolarCloud | V40: YES | W40: =IF(ISNUMBER(S40),(TODAY()-S40)/365.25,"") -> 2.7022587 | X40: Low
...

Sheet Simulated Production
A1: Site Name | B1: Jan | C1: Feb | D1: Mar | E1: Apr | F1: May | G1: Jun | H1: Jul | I1: Aug | J1: Sep | K1: Oct | L1: Nov | M1: Dec
A2: 21 Melrose | B2: 2634 | C2: 2978 | D2: 2426 | E2: 2082 | F2: 2025 | G2: 1810 | H2: 2016 | I2: 2352 | J2: 2528 | K2: 2675 | L2: 2618 | M2: 2758
A3: African Global Plastics | B3: 26489.3 | C3: 23277.8 | D3: 23704 | E3: 19723.4 | F3: 18790.7 | G3: 16902.6 | H3: 18714.9 | I3: 21796.9 | J3: 24005.1 | K3: 26259.6 | L3: 26494.9 | M3: 27974.1
A4: Alpine Heath Residential | B4: 5335 | C4: 4782 | D4: 5051 | E4: 5133 | F4: 5545 | G4: 5291 | H4: 5201 | I4: 5833 | J4: 5216 | K4: 5258 | L4: 5358 | M4: 5339
A5: Bendstore Plaza Shops | B5: 19132 | C5: 16455 | D5: 18192 | E5: 17513 | F5: 16955 | G5: 15353 | H5: 16159 | I5: 18059 | J5: 18155 | K5: 17437 | L5: 17289 | M5: 19005
A6: Bendstore Spar | B6: 57016.372 | C6: 49003.656 | D6: 54154.745 | E6: 52055.443 | F6: 50303.593 | G6: 45493.302 | H6: 47903.114 | I6: 53629.448 | J6: 54003.213 | K6: 51943.234 | L6: 51542.757 | M6: 56267.013
A7: Beyerskloof | B7: 15319 | C7: 12622 | D7: 12090 | E7: 8698 | F7: 6615 | G7: 5740 | H7: 6183 | I7: 7734 | J7: 9940 | K7: 12572 | L7: 14126 | M7: 15421
A8: BP Parys | B8: 9057 | C8: 8039 | D8: 7862 | E8: 6394 | F8: 6027 | G8: 5319 | H8: 5956 | I8: 7070 | J8: 8021 | K8: 8710 | L8: =9102 -> 9102 | M8: 9142
A9: Buffalo Rock | B9: 2447 | C9: 2204 | D9: 2364 | E9: 1964 | F9: 1813 | G9: 1645 | H9: 1792 | I9: 1960 | J9: 2076 | K9: 2112 | L9: 2039 | M9: 2207
A10: Checkers De Aar | B10: 29655 | C10: 22972 | D10: 22328 | E10: 18096 | F10: 15021 | G10: 13183 | H10: 15099 | I10: 19010 | J10: 21674 | K10: 26757 | L10: 28766 | M10: 31103
A11: Checkers Silverlakes Gen | B11: 23450 | C11: 20245 | D11: 20409 | E11: 16782 | F11: 15700 | G11: 14022 | H11: 15558 | I11: 18491 | J11: 20696 | K11: 22782 | L11: 22890 | M11: 24472
A12: Checkers Silverlakes No Gen | B12: 23450 | C12: 20245 | D12: 20409 | E12: 16782 | F12: 15700 | G12: 14022 | H12: 15558 | I12: 18491 | J12: 20696 | K12: 22782 | L12: 22890 | M12: 24472
A13: Checkrite Inanda | B13: 9627 | C13: 9000 | D13: 8673 | E13: 7260 | F13: 6214 | G13: 5622 | H13: 5969 | I13: 7206 | J13: 7683 | K13: 8926 | L13: 8903 | M13: 9497
A14: Club Houghton | B14: 6408 | C14: 5365 | D14: 5459 | E14: 4611 | F14: 4375 | G14: 3848 | H14: 4305 | I14: 5067 | J14: 5593 | K14: 6237 | L14: 6347 | M14: 6697
A15: Coldstar International | B15: 5761.2 | C15: 5289.7 | D15: 5351.3 | E15: 4476.7 | F15: 4144.2 | G15: 3750.5 | H15: 4019 | I15: 4537.7 | J15: 4477.3 | K15: 4986.7 | L15: 5100.4 | M15: 5950.6
A16: Cultura Fresh | B16: 13109 | C16: 11411 | D16: 11746 | E16: 9262 | F16: 7471 | G16: 6511 | H16: 7170 | I16: 8324 | J16: 9849 | K16: 11513 | L16: 12192 | M16: 12923
A17: Demco | B17: 41895 | C17: 35971 | D17: 36483 | E17: 30848 | F17: 29226 | G17: 26233 | H17: 29069 | I17: 34133 | J17: 37890 | K17: 41280 | L17: 41518 | M17: 43833
A18: Engen Lotus Gardens | B18: 2735 | C18: 2556 | D18: 2535 | E18: 2442 | F18: 2474 | G18: 2756 | H18: 2611 | I18: 2800 | J18: 2707 | K18: 2695 | L18: 2618 | M18: 2708
A19: Giba Gorge Main | B19: 16980 | C19: 15556.6 | D19: 15927.6 | E19: 13677.3 | F19: 12351.6 | G19: 11543.6 | H19: 12195.1 | I19: 13528 | J19: 13644.6 | K19: 15166.4 | L19: 15407.487 | M19: 16842.372
A20: Giba Gorge Storage | B20: 15179.5 | C20: 13524.8 | D20: 13861.9 | E20: 11789.7 | F20: 10618.3 | G20: 9819.1 | H20: 10486.9 | I20: 11678.3 | J20: 11941.8 | K20: 13277 | L20: 13346.218 | M20: 14828.668
... A22: Golden Spot Shops | B22: 4020 | C22: 3616 | D22: 4009 | E22: 3292 | F22: 3026 | G22: 2735 | H22: 3002 | I22: 3304 | J22: 3497 | K22: 3533 | L22: 3348 | M22: 3560
A23: Grootpan
A24: HB Dunn | B24: 4706 | C24: 4110 | D24: 4209 | E24: 3538 | F24: 3392 | G24: 3058 | H24: 3366 | I24: 3941 | J24: 4346 | K24: 4559 | L24: 4578 | M24: 4864
A25: Helderberg Collage | B25: 44000.9 | C25: 36738.8 | D25: 35799.5 | E25: 26238.2 | F25: 19947.3 | G25: 16584 | H25: 18638.7 | I25: 23207.5 | J25: 29655.5 | K25: 36694.1 | L25: 41235.3 | M25: 44584.1
A26: Hilston Rotoflo | B26: 32657 | C26: 28530 | D26: 26894 | E26: 23945 | F26: 21446 | G26: 18974 | H26: 21123 | I26: 24633 | J26: 27402 | K26: 30501 | L26: 32028 | M26: 31475
A27: Huis Herfsblaar | B27: 33572 | C27: 29313 | D27: 30629 | E27: 26386 | F27: 25077 | G27: 22476 | H27: 24838 | I27: 29965 | J27: 32045 | K27: 33620 | L27: 32645 | M27: 34688
A28: IPID - Floor 4 | B28: 8415 | C28: 7237.5 | D28: 7601.5 | E28: 6870 | F28: 6583 | G28: 5884 | H28: 6428 | I28: 7317 | J28: 7798.5 | K28: 8310.5 | L28: 8392 | M28: 8239
A29: IPID - Floor 6 | B29: 8415 | C29: 7237.5 | D29: 7601.5 | E29: 6870 | F29: 6583 | G29: 5884 | H29: 6428 | I29: 7317 | J29: 7798.5 | K29: 8310.5 | L29: 8392 | M29: 8239
A30: Kool Village | B30: 13570 | C30: 11745 | D30: 11799 | E30: 10155 | F30: 9548 | G30: 8534 | H30: 9501 | I30: 11108 | J30: 11891 | K30: 13149 | L30: 13477 | M30: 14443
A31: Makalali
A32: Mambha Cash & Carry | B32: 24713 | C32: 21612 | D32: 21750 | E32: 17547 | F32: 14975 | G32: 13472 | H32: 14555 | I32: 17167 | J32: 18426 | K32: 21592 | L32: 22234 | M32: 24984
A33: Mathe Group Company | B33: 72121 | C33: 65458 | D33: 68264 | E33: 57584 | F33: 52130 | G33: 48157 | H33: 51738 | I33: 57201 | J33: 59213 | K33: 64977 | L33: 66569 | M33: 71854
A34: Mdluli | B34: 17634 | C34: 16473 | D34: 19238 | E34: 17065 | F34: 16886 | G34: 16099 | H34: 17101 | I34: 17348 | J34: 16879 | K34: 15944 | L34: 14731 | M34: 15377
A35: Medipost | B35: 59291 | C35: 48612 | D35: 45479 | E35: 32312 | F35: 23816 | G35: 19426 | H35: 21982 | I35: 28360 | J35: 37091 | K35: 47820 | L35: 55073 | M35: 60151
A36: Meredale Heights | B36: 5957 | C36: 5410 | D36: 5967 | E36: 5723 | F36: 6086 | G36: 5885 | H36: 6334 | I36: 6633 | J36: 6573 | K36: 6461 | L36: 6012 | M36: 6145
A37: Monument Park Checkers | B37: 44907 | C37: 37765 | D37: 39036 | E37: 33226 | F37: 31537 | G37: 28491 | H37: 31513 | I37: 36674 | J37: 40579 | K37: 44092 | L37: 44165 | M37: 47244
A38: Nkambeni Industrial | B38: 23544 | C38: 21677 | D38: 24212 | E38: 20861 | F38: 20012 | G38: 18485 | H38: 20016 | I38: 21052 | J38: 21403 | K38: 20962 | L38: 19856 | M38: 21184
A39: Olievenhoutbosch 1 | B39: 52080 | C39: 45544 | D39: 44433 | E39: 38648 | F39: 35710 | G39: 31508 | H39: 34699 | I39: 40906 | J39: 45309 | K39: 51347 | L39: 51837 | M39: 52952
A40: Olievenhoutbosch 2 | B40: 13744 | C40: 12002 | D40: 11708 | E40: 10193 | F40: 9448 | G40: 8384 | H40: 9230 | I40: 10801 | J40: 11951 | K40: 13545 | L40: 13626 | M40: 13933
A41: Opal Students | B41: 6317 | C41: 5312 | D41: 5484 | E41: 4844 | F41: 4660 | G41: 4243 | H41: 4686 | I41: 5383 | J41: 5889 | K41: 6297 | L41: 6249 | M41: 6662
...

Sheet OG
A1: Site Name | B1: Offtake Guarantee | C1: Expected Utilisation% | D1: Age | E1: As-Built kWh | F1: Guaranteed Generation (kWh) | G1: Unavailability kWh | H1: Correct kWh | I1: Actual Generation (kWh) | J1: Shortfall (kWh) | K1: Performance Rate | L1: Notes
A2: Alpine Heath Residential | B2: YES | C2: {=IFERROR(INDEX('Expected Production'!$B$2:$B$80,MATCH(TRIM($A2),INDEX(TRIM('Expected Production'!$A$2:$A$80),0),0)),"Not found")} -> 0.9 | D2: {=_xlfn.IFNA(_xlfn.XLOOKUP(TRIM(A2),TRIM(site_tech_info!$A$2:$A$79),site_tech_info!$W$2:$W$79),"")} -> 1.6262834 | E2: {=IFERROR(SUM(INDEX('Simulated Production'!$B$2:$M$80,MATCH(TRIM($A2),INDEX(TRIM('Simulated Production'!$A$2:$A$80),0),0),0)),"Not found")} -> 63342 | F2: =(Table2[[#This Row],[As-Built kWh]]*Table2[[#This Row],[Expected Utilisation%]])*(1-0.007)^(Table2[[#This Row],[Age]]) -> 56360.248 | G2: =(4681+4732*(9/31)+4546*(10/31)+4620*(3/30)+4991+4762)*(1-0.007)^(Table2[[#This Row],[Age]]) -> 17534.792 | H2: =F2-G2 -> 38825.456 | I2: {=SUMPRODUCT((TRIM(measured[Site Name])=TRIM($A2))*(measured[Date]>=DATE(2025,7,1))*(measured[Date]<=DATE(2026,6,30))*measured[Measured Value (kWh)])} -> 34917.2 | J2: =I2-H2 -> -3908.2562 | K2: =(Table2[[#This Row],[Actual Generation (kWh)]]/Table2[[#This Row],[Correct kWh]])*100 -> 89.933779 | L2: The system performed moderately. A few technical issues were experienced , the expected system production was corrected and system restored to normal production.
A3: Checkrite Inanda | B3: YES | C3: {=IFERROR(INDEX('Expected Production'!$B$2:$B$80,MATCH(TRIM($A3),INDEX(TRIM('Expected Production'!$A$2:$A$80),0),0)),"Not found")} -> 0.9 | D3: {=_xlfn.IFNA(_xlfn.XLOOKUP(TRIM(A3),TRIM(site_tech_info!$A$2:$A$79),site_tech_info!$W$2:$W$79),"")} -> 2.5571526 | E3: {=IFERROR(SUM(INDEX('Simulated Production'!$B$2:$M$80,MATCH(TRIM($A3),INDEX(TRIM('Simulated Production'!$A$2:$A$80),0),0),0)),"Not found")} -> 94580 | F3: =(Table2[[#This Row],[As-Built kWh]]*Table2[[#This Row],[Expected Utilisation%]])*(1-0.007)^(Table2[[#This Row],[Age]]) -> 83606.604 | G3: =(8100*(1/2)+7806*(1/2))*(1-0.007)^(Table2[[#This Row],[Age]]) -> 7811.4156 | H3: =F3-G3 -> 75795.188 | I3: {=SUMPRODUCT((TRIM(measured[Site Name])=TRIM($A3))*(measured[Date]>=DATE(2025,7,1))*(measured[Date]<=DATE(2026,6,30))*measured[Measured Value (kWh)])} -> 76046.756 | J3: =I3-H3 -> 251.56778 | K3: =(Table2[[#This Row],[Actual Generation (kWh)]]/Table2[[#This Row],[Correct kWh]])*100 -> 100.3319 | L3: The system performed as expected. A few technical issues were experienced during Feb 2026, the expected system production was corrected and system restored to normal production.
A4: Demco | B4: YES | C4: {=IFERROR(INDEX('Expected Production'!$B$2:$B$80,MATCH(TRIM($A4),INDEX(TRIM('Expected Production'!$A$2:$A$80),0),0)),"Not found")} -> 0.8 | D4: {=_xlfn.IFNA(_xlfn.XLOOKUP(TRIM(A4),TRIM(site_tech_info!$A$2:$A$79),site_tech_info!$W$2:$W$79),"")} -> 3.2991102 | E4: {=IFERROR(SUM(INDEX('Simulated Production'!$B$2:$M$80,MATCH(TRIM($A4),INDEX(TRIM('Simulated Production'!$A$2:$A$80),0),0),0)),"Not found")} -> 428379 | F4: =(Table2[[#This Row],[As-Built kWh]]*Table2[[#This Row],[Expected Utilisation%]])*(1-0.007)^(Table2[[#This Row],[Age]]) -> 334852.38 | G4: =(23255*(7/30)+35066*(2/30))*(1-0.007)^(Table2[[#This Row],[Age]]) -> 7586.0407 | H4: =F4-G4 -> 327266.34 | I4: {=SUMPRODUCT((TRIM(measured[Site Name])=TRIM($A4))*(measured[Date]>=DATE(2025,7,1))*(measured[Date]<=DATE(2026,6,30))*measured[Measured Value (kWh)])} -> 166060.42 | J4: =I4-H4 -> -161205.92 | K4: =(Table2[[#This Row],[Actual Generation (kWh)]]/Table2[[#This Row],[Correct kWh]])*100 -> 50.741674 | L4: The system performed as expected. As previously experienced, the site demand is low and the system was not fully utilized.
A5: Golden Spot Resort | B5: YES | C5: {=IFERROR(INDEX('Expected Production'!$B$2:$B$80,MATCH(TRIM($A5),INDEX(TRIM('Expected Production'!$A$2:$A$80),0),0)),"Not found")} -> 0.9 | D5: {=_xlfn.IFNA(_xlfn.XLOOKUP(TRIM(A5),TRIM(site_tech_info!$A$2:$A$79),site_tech_info!$W$2:$W$79),"")} -> 3.2306639 | E5: {=IFERROR(SUM(INDEX('Simulated Production'!$B$2:$M$80,MATCH(TRIM($A5),INDEX(TRIM('Simulated Production'!$A$2:$A$80),0),0),0)),"Not found")} -> 45617 | F5: =(Table2[[#This Row],[As-Built kWh]]*Table2[[#This Row],[Expected Utilisation%]])*(1-0.007)^(Table2[[#This Row],[Age]]) -> 40134.077 | G5: =(4681+3499*(9/31)+2081*(10/31)+4317*(3/30)+4991*(18/31))*(1-0.007)^(Table2[[#This Row],[Age]]) -> 9480.2234 | H5: =F5-G5 -> 30653.853 | I5: {=SUMPRODUCT((TRIM(measured[Site Name])=TRIM($A5))*(measured[Date]>=DATE(2025,7,1))*(measured[Date]<=DATE(2026,6,30))*measured[Measured Value (kWh)])} -> 24341.6 | J5: =I5-H5 -> -6312.2534 | K5: =(Table2[[#This Row],[Actual Generation (kWh)]]/Table2[[#This Row],[Correct kWh]])*100 -> 79.407961
A6: Golden Spot Shops | B6: YES | C6: {=IFERROR(INDEX('Expected Production'!$B$2:$B$80,MATCH(TRIM($A6),INDEX(TRIM('Expected Production'!$A$2:$A$80),0),0)),"Not found")} -> 0.9 | D6: {=_xlfn.IFNA(_xlfn.XLOOKUP(TRIM(A6),TRIM(site_tech_info!$A$2:$A$79),site_tech_info!$W$2:$W$79),"")} -> 3.2306639 | E6: {=IFERROR(SUM(INDEX('Simulated Production'!$B$2:$M$80,MATCH(TRIM($A6),INDEX(TRIM('Simulated Production'!$A$2:$A$80),0),0),0)),"Not found")} -> 40942 | F6: =(Table2[[#This Row],[As-Built kWh]]*Table2[[#This Row],[Expected Utilisation%]])*(1-0.007)^(Table2[[#This Row],[Age]]) -> 36020.987 | G6: =(2974*(24/31)+3147*(2/30))*(1-0.007)^(Table2[[#This Row],[Age]]) -> 2455.8802 | H6: =F6-G6 -> 33565.107 | I6: {=SUMPRODUCT((TRIM(measured[Site Name])=TRIM($A6))*(measured[Date]>=DATE(2025,7,1))*(measured[Date]<=DATE(2026,6,30))*measured[Measured Value (kWh)])} -> 32105.5 | J6: =I6-H6 -> -1459.6069 | K6: =(Table2[[#This Row],[Actual Generation (kWh)]]/Table2[[#This Row],[Correct kWh]])*100 -> 95.651416 | L6: Testing
A7: Hilston Rotoflo | B7: YES | C7: {=IFERROR(INDEX('Expected Production'!$B$2:$B$80,MATCH(TRIM($A7),INDEX(TRIM('Expected Production'!$A$2:$A$80),0),0)),"Not found")} -> 0.85 | D7: {=_xlfn.IFNA(_xlfn.XLOOKUP(TRIM(A7),TRIM(site_tech_info!$A$2:$A$79),site_tech_info!$W$2:$W$79),"")} -> 2.9486653 | E7: {=IFERROR(SUM(INDEX('Simulated Production'!$B$2:$M$80,MATCH(TRIM($A7),INDEX(TRIM('Simulated Production'!$A$2:$A$80),0),0),0)),"Not found")} -> 319608 | F7: =(Table2[[#This Row],[As-Built kWh]]*Table2[[#This Row],[Expected Utilisation%]])*(1-0.007)^(Table2[[#This Row],[Age]]) -> 266097.58 | G7: 0 | H7: =F7-G7 -> 266097.58 | I7: {=SUMPRODUCT((TRIM(measured[Site Name])=TRIM($A7))*(measured[Date]>=DATE(2025,7,1))*(measured[Date]<=DATE(2026,6,30))*measured[Measured Value (kWh)])} -> 254905.02 | J7: =I7-H7 -> -11192.558 | K7: =(Table2[[#This Row],[Actual Generation (kWh)]]/Table2[[#This Row],[Correct kWh]])*100 -> 95.793814 | L7: The system performed as expected. System produced 96% of expected production due to 20 days of closure during December-Jan.
A8: Huis Herfsblaar | B8: YES | C8: {=IFERROR(INDEX('Expected Production'!$B$2:$B$80,MATCH(TRIM($A8),INDEX(TRIM('Expected Production'!$A$2:$A$80),0),0)),"Not found")} -> 0.9 | D8: {=_xlfn.IFNA(_xlfn.XLOOKUP(TRIM(A8),TRIM(site_tech_info!$A$2:$A$79),site_tech_info!$W$2:$W$79),"")} -> 2.1601643 | E8: {=IFERROR(SUM(INDEX('Simulated Production'!$B$2:$M$80,MATCH(TRIM($A8),INDEX(TRIM('Simulated Production'!$A$2:$A$80),0),0),0)),"Not found")} -> 355254 | F8: =(Table2[[#This Row],[As-Built kWh]]*Table2[[#This Row],[Expected Utilisation%]])*(1-0.007)^(Table2[[#This Row],[Age]]) -> 314913.56 | G8: =((22354*(0.5)+26969*(7/31))*(1-0.007)^(Table2[[#This Row],[Age]]))*(1-0.007)^(Table2[[#This Row],[Age]]) -> 16750.623 | H8: =F8-G8 -> 298162.94 | I8: {=SUMPRODUCT((TRIM(measured[Site Name])=TRIM($A8))*(measured[Date]>=DATE(2025,7,1))*(measured[Date]<=DATE(2026,6,30))*measured[Measured Value (kWh)])} -> 271722.18 | J8: =I8-H8 -> -26440.758 | K8: =(Table2[[#This Row],[Actual Generation (kWh)]]/Table2[[#This Row],[Correct kWh]])*100 -> 91.132111 | L8: The system performed as expected. A few technical issues were experienced during July - Aug 2025, the expected system production was corrected and system restored to normal production.
A9: Mdluli | B9: YES | C9: {=IFERROR(INDEX('Expected Production'!$B$2:$B$80,MATCH(TRIM($A9),INDEX(TRIM('Expected Production'!$A$2:$A$80),0),0)),"Not found")} -> 0.8 | D9: {=_xlfn.IFNA(_xlfn.XLOOKUP(TRIM(A9),TRIM(site_tech_info!$A$2:$A$79),site_tech_info!$W$2:$W$79),"")} -> 2.4640657 | E9: {=IFERROR(SUM(INDEX('Simulated Production'!$B$2:$M$80,MATCH(TRIM($A9),INDEX(TRIM('Simulated Production'!$A$2:$A$80),0),0),0)),"Not found")} -> 200775 | F9: =(Table2[[#This Row],[As-Built kWh]]*Table2[[#This Row],[Expected Utilisation%]])*(1-0.007)^(Table2[[#This Row],[Age]]) -> 157863.73 | G9: =('Expected Production'!I34*0.5+'Expected Production'!C34*0.8)*(1-0.007)^(Table2[[#This Row],[Age]]) -> 17815.112 | H9: =F9-G9 -> 140048.62 | I9: {=SUMPRODUCT((TRIM(measured[Site Name])=TRIM($A9))*(measured[Date]>=DATE(2025,7,1))*(measured[Date]<=DATE(2026,6,30))*measured[Measured Value (kWh)])} -> 147166.31 | J9: =I9-H9 -> 7117.6886 | K9: =(Table2[[#This Row],[Actual Generation (kWh)]]/Table2[[#This Row],[Correct kWh]])*100 -> 105.0823 | L9: The system performed as expected. A few technical issues were experienced during July - Aug 2025 and Jan 2026 which limited inverter production during repairs, the expected system production was corrected and system restored to normal production.
A10: Meredale Heights | B10: YES | C10: {=IFERROR(INDEX('Expected Production'!$B$2:$B$80,MATCH(TRIM($A10),INDEX(TRIM('Expected Production'!$A$2:$A$80),0),0)),"Not found")} -> 0.9 | D10: {=_xlfn.IFNA(_xlfn.XLOOKUP(TRIM(A10),TRIM(site_tech_info!$A$2:$A$79),site_tech_info!$W$2:$W$79),"")} -> 3.5290897 | E10: {=IFERROR(SUM(INDEX('Simulated Production'!$B$2:$M$80,MATCH(TRIM($A10),INDEX(TRIM('Simulated Production'!$A$2:$A$80),0),0),0)),"Not found")} -> 73186 | F10: =(Table2[[#This Row],[As-Built kWh]]*Table2[[#This Row],[Expected Utilisation%]])*(1-0.007)^(Table2[[#This Row],[Age]]) -> 64254.588 | G10: 0 | H10: =F10-G10 -> 64254.588 | I10: {=SUMPRODUCT((TRIM(measured[Site Name])=TRIM($A10))*(measured[Date]>=DATE(2025,7,1))*(measured[Date]<=DATE(2026,6,30))*measured[Measured Value (kWh)])} -> 61467.39 | J10: =I10-H10 -> -2787.1983 | K10: =(Table2[[#This Row],[Actual Generation (kWh)]]/Table2[[#This Row],[Correct kWh]])*100 -> 95.662258 | L10: The system performed as expected. As previously experienced, the site demand is low and the system was not fully utilized.
A11: Opal Students | B11: YES | C11: {=IFERROR(INDEX('Expected Production'!$B$2:$B$80,MATCH(TRIM($A11),INDEX(TRIM('Expected Production'!$A$2:$A$80),0),0)),"Not found")} -> 0.9 | D11: {=_xlfn.IFNA(_xlfn.XLOOKUP(TRIM(A11),TRIM(site_tech_info!$A$2:$A$79),site_tech_info!$W$2:$W$79),"")} -> 2.9514031 | E11: {=IFERROR(SUM(INDEX('Simulated Production'!$B$2:$M$80,MATCH(TRIM($A11),INDEX(TRIM('Simulated Production'!$A$2:$A$80),0),0),0)),"Not found")} -> 66026 | F11: =(Table2[[#This Row],[As-Built kWh]]*Table2[[#This Row],[Expected Utilisation%]])*(1-0.007)^(Table2[[#This Row],[Age]]) -> 58204.089 | G11: 0 | H11: =F11-G11 -> 58204.089 | I11: {=SUMPRODUCT((TRIM(measured[Site Name])=TRIM($A11))*(measured[Date]>=DATE(2025,7,1))*(measured[Date]<=DATE(2026,6,30))*measured[Measured Value (kWh)])} -> 46668.7 | J11: =I11-H11 -> -11535.389 | K11: =(Table2[[#This Row],[Actual Generation (kWh)]]/Table2[[#This Row],[Correct kWh]])*100 -> 80.181136 | L11: Testing
A12: Plastiplate | B12: YES | C12: {=IFERROR(INDEX('Expected Production'!$B$2:$B$80,MATCH(TRIM($A12),INDEX(TRIM('Expected Production'!$A$2:$A$80),0),0)),"Not found")} -> 0.75 | D12: {=_xlfn.IFNA(_xlfn.XLOOKUP(TRIM(A12),TRIM(site_tech_info!$A$2:$A$79),site_tech_info!$W$2:$W$79),"")} -> 4.2819986 | E12: {=IFERROR(SUM(INDEX('Simulated Production'!$B$2:$M$80,MATCH(TRIM($A12),INDEX(TRIM('Simulated Production'!$A$2:$A$80),0),0),0)),"Not found")} -> 125072.5 | F12: =(Table2[[#This Row],[As-Built kWh]]*Table2[[#This Row],[Expected Utilisation%]])*(1-0.007)^(Table2[[#This Row],[Age]]) -> 91024.81 | G12: =(5691*0.3*(1-0.007)^(Table2[[#This Row],[Age]]))*(1-0.007)^(Table2[[#This Row],[Age]]) -> 1607.6193 | H12: =F12-G12 -> 89417.191 | I12: {=SUMPRODUCT((TRIM(measured[Site Name])=TRIM($A12))*(measured[Date]>=DATE(2025,7,1))*(measured[Date]<=DATE(2026,6,30))*measured[Measured Value (kWh)])} -> 72438 | J12: =I12-H12 -> -16979.191 | K12: =(Table2[[#This Row],[Actual Generation (kWh)]]/Table2[[#This Row],[Correct kWh]])*100 -> 81.011268 | L12: Testing
A13: Riverside Lodge | B13: YES | C13: {=IFERROR(INDEX('Expected Production'!$B$2:$B$80,MATCH(TRIM($A13),INDEX(TRIM('Expected Production'!$A$2:$A$80),0),0)),"Not found")} -> 0.85 | D13: {=_xlfn.IFNA(_xlfn.XLOOKUP(TRIM(A13),TRIM(site_tech_info!$A$2:$A$79),site_tech_info!$W$2:$W$79),"")} -> 2.7022587 | E13: {=IFERROR(SUM(INDEX('Simulated Production'!$B$2:$M$80,MATCH(TRIM($A13),INDEX(TRIM('Simulated Production'!$A$2:$A$80),0),0),0)),"Not found")} -> 225937 | F13: =(Table2[[#This Row],[As-Built kWh]]*Table2[[#This Row],[Expected Utilisation%]])*(1-0.007)^(Table2[[#This Row],[Age]]) -> 188435.34 | G13: 0 | H13: =F13-G13 -> 188435.34 | I13: {=SUMPRODUCT((TRIM(measured[Site Name])=TRIM($A13))*(measured[Date]>=DATE(2025,7,1))*(measured[Date]<=DATE(2026,6,30))*measured[Measured Value (kWh)])} -> 176720.45 | J13: =I13-H13 -> -11714.894 | K13: =(Table2[[#This Row],[Actual Generation (kWh)]]/Table2[[#This Row],[Correct kWh]])*100 -> 93.78307 | L13: Testing
A14: The Alec | B14: YES | C14: {=IFERROR(INDEX('Expected Production'!$B$2:$B$80,MATCH(TRIM($A14),INDEX(TRIM('Expected Production'!$A$2:$A$80),0),0)),"Not found")} -> 0.925 | D14: {=_xlfn.IFNA(_xlfn.XLOOKUP(TRIM(A14),TRIM(site_tech_info!$A$2:$A$79),site_tech_info!$W$2:$W$79),"")} -> 3.0800821 | E14: {=IFERROR(SUM(INDEX('Simulated Production'!$B$2:$M$80,MATCH(TRIM($A14),INDEX(TRIM('Simulated Production'!$A$2:$A$80),0),0),0)),"Not found")} -> 81158 | F14: =(Table2[[#This Row],[As-Built kWh]]*Table2[[#This Row],[Expected Utilisation%]])*(1-0.007)^(Table2[[#This Row],[Age]]) -> 73464.327 | G14: 0 | H14: =F14-G14 -> 73464.327 | I14: {=SUMPRODUCT((TRIM(measured[Site Name])=TRIM($A14))*(measured[Date]>=DATE(2025,7,1))*(measured[Date]<=DATE(2026,6,30))*measured[Measured Value (kWh)])} -> 56043.3 | J14: =I14-H14 -> -17421.027 | K14: =(Table2[[#This Row],[Actual Generation (kWh)]]/Table2[[#This Row],[Correct kWh]])*100 -> 76.286413 | L14: Testing
A15: Watt Place Rotoflo | B15: YES | C15: {=IFERROR(INDEX('Expected Production'!$B$2:$B$80,MATCH(TRIM($A15),INDEX(TRIM('Expected Production'!$A$2:$A$80),0),0)),"Not found")} -> 0.9 | D15: {=_xlfn.IFNA(_xlfn.XLOOKUP(TRIM(A15),TRIM(site_tech_info!$A$2:$A$79),site_tech_info!$W$2:$W$79),"")} -> 2.9486653 | E15: {=IFERROR(SUM(INDEX('Simulated Production'!$B$2:$M$80,MATCH(TRIM($A15),INDEX(TRIM('Simulated Production'!$A$2:$A$80),0),0),0)),"Not found")} -> 312107 | F15: =(Table2[[#This Row],[As-Built kWh]]*Table2[[#This Row],[Expected Utilisation%]])*(1-0.007)^(Table2[[#This Row],[Age]]) -> 275137.87 | G15: 0 | H15: =F15-G15 -> 275137.87 | I15: {=SUMPRODUCT((TRIM(measured[Site Name])=TRIM($A15))*(measured[Date]>=DATE(2025,7,1))*(measured[Date]<=DATE(2026,6,30))*measured[Measured Value (kWh)])} -> 237169.27 | J15: =I15-H15 -> -37968.602 | K15: =(Table2[[#This Row],[Actual Generation (kWh)]]/Table2[[#This Row],[Correct kWh]])*100 -> 86.200154 | L15: Testing
A16: SR Morula TF 1 | B16: YES | C16: {=IFERROR(INDEX('Expected Production'!$B$2:$B$80,MATCH(TRIM($A16),INDEX(TRIM('Expected Production'!$A$2:$A$80),0),0)),"Not found")} -> 0.9 | D16: {=_xlfn.IFNA(_xlfn.XLOOKUP(TRIM(A16),TRIM(site_tech_info!$A$2:$A$79),site_tech_info!$W$2:$W$79),"")} -> 2.9924709 | E16: {=IFERROR(SUM(INDEX('Simulated Production'!$B$2:$M$80,MATCH(TRIM($A16),INDEX(TRIM('Simulated Production'!$A$2:$A$80),0),0),0)),"Not found")} -> 96848.548 | F16: =(Table2[[#This Row],[As-Built kWh]]*Table2[[#This Row],[Expected Utilisation%]])*(1-0.007)^(Table2[[#This Row],[Age]]) -> 85350.553 | G16: =(6087*(1-0.007)^(Table2[[#This Row],[Age]]))*(1-0.007)^(Table2[[#This Row],[Age]]) -> 5836.3957 | H16: =F16-G16 -> 79514.157 | I16: {=SUMPRODUCT((TRIM(measured[Site Name])=TRIM($A16))*(measured[Date]>=DATE(2025,7,1))*(measured[Date]<=DATE(2026,6,30))*measured[Measured Value (kWh)])} -> 77775.48 | J16: =I16-H16 -> -1738.6774 | K16: =(Table2[[#This Row],[Actual Generation (kWh)]]/Table2[[#This Row],[Correct kWh]])*100 -> 97.813374 | L16: Testing
A17: SR Morula TF 2 | B17: YES | C17: {=IFERROR(INDEX('Expected Production'!$B$2:$B$80,MATCH(TRIM($A17),INDEX(TRIM('Expected Production'!$A$2:$A$80),0),0)),"Not found")} -> 0.9 | D17: {=_xlfn.IFNA(_xlfn.XLOOKUP(TRIM(A17),TRIM(site_tech_info!$A$2:$A$79),site_tech_info!$W$2:$W$79),"")} -> 2.9924709 | E17: {=IFERROR(SUM(INDEX('Simulated Production'!$B$2:$M$80,MATCH(TRIM($A17),INDEX(TRIM('Simulated Production'!$A$2:$A$80),0),0),0)),"Not found")} -> 100237.87 | F17: =(Table2[[#This Row],[As-Built kWh]]*Table2[[#This Row],[Expected Utilisation%]])*(1-0.007)^(Table2[[#This Row],[Age]]) -> 88337.491 | G17: =(6247*(1-0.007)^(Table2[[#This Row],[Age]]))*(1-0.007)^(Table2[[#This Row],[Age]]) -> 5989.8085 | H17: =F17-G17 -> 82347.682 | I17: {=SUMPRODUCT((TRIM(measured[Site Name])=TRIM($A17))*(measured[Date]>=DATE(2025,7,1))*(measured[Date]<=DATE(2026,6,30))*measured[Measured Value (kWh)])} -> 78264.64 | J17: =I17-H17 -> -4083.0421 | K17: =(Table2[[#This Row],[Actual Generation (kWh)]]/Table2[[#This Row],[Correct kWh]])*100 -> 95.041704 | L17: Testing
A18: Olievenhoutbosch 1 | B18: YES | C18: {=IFERROR(INDEX('Expected Production'!$B$2:$B$80,MATCH(TRIM($A18),INDEX(TRIM('Expected Production'!$A$2:$A$80),0),0)),"Not found")} -> 0.9 | D18: {=_xlfn.IFNA(_xlfn.XLOOKUP(TRIM(A18),TRIM(site_tech_info!$A$2:$A$79),site_tech_info!$W$2:$W$79),"")} -> 0.89801506 | E18: {=IFERROR(SUM(INDEX('Simulated Production'!$B$2:$M$80,MATCH(TRIM($A18),INDEX(TRIM('Simulated Production'!$A$2:$A$80),0),0),0)),"Not found")} -> 524973 | F18: =(Table2[[#This Row],[As-Built kWh]]*Table2[[#This Row],[Expected Utilisation%]])*(1-0.007)^(Table2[[#This Row],[Age]]) -> 469504.61 | G18: =(31229+36815+40778+47657*(5/30))*(1-0.007)^(Table2[[#This Row],[Age]]) -> 116030.57 | H18: =F18-G18 -> 353474.03 | I18: {=SUMPRODUCT((TRIM(measured[Site Name])=TRIM($A18))*(measured[Date]>=DATE(2025,7,1))*(measured[Date]<=DATE(2026,6,30))*measured[Measured Value (kWh)])} -> 300497.96 | J18: =I18-H18 -> -52976.075 | K18: =(Table2[[#This Row],[Actual Generation (kWh)]]/Table2[[#This Row],[Correct kWh]])*100 -> 85.012739 | L18: Testing
A19: Olievenhoutbosch 2 | B19: YES | C19: {=IFERROR(INDEX('Expected Production'!$B$2:$B$80,MATCH(TRIM($A19),INDEX(TRIM('Expected Production'!$A$2:$A$80),0),0)),"Not found")} -> 0.9 | D19: {=_xlfn.IFNA(_xlfn.XLOOKUP(TRIM(A19),TRIM(site_tech_info!$A$2:$A$79),site_tech_info!$W$2:$W$79),"")} -> 0.89801506 | E19: {=IFERROR(SUM(INDEX('Simulated Production'!$B$2:$M$80,MATCH(TRIM($A19),INDEX(TRIM('Simulated Production'!$A$2:$A$80),0),0),0)),"Not found")} -> 138565 | F19: =(Table2[[#This Row],[As-Built kWh]]*Table2[[#This Row],[Expected Utilisation%]])*(1-0.007)^(Table2[[#This Row],[Age]]) -> 123924.29 | G19: =(8307+9721+10756+12191*(5/30))*(1-0.007)^(Table2[[#This Row],[Age]]) -> 30622.052 | H19: =F19-G19 -> 93302.236 | I19: {=SUMPRODUCT((TRIM(measured[Site Name])=TRIM($A19))*(measured[Date]>=DATE(2025,7,1))*(measured[Date]<=DATE(2026,6,30))*measured[Measured Value (kWh)])} -> 81974.633 | J19: =I19-H19 -> -11327.603 | K19: =(Table2[[#This Row],[Actual Generation (kWh)]]/Table2[[#This Row],[Correct kWh]])*100 -> 87.859237 | L19: Testing
A20: IPID - Floor 6 | B20: YES | C20: {=IFERROR(INDEX('Expected Production'!$B$2:$B$80,MATCH(TRIM($A20),INDEX(TRIM('Expected Production'!$A$2:$A$80),0),0)),"Not found")} -> 0.9 | D20: {=_xlfn.IFNA(_xlfn.XLOOKUP(TRIM(A20),TRIM(site_tech_info!$A$2:$A$79),site_tech_info!$W$2:$W$79),"")} -> 0.87063655 | E20: {=IFERROR(SUM(INDEX('Simulated Production'!$B$2:$M$80,MATCH(TRIM($A20),INDEX(TRIM('Simulated Production'!$A$2:$A$80),0),0),0)),"Not found")} -> 89076 | F20: =(Table2[[#This Row],[As-Built kWh]]*Table2[[#This Row],[Expected Utilisation%]])*(1-0.007)^(Table2[[#This Row],[Age]]) -> 79679.595 | G20: =(5785+6585+7019+7479+7553+7553*(3/30))*(1-0.007)^(Table2[[#This Row],[Age]]) -> 34961.822 | H20: =F20-G20 -> 44717.773 | I20: {=SUMPRODUCT((TRIM(measured[Site Name])=TRIM($A20))*(measured[Date]>=DATE(2025,7,1))*(measured[Date]<=DATE(2026,6,30))*measured[Measured Value (kWh)])} -> 33061.7 | J20: =I20-H20 -> -11656.073 | K20: =(Table2[[#This Row],[Actual Generation (kWh)]]/Table2[[#This Row],[Correct kWh]])*100 -> 73.934138 | L20: Testing
A21: IPID - Floor 4 | B21: YES | C21: {=IFERROR(INDEX('Expected Production'!$B$2:$B$80,MATCH(TRIM($A21),INDEX(TRIM('Expected Production'!$A$2:$A$80),0),0)),"Not found")} -> 0.9 | D21: {=_xlfn.IFNA(_xlfn.XLOOKUP(TRIM(A21),TRIM(site_tech_info!$A$2:$A$79),site_tech_info!$W$2:$W$79),"")} -> 0.87063655 | E21: {=IFERROR(SUM(INDEX('Simulated Production'!$B$2:$M$80,MATCH(TRIM($A21),INDEX(TRIM('Simulated Production'!$A$2:$A$80),0),0),0)),"Not found")} -> 89076 | F21: =(Table2[[#This Row],[As-Built kWh]]*Table2[[#This Row],[Expected Utilisation%]])*(1-0.007)^(Table2[[#This Row],[Age]]) -> 79679.595 | G21: =(5785+6585+7019+7479+7553+7553*(3/30))*(1-0.007)^(Table2[[#This Row],[Age]]) -> 34961.822 | H21: =F21-G21 -> 44717.773 | I21: {=SUMPRODUCT((TRIM(measured[Site Name])=TRIM($A21))*(measured[Date]>=DATE(2025,7,1))*(measured[Date]<=DATE(2026,6,30))*measured[Measured Value (kWh)])} -> 47460.3 | J21: =I21-H21 -> 2742.5268 | K21: =(Table2[[#This Row],[Actual Generation (kWh)]]/Table2[[#This Row],[Correct kWh]])*100 -> 106.13297 | L21: Testing
A22: Engen Lotus Gardens | B22: YES | C22: {=IFERROR(INDEX('Expected Production'!$B$2:$B$80,MATCH(TRIM($A22),INDEX(TRIM('Expected Production'!$A$2:$A$80),0),0)),"Not found")} -> 0.9 | D22: {=_xlfn.IFNA(_xlfn.XLOOKUP(TRIM(A22),TRIM(site_tech_info!$A$2:$A$79),site_tech_info!$W$2:$W$79),"")} -> 0.82409309 | E22: {=IFERROR(SUM(INDEX('Simulated Production'!$B$2:$M$80,MATCH(TRIM($A22),INDEX(TRIM('Simulated Production'!$A$2:$A$80),0),0),0)),"Not found")} -> 31637 | F22: =(Table2[[#This Row],[As-Built kWh]]*Table2[[#This Row],[Expected Utilisation%]])*(1-0.007)^(Table2[[#This Row],[Age]]) -> 28308.946 | G22: =(2350+2520+2436+2426+2356+2437)*(1-0.007)^(Table2[[#This Row],[Age]]) -> 14441.159 | H22: =F22-G22 -> 13867.787 | I22: {=SUMPRODUCT((TRIM(measured[Site Name])=TRIM($A22))*(measured[Date]>=DATE(2025,7,1))*(measured[Date]<=DATE(2026,6,30))*measured[Measured Value (kWh)])} -> 17882.44 | J22: =I22-H22 -> 4014.6526 | K22: =(Table2[[#This Row],[Actual Generation (kWh)]]/Table2[[#This Row],[Correct kWh]])*100 -> 128.94948 | L22: Testing
A23: Engen Kaalfontein | B23: YES | C23: {=IFERROR(INDEX('Expected Production'!$B$2:$B$80,MATCH(TRIM($A23),INDEX(TRIM('Expected Production'!$A$2:$A$80),0),0)),"Not found")} -> 0.9 | D23: {=_xlfn.IFNA(_xlfn.XLOOKUP(TRIM(A23),TRIM(site_tech_info!$A$2:$A$79),site_tech_info!$W$2:$W$79),"")} -> 0.24640657 | E23: {=IFERROR(SUM(INDEX('Simulated Production'!$B$2:$M$80,MATCH(TRIM($A23),INDEX(TRIM('Simulated Production'!$A$2:$A$80),0),0),0)),"Not found")} -> 190644.6 | F23: =(Table2[[#This Row],[As-Built kWh]]*Table2[[#This Row],[Expected Utilisation%]])*(1-0.007)^(Table2[[#This Row],[Age]]) -> 171283.41 | G23: 171487.77 | H23: =F23-G23 -> -204.3611 | I23: {=SUMPRODUCT((TRIM(measured[Site Name])=TRIM($A23))*(measured[Date]>=DATE(2025,7,1))*(measured[Date]<=DATE(2026,6,30))*measured[Measured Value (kWh)])} -> 10169 | J23: =I23-H23 -> 10373.361 | K23: =(Table2[[#This Row],[Actual Generation (kWh)]]/Table2[[#This Row],[Correct kWh]])*100 -> -4975.9959 | L23: Testing
A24: Alpine Heath Resort | B24: YES | C24: {=IFERROR(INDEX('Expected Production'!$B$2:$B$80,MATCH(TRIM($A24),INDEX(TRIM('Expected Production'!$A$2:$A$80),0),0)),"Not found")} -> 0.9 | D24: {=_xlfn.IFNA(_xlfn.XLOOKUP(TRIM(A24),TRIM(site_tech_info!$A$2:$A$79),site_tech_info!$W$2:$W$79),"")} -> 0.30663929 | E24: {=IFERROR(SUM(INDEX('Simulated Production'!$B$2:$M$80,MATCH(TRIM($A24),INDEX(TRIM('Simulated Production'!$A$2:$A$80),0),0),0)),"Not found")} -> 380893 | F24: =(Table2[[#This Row],[As-Built kWh]]*Table2[[#This Row],[Expected Utilisation%]])*(1-0.007)^(Table2[[#This Row],[Age]]) -> 342066.09 | G24: =(28051+31649+28250+28466+28992+28904+28877+25885+27341+27824*(28/30))*(1-0.007)^(Table2[[#This Row],[Age]]) -> 281776.46 | H24: =F24-G24 -> 60289.628 | I24: {=SUMPRODUCT((TRIM(measured[Site Name])=TRIM($A24))*(measured[Date]>=DATE(2025,7,1))*(measured[Date]<=DATE(2026,6,30))*measured[Measured Value (kWh)])} -> 53212.2 | J24: =I24-H24 -> -7077.4281 | K24: =(Table2[[#This Row],[Actual Generation (kWh)]]/Table2[[#This Row],[Correct kWh]])*100 -> 88.260952 | L24: Testing

Sheet measured
A1: Site Name | B1: Date | C1: Measured Value (kWh)
A2: 21 Melrose | B2: 45292 | C2: 1815
A3: 21 Melrose | B3: 45323 | C3: 2295
A4: 21 Melrose | B4: 45352 | C4: 2474
A5: 21 Melrose | B5: 45383 | C5: 2136
A6: 21 Melrose | B6: 45413 | C6: 2212
A7: 21 Melrose | B7: 45444 | C7: 1863
A8: 21 Melrose | B8: 45474 | C8: 1943
A9: 21 Melrose | B9: 45505 | C9: 1710
A10: 21 Melrose | B10: 45536 | C10: 1579
A11: 21 Melrose | B11: 45566 | C11: 1593
A12: 21 Melrose | B12: 45597 | C12: 1794
A13: 21 Melrose | B13: 45627 | C13: 1794
... A32: 21 Melrose | B32: 46204 | C32: 1638
A33: 21 Melrose | B33: 46235
A34: 21 Melrose | B34: 46266
A35: 21 Melrose | B35: 46296
A36: 21 Melrose | B36: 46327
A37: 21 Melrose | B37: 46357
A38: African Global Plastics | B38: 45292 | C38: 23024
A39: African Global Plastics | B39: 45323 | C39: 23235
A40: African Global Plastics | B40: 45352 | C40: 23235
A41: African Global Plastics | B41: 45383 | C41: 19307
A42: African Global Plastics | B42: 45413 | C42: 18418
A43: African Global Plastics | B43: 45444 | C43: 15949
A44: African Global Plastics | B44: 45474 | C44: 17174
A45: African Global Plastics | B45: 45505 | C45: 13588
A46: African Global Plastics | B46: 45536 | C46: 20254
A47: African Global Plastics | B47: 45566 | C47: 27693
A48: African Global Plastics | B48: 45597 | C48: 24041
A49: African Global Plastics | B49: 45627 | C49: 25076
... A68: African Global Plastics | B68: 46204 | C68: 13136.53
A69: African Global Plastics | B69: 46235
A70: African Global Plastics | B70: 46266
A71: African Global Plastics | B71: 46296
A72: African Global Plastics | B72: 46327
A73: African Global Plastics | B73: 46357
A74: Alpine Heath Residential | B74: 45292
A75: Alpine Heath Residential | B75: 45323
A76: Alpine Heath Residential | B76: 45352
...

Sheet Expected Production
A1: Site Name | B1: Expected Utilisation% | C1: Jan | D1: Feb | E1: Mar | F1: Apr | G1: May | H1: Jun | I1: Jul | J1: Aug | K1: Sep | L1: Oct | M1: Nov | N1: Dec
A2: 21 Melrose | B2: 0.9 | C2: =Table4[[#This Row],[Jan]]*$B2 -> 2370.6 | D2: =Table4[[#This Row],[Feb]]*$B2 -> 2680.2 | E2: =Table4[[#This Row],[Mar]]*$B2 -> 2183.4 | F2: =Table4[[#This Row],[Apr]]*$B2 -> 1873.8 | G2: =Table4[[#This Row],[May]]*$B2 -> 1822.5 | H2: =Table4[[#This Row],[Jun]]*$B2 -> 1629 | I2: =Table4[[#This Row],[Jul]]*$B2 -> 1814.4 | J2: =Table4[[#This Row],[Aug]]*$B2 -> 2116.8 | K2: =Table4[[#This Row],[Sep]]*$B2 -> 2275.2 | L2: =Table4[[#This Row],[Oct]]*$B2 -> 2407.5 | M2: =Table4[[#This Row],[Nov]]*$B2 -> 2356.2 | N2: =Table4[[#This Row],[Dec]]*$B2 -> 2482.2
A3: African Global Plastics | B3: 0.85 | C3: =Table4[[#This Row],[Jan]]*$B3 -> 22515.905 | D3: =Table4[[#This Row],[Feb]]*$B3 -> 19786.13 | E3: =Table4[[#This Row],[Mar]]*$B3 -> 20148.4 | F3: =Table4[[#This Row],[Apr]]*$B3 -> 16764.89 | G3: =Table4[[#This Row],[May]]*$B3 -> 15972.095 | H3: =Table4[[#This Row],[Jun]]*$B3 -> 14367.21 | I3: =Table4[[#This Row],[Jul]]*$B3 -> 15907.665 | J3: =Table4[[#This Row],[Aug]]*$B3 -> 18527.365 | K3: =Table4[[#This Row],[Sep]]*$B3 -> 20404.335 | L3: =Table4[[#This Row],[Oct]]*$B3 -> 22320.66 | M3: =Table4[[#This Row],[Nov]]*$B3 -> 22520.665 | N3: =Table4[[#This Row],[Dec]]*$B3 -> 23777.985
A4: Alpine Heath Residential | B4: 0.9 | C4: =Table4[[#This Row],[Jan]]*$B4 -> 4801.5 | D4: =Table4[[#This Row],[Feb]]*$B4 -> 4303.8 | E4: =Table4[[#This Row],[Mar]]*$B4 -> 4545.9 | F4: =Table4[[#This Row],[Apr]]*$B4 -> 4619.7 | G4: =Table4[[#This Row],[May]]*$B4 -> 4990.5 | H4: =Table4[[#This Row],[Jun]]*$B4 -> 4761.9 | I4: =Table4[[#This Row],[Jul]]*$B4 -> 4680.9 | J4: =Table4[[#This Row],[Aug]]*$B4 -> 5249.7 | K4: =Table4[[#This Row],[Sep]]*$B4 -> 4694.4 | L4: =Table4[[#This Row],[Oct]]*$B4 -> 4732.2 | M4: =Table4[[#This Row],[Nov]]*$B4 -> 4822.2 | N4: =Table4[[#This Row],[Dec]]*$B4 -> 4805.1
A5: Bendstore Plaza Shops | B5: 0.85 | C5: =Table4[[#This Row],[Jan]]*$B5 -> 16262.2 | D5: =Table4[[#This Row],[Feb]]*$B5 -> 13986.75 | E5: =Table4[[#This Row],[Mar]]*$B5 -> 15463.2 | F5: =Table4[[#This Row],[Apr]]*$B5 -> 14886.05 | G5: =Table4[[#This Row],[May]]*$B5 -> 14411.75 | H5: =Table4[[#This Row],[Jun]]*$B5 -> 13050.05 | I5: =Table4[[#This Row],[Jul]]*$B5 -> 13735.15 | J5: =Table4[[#This Row],[Aug]]*$B5 -> 15350.15 | K5: =Table4[[#This Row],[Sep]]*$B5 -> 15431.75 | L5: =Table4[[#This Row],[Oct]]*$B5 -> 14821.45 | M5: =Table4[[#This Row],[Nov]]*$B5 -> 14695.65 | N5: =Table4[[#This Row],[Dec]]*$B5 -> 16154.25
A6: Bendstore Spar | B6: 0.9 | C6: =Table4[[#This Row],[Jan]]*$B6 -> 51314.735 | D6: =Table4[[#This Row],[Feb]]*$B6 -> 44103.291 | E6: =Table4[[#This Row],[Mar]]*$B6 -> 48739.27 | F6: =Table4[[#This Row],[Apr]]*$B6 -> 46849.899 | G6: =Table4[[#This Row],[May]]*$B6 -> 45273.233 | H6: =Table4[[#This Row],[Jun]]*$B6 -> 40943.972 | I6: =Table4[[#This Row],[Jul]]*$B6 -> 43112.803 | J6: =Table4[[#This Row],[Aug]]*$B6 -> 48266.503 | K6: =Table4[[#This Row],[Sep]]*$B6 -> 48602.891 | L6: =Table4[[#This Row],[Oct]]*$B6 -> 46748.911 | M6: =Table4[[#This Row],[Nov]]*$B6 -> 46388.482 | N6: =Table4[[#This Row],[Dec]]*$B6 -> 50640.311
A7: Beyerskloof | B7: 0.9 | C7: =Table4[[#This Row],[Jan]]*$B7 -> 13787.1 | D7: =Table4[[#This Row],[Feb]]*$B7 -> 11359.8 | E7: =Table4[[#This Row],[Mar]]*$B7 -> 10881 | F7: =Table4[[#This Row],[Apr]]*$B7 -> 7828.2 | G7: =Table4[[#This Row],[May]]*$B7 -> 5953.5 | H7: =Table4[[#This Row],[Jun]]*$B7 -> 5166 | I7: =Table4[[#This Row],[Jul]]*$B7 -> 5564.7 | J7: =Table4[[#This Row],[Aug]]*$B7 -> 6960.6 | K7: =Table4[[#This Row],[Sep]]*$B7 -> 8946 | L7: =Table4[[#This Row],[Oct]]*$B7 -> 11314.8 | M7: =Table4[[#This Row],[Nov]]*$B7 -> 12713.4 | N7: =Table4[[#This Row],[Dec]]*$B7 -> 13878.9
A8: BP Parys | B8: 0.9 | C8: =Table4[[#This Row],[Jan]]*$B8 -> 8151.3 | D8: =Table4[[#This Row],[Feb]]*$B8 -> 7235.1 | E8: =Table4[[#This Row],[Mar]]*$B8 -> 7075.8 | F8: =Table4[[#This Row],[Apr]]*$B8 -> 5754.6 | G8: =Table4[[#This Row],[May]]*$B8 -> 5424.3 | H8: =Table4[[#This Row],[Jun]]*$B8 -> 4787.1 | I8: =Table4[[#This Row],[Jul]]*$B8 -> 5360.4 | J8: =Table4[[#This Row],[Aug]]*$B8 -> 6363 | K8: =Table4[[#This Row],[Sep]]*$B8 -> 7218.9 | L8: =Table4[[#This Row],[Oct]]*$B8 -> 7839 | M8: =Table4[[#This Row],[Nov]]*$B8 -> 8191.8 | N8: =Table4[[#This Row],[Dec]]*$B8 -> 8227.8
A9: Buffalo Rock | B9: 0.9 | C9: =Table4[[#This Row],[Jan]]*$B9 -> 2202.3 | D9: =Table4[[#This Row],[Feb]]*$B9 -> 1983.6 | E9: =Table4[[#This Row],[Mar]]*$B9 -> 2127.6 | F9: =Table4[[#This Row],[Apr]]*$B9 -> 1767.6 | G9: =Table4[[#This Row],[May]]*$B9 -> 1631.7 | H9: =Table4[[#This Row],[Jun]]*$B9 -> 1480.5 | I9: =Table4[[#This Row],[Jul]]*$B9 -> 1612.8 | J9: =Table4[[#This Row],[Aug]]*$B9 -> 1764 | K9: =Table4[[#This Row],[Sep]]*$B9 -> 1868.4 | L9: =Table4[[#This Row],[Oct]]*$B9 -> 1900.8 | M9: =Table4[[#This Row],[Nov]]*$B9 -> 1835.1 | N9: =Table4[[#This Row],[Dec]]*$B9 -> 1986.3
A10: Checkers De Aar | B10: 0.9 | C10: =Table4[[#This Row],[Jan]]*$B10 -> 26689.5 | D10: =Table4[[#This Row],[Feb]]*$B10 -> 20674.8 | E10: =Table4[[#This Row],[Mar]]*$B10 -> 20095.2 | F10: =Table4[[#This Row],[Apr]]*$B10 -> 16286.4 | G10: =Table4[[#This Row],[May]]*$B10 -> 13518.9 | H10: =Table4[[#This Row],[Jun]]*$B10 -> 11864.7 | I10: =Table4[[#This Row],[Jul]]*$B10 -> 13589.1 | J10: =Table4[[#This Row],[Aug]]*$B10 -> 17109 | K10: =Table4[[#This Row],[Sep]]*$B10 -> 19506.6 | L10: =Table4[[#This Row],[Oct]]*$B10 -> 24081.3 | M10: =Table4[[#This Row],[Nov]]*$B10 -> 25889.4 | N10: =Table4[[#This Row],[Dec]]*$B10 -> 27992.7
A11: Checkers Silverlakes Gen | B11: 0.9 | C11: =Table4[[#This Row],[Jan]]*$B11 -> 21105 | D11: =Table4[[#This Row],[Feb]]*$B11 -> 18220.5 | E11: =Table4[[#This Row],[Mar]]*$B11 -> 18368.1 | F11: =Table4[[#This Row],[Apr]]*$B11 -> 15103.8 | G11: =Table4[[#This Row],[May]]*$B11 -> 14130 | H11: =Table4[[#This Row],[Jun]]*$B11 -> 12619.8 | I11: =Table4[[#This Row],[Jul]]*$B11 -> 14002.2 | J11: =Table4[[#This Row],[Aug]]*$B11 -> 16641.9 | K11: =Table4[[#This Row],[Sep]]*$B11 -> 18626.4 | L11: =Table4[[#This Row],[Oct]]*$B11 -> 20503.8 | M11: =Table4[[#This Row],[Nov]]*$B11 -> 20601 | N11: =Table4[[#This Row],[Dec]]*$B11 -> 22024.8
A12: Checkers Silverlakes No Gen | B12: 0.9 | C12: =Table4[[#This Row],[Jan]]*$B12 -> 21105 | D12: =Table4[[#This Row],[Feb]]*$B12 -> 18220.5 | E12: =Table4[[#This Row],[Mar]]*$B12 -> 18368.1 | F12: =Table4[[#This Row],[Apr]]*$B12 -> 15103.8 | G12: =Table4[[#This Row],[May]]*$B12 -> 14130 | H12: =Table4[[#This Row],[Jun]]*$B12 -> 12619.8 | I12: =Table4[[#This Row],[Jul]]*$B12 -> 14002.2 | J12: =Table4[[#This Row],[Aug]]*$B12 -> 16641.9 | K12: =Table4[[#This Row],[Sep]]*$B12 -> 18626.4 | L12: =Table4[[#This Row],[Oct]]*$B12 -> 20503.8 | M12: =Table4[[#This Row],[Nov]]*$B12 -> 20601 | N12: =Table4[[#This Row],[Dec]]*$B12 -> 22024.8
A13: Checkrite Inanda | B13: 0.9 | C13: =Table4[[#This Row],[Jan]]*$B13 -> 8664.3 | D13: =Table4[[#This Row],[Feb]]*$B13 -> 8100 | E13: =Table4[[#This Row],[Mar]]*$B13 -> 7805.7 | F13: =Table4[[#This Row],[Apr]]*$B13 -> 6534 | G13: =Table4[[#This Row],[May]]*$B13 -> 5592.6 | H13: =Table4[[#This Row],[Jun]]*$B13 -> 5059.8 | I13: =Table4[[#This Row],[Jul]]*$B13 -> 5372.1 | J13: =Table4[[#This Row],[Aug]]*$B13 -> 6485.4 | K13: =Table4[[#This Row],[Sep]]*$B13 -> 6914.7 | L13: =Table4[[#This Row],[Oct]]*$B13 -> 8033.4 | M13: =Table4[[#This Row],[Nov]]*$B13 -> 8012.7 | N13: =Table4[[#This Row],[Dec]]*$B13 -> 8547.3
... A30: Kool Village | B30: 0.9 | C30: =Table4[[#This Row],[Jan]]*$B30 -> 12213 | D30: =Table4[[#This Row],[Feb]]*$B30 -> 10570.5 | E30: =Table4[[#This Row],[Mar]]*$B30 -> 10619.1 | F30: =Table4[[#This Row],[Apr]]*$B30 -> 9139.5 | G30: =Table4[[#This Row],[May]]*$B30 -> 8593.2 | H30: =Table4[[#This Row],[Jun]]*$B30 -> 7680.6 | I30: =Table4[[#This Row],[Jul]]*$B30 -> 8550.9 | J30: =Table4[[#This Row],[Aug]]*$B30 -> 9997.2 | K30: =Table4[[#This Row],[Sep]]*$B30 -> 10701.9 | L30: =Table4[[#This Row],[Oct]]*$B30 -> 11834.1 | M30: =Table4[[#This Row],[Nov]]*$B30 -> 12129.3 | N30: =Table4[[#This Row],[Dec]]*$B30 -> 12998.7
A31: Makalali | C31: =Table4[[#This Row],[Jan]]*$B31 -> 0 | D31: =Table4[[#This Row],[Feb]]*$B31 -> 0 | E31: =Table4[[#This Row],[Mar]]*$B31 -> 0 | F31: =Table4[[#This Row],[Apr]]*$B31 -> 0 | G31: =Table4[[#This Row],[May]]*$B31 -> 0 | H31: =Table4[[#This Row],[Jun]]*$B31 -> 0 | I31: =Table4[[#This Row],[Jul]]*$B31 -> 0 | J31: =Table4[[#This Row],[Aug]]*$B31 -> 0 | K31: =Table4[[#This Row],[Sep]]*$B31 -> 0 | L31: =Table4[[#This Row],[Oct]]*$B31 -> 0 | M31: =Table4[[#This Row],[Nov]]*$B31 -> 0 | N31: =Table4[[#This Row],[Dec]]*$B31 -> 0
A32: Mambha Cash & Carry | B32: 0.9 | C32: =Table4[[#This Row],[Jan]]*$B32 -> 22241.7 | D32: =Table4[[#This Row],[Feb]]*$B32 -> 19450.8 | E32: =Table4[[#This Row],[Mar]]*$B32 -> 19575 | F32: =Table4[[#This Row],[Apr]]*$B32 -> 15792.3 | G32: =Table4[[#This Row],[May]]*$B32 -> 13477.5 | H32: =Table4[[#This Row],[Jun]]*$B32 -> 12124.8 | I32: =Table4[[#This Row],[Jul]]*$B32 -> 13099.5 | J32: =Table4[[#This Row],[Aug]]*$B32 -> 15450.3 | K32: =Table4[[#This Row],[Sep]]*$B32 -> 16583.4 | L32: =Table4[[#This Row],[Oct]]*$B32 -> 19432.8 | M32: =Table4[[#This Row],[Nov]]*$B32 -> 20010.6 | N32: =Table4[[#This Row],[Dec]]*$B32 -> 22485.6
A33: Mathe Group Company | B33: 0.85 | C33: =Table4[[#This Row],[Jan]]*$B33 -> 61302.85 | D33: =Table4[[#This Row],[Feb]]*$B33 -> 55639.3 | E33: =Table4[[#This Row],[Mar]]*$B33 -> 58024.4 | F33: =Table4[[#This Row],[Apr]]*$B33 -> 48946.4 | G33: =Table4[[#This Row],[May]]*$B33 -> 44310.5 | H33: =Table4[[#This Row],[Jun]]*$B33 -> 40933.45 | I33: =Table4[[#This Row],[Jul]]*$B33 -> 43977.3 | J33: =Table4[[#This Row],[Aug]]*$B33 -> 48620.85 | K33: =Table4[[#This Row],[Sep]]*$B33 -> 50331.05 | L33: =Table4[[#This Row],[Oct]]*$B33 -> 55230.45 | M33: =Table4[[#This Row],[Nov]]*$B33 -> 56583.65 | N33: =Table4[[#This Row],[Dec]]*$B33 -> 61075.9
A34: Mdluli | B34: 0.8 | C34: =Table4[[#This Row],[Jan]]*$B34 -> 14107.2 | D34: =Table4[[#This Row],[Feb]]*$B34 -> 13178.4 | E34: =Table4[[#This Row],[Mar]]*$B34 -> 15390.4 | F34: =Table4[[#This Row],[Apr]]*$B34 -> 13652 | G34: =Table4[[#This Row],[May]]*$B34 -> 13508.8 | H34: =Table4[[#This Row],[Jun]]*$B34 -> 12879.2 | I34: =Table4[[#This Row],[Jul]]*$B34 -> 13680.8 | J34: =Table4[[#This Row],[Aug]]*$B34 -> 13878.4 | K34: =Table4[[#This Row],[Sep]]*$B34 -> 13503.2 | L34: =Table4[[#This Row],[Oct]]*$B34 -> 12755.2 | M34: =Table4[[#This Row],[Nov]]*$B34 -> 11784.8 | N34: =Table4[[#This Row],[Dec]]*$B34 -> 12301.6
